[2025-06-14T19:19:17.154+0000] {taskinstance.py:1956} INFO - Dependencies all met for dep_context=non-requeueable deps ti=<TaskInstance: scraping_autopia_dag.trigger_entrenamiento manual__2025-06-14T19:15:08.479063+00:00 [queued]>
[2025-06-14T19:19:17.165+0000] {taskinstance.py:1956} INFO - Dependencies all met for dep_context=requeueable deps ti=<TaskInstance: scraping_autopia_dag.trigger_entrenamiento manual__2025-06-14T19:15:08.479063+00:00 [queued]>
[2025-06-14T19:19:17.166+0000] {taskinstance.py:2170} INFO - Starting attempt 1 of 1
[2025-06-14T19:19:17.185+0000] {taskinstance.py:2191} INFO - Executing <Task(TriggerDagRunOperator): trigger_entrenamiento> on 2025-06-14 19:15:08.479063+00:00
[2025-06-14T19:19:17.193+0000] {standard_task_runner.py:60} INFO - Started process 1128 to run task
[2025-06-14T19:19:17.199+0000] {standard_task_runner.py:87} INFO - Running: ['***', 'tasks', 'run', 'scraping_autopia_dag', 'trigger_entrenamiento', 'manual__2025-06-14T19:15:08.479063+00:00', '--job-id', '118', '--raw', '--subdir', 'DAGS_FOLDER/scraping_autopia_dag.py', '--cfg-path', '/tmp/tmp5ude5dbu']
[2025-06-14T19:19:17.202+0000] {standard_task_runner.py:88} INFO - Job 118: Subtask trigger_entrenamiento
[2025-06-14T19:19:17.290+0000] {task_command.py:423} INFO - Running <TaskInstance: scraping_autopia_dag.trigger_entrenamiento manual__2025-06-14T19:15:08.479063+00:00 [running]> on host 15346582a165
[2025-06-14T19:19:17.440+0000] {taskinstance.py:2480} INFO - Exporting env vars: AIRFLOW_CTX_DAG_OWNER='***' AIRFLOW_CTX_DAG_ID='scraping_autopia_dag' AIRFLOW_CTX_TASK_ID='trigger_entrenamiento' AIRFLOW_CTX_EXECUTION_DATE='2025-06-14T19:15:08.479063+00:00' AIRFLOW_CTX_TRY_NUMBER='1' AIRFLOW_CTX_DAG_RUN_ID='manual__2025-06-14T19:15:08.479063+00:00'
[2025-06-14T19:19:23.348+0000] {logging_mixin.py:188} WARNING - /home/***/.local/lib/python3.8/site-packages/***/providers/google/cloud/links/dataproc.py:79 AirflowProviderDeprecationWarning: This DataprocLink is deprecated.
[2025-06-14T19:19:23.353+0000] {logging_mixin.py:188} WARNING - /home/***/.local/lib/python3.8/site-packages/***/providers/google/cloud/links/dataproc.py:128 AirflowProviderDeprecationWarning: This DataprocListLink is deprecated.
[2025-06-14T19:19:29.050+0000] {trigger_dagrun.py:210} INFO - Waiting for entrenamiento_modelos_regresion on 2025-06-14 19:19:17.442300+00:00 to become allowed state ['success'] ...
[2025-06-14T19:20:29.453+0000] {trigger_dagrun.py:210} INFO - Waiting for entrenamiento_modelos_regresion on 2025-06-14 19:19:17.442300+00:00 to become allowed state ['success'] ...
[2025-06-14T19:21:29.505+0000] {trigger_dagrun.py:210} INFO - Waiting for entrenamiento_modelos_regresion on 2025-06-14 19:19:17.442300+00:00 to become allowed state ['success'] ...
[2025-06-14T19:22:29.593+0000] {trigger_dagrun.py:210} INFO - Waiting for entrenamiento_modelos_regresion on 2025-06-14 19:19:17.442300+00:00 to become allowed state ['success'] ...
[2025-06-14T19:23:29.660+0000] {trigger_dagrun.py:210} INFO - Waiting for entrenamiento_modelos_regresion on 2025-06-14 19:19:17.442300+00:00 to become allowed state ['success'] ...
[2025-06-14T19:24:29.757+0000] {trigger_dagrun.py:210} INFO - Waiting for entrenamiento_modelos_regresion on 2025-06-14 19:19:17.442300+00:00 to become allowed state ['success'] ...
[2025-06-14T19:25:29.784+0000] {taskinstance.py:2698} ERROR - Task failed with exception
Traceback (most recent call last):
  File "/home/airflow/.local/lib/python3.8/site-packages/airflow/models/taskinstance.py", line 433, in _execute_task
    result = execute_callable(context=context, **execute_callable_kwargs)
  File "/home/airflow/.local/lib/python3.8/site-packages/airflow/operators/trigger_dagrun.py", line 221, in execute
    raise AirflowException(f"{self.trigger_dag_id} failed with failed states {state}")
airflow.exceptions.AirflowException: entrenamiento_modelos_regresion failed with failed states failed
[2025-06-14T19:25:29.788+0000] {taskinstance.py:1138} INFO - Marking task as FAILED. dag_id=scraping_autopia_dag, task_id=trigger_entrenamiento, execution_date=20250614T191508, start_date=20250614T191917, end_date=20250614T192529
[2025-06-14T19:25:29.802+0000] {standard_task_runner.py:107} ERROR - Failed to execute job 118 for task trigger_entrenamiento (entrenamiento_modelos_regresion failed with failed states failed; 1128)
[2025-06-14T19:25:29.852+0000] {local_task_job_runner.py:234} INFO - Task exited with return code 1
[2025-06-14T19:25:29.875+0000] {taskinstance.py:3280} INFO - 0 downstream tasks scheduled from follow-on schedule check
