[2025-05-25T14:58:36.416+0000] {taskinstance.py:1956} INFO - Dependencies all met for dep_context=non-requeueable deps ti=<TaskInstance: entrenamiento_modelos_regresion.entrenar_y_promover scheduled__2025-05-23T21:00:00+00:00 [queued]>
[2025-05-25T14:58:36.429+0000] {taskinstance.py:1956} INFO - Dependencies all met for dep_context=requeueable deps ti=<TaskInstance: entrenamiento_modelos_regresion.entrenar_y_promover scheduled__2025-05-23T21:00:00+00:00 [queued]>
[2025-05-25T14:58:36.429+0000] {taskinstance.py:2170} INFO - Starting attempt 1 of 2
[2025-05-25T14:58:36.455+0000] {taskinstance.py:2191} INFO - Executing <Task(_PythonDecoratedOperator): entrenar_y_promover> on 2025-05-23 21:00:00+00:00
[2025-05-25T14:58:36.464+0000] {standard_task_runner.py:60} INFO - Started process 262 to run task
[2025-05-25T14:58:36.470+0000] {standard_task_runner.py:87} INFO - Running: ['***', 'tasks', 'run', 'entrenamiento_modelos_regresion', 'entrenar_y_promover', 'scheduled__2025-05-23T21:00:00+00:00', '--job-id', '2', '--raw', '--subdir', 'DAGS_FOLDER/entrenamiento_modelos_regresion_dag.py', '--cfg-path', '/tmp/tmpbv0a1226']
[2025-05-25T14:58:36.474+0000] {standard_task_runner.py:88} INFO - Job 2: Subtask entrenar_y_promover
[2025-05-25T14:58:36.593+0000] {task_command.py:423} INFO - Running <TaskInstance: entrenamiento_modelos_regresion.entrenar_y_promover scheduled__2025-05-23T21:00:00+00:00 [running]> on host d0d6dccb390f
[2025-05-25T14:58:36.772+0000] {taskinstance.py:2480} INFO - Exporting env vars: AIRFLOW_CTX_DAG_OWNER='fede' AIRFLOW_CTX_DAG_ID='entrenamiento_modelos_regresion' AIRFLOW_CTX_TASK_ID='entrenar_y_promover' AIRFLOW_CTX_EXECUTION_DATE='2025-05-23T21:00:00+00:00' AIRFLOW_CTX_TRY_NUMBER='1' AIRFLOW_CTX_DAG_RUN_ID='scheduled__2025-05-23T21:00:00+00:00'
[2025-05-25T14:58:41.004+0000] {taskinstance.py:2698} ERROR - Task failed with exception
Traceback (most recent call last):
  File "/home/airflow/.local/lib/python3.8/site-packages/airflow/models/taskinstance.py", line 433, in _execute_task
    result = execute_callable(context=context, **execute_callable_kwargs)
  File "/home/airflow/.local/lib/python3.8/site-packages/airflow/decorators/base.py", line 241, in execute
    return_value = super().execute(context)
  File "/home/airflow/.local/lib/python3.8/site-packages/airflow/operators/python.py", line 199, in execute
    return_value = self.execute_callable()
  File "/home/airflow/.local/lib/python3.8/site-packages/airflow/operators/python.py", line 216, in execute_callable
    return self.python_callable(*self.op_args, **self.op_kwargs)
  File "/opt/airflow/dags/entrenamiento_modelos_regresion_dag.py", line 38, in entrenar_y_promover
    df['Año'] = df['Año'].str.replace(' ', '').astype(int)
  File "/home/airflow/.local/lib/python3.8/site-packages/pandas/core/generic.py", line 5989, in __getattr__
    return object.__getattribute__(self, name)
  File "/home/airflow/.local/lib/python3.8/site-packages/pandas/core/accessor.py", line 224, in __get__
    accessor_obj = self._accessor(obj)
  File "/home/airflow/.local/lib/python3.8/site-packages/pandas/core/strings/accessor.py", line 181, in __init__
    self._inferred_dtype = self._validate(data)
  File "/home/airflow/.local/lib/python3.8/site-packages/pandas/core/strings/accessor.py", line 235, in _validate
    raise AttributeError("Can only use .str accessor with string values!")
AttributeError: Can only use .str accessor with string values!
[2025-05-25T14:58:41.030+0000] {taskinstance.py:1138} INFO - Marking task as UP_FOR_RETRY. dag_id=entrenamiento_modelos_regresion, task_id=entrenar_y_promover, execution_date=20250523T210000, start_date=20250525T145836, end_date=20250525T145841
[2025-05-25T14:58:41.050+0000] {standard_task_runner.py:107} ERROR - Failed to execute job 2 for task entrenar_y_promover (Can only use .str accessor with string values!; 262)
[2025-05-25T14:58:41.083+0000] {local_task_job_runner.py:234} INFO - Task exited with return code 1
[2025-05-25T14:58:41.135+0000] {taskinstance.py:3280} INFO - 0 downstream tasks scheduled from follow-on schedule check
[2025-05-25T17:10:25.671+0000] {taskinstance.py:1956} INFO - Dependencies all met for dep_context=non-requeueable deps ti=<TaskInstance: entrenamiento_modelos_regresion.entrenar_y_promover scheduled__2025-05-23T21:00:00+00:00 [queued]>
[2025-05-25T17:10:25.685+0000] {taskinstance.py:1956} INFO - Dependencies all met for dep_context=requeueable deps ti=<TaskInstance: entrenamiento_modelos_regresion.entrenar_y_promover scheduled__2025-05-23T21:00:00+00:00 [queued]>
[2025-05-25T17:10:25.686+0000] {taskinstance.py:2170} INFO - Starting attempt 1 of 2
[2025-05-25T17:10:25.705+0000] {taskinstance.py:2191} INFO - Executing <Task(_PythonDecoratedOperator): entrenar_y_promover> on 2025-05-23 21:00:00+00:00
[2025-05-25T17:10:25.711+0000] {standard_task_runner.py:60} INFO - Started process 458 to run task
[2025-05-25T17:10:25.716+0000] {standard_task_runner.py:87} INFO - Running: ['***', 'tasks', 'run', 'entrenamiento_modelos_regresion', 'entrenar_y_promover', 'scheduled__2025-05-23T21:00:00+00:00', '--job-id', '3', '--raw', '--subdir', 'DAGS_FOLDER/entrenamiento_modelos_regresion_dag.py', '--cfg-path', '/tmp/tmpaxzm1i_5']
[2025-05-25T17:10:25.719+0000] {standard_task_runner.py:88} INFO - Job 3: Subtask entrenar_y_promover
[2025-05-25T17:10:25.807+0000] {task_command.py:423} INFO - Running <TaskInstance: entrenamiento_modelos_regresion.entrenar_y_promover scheduled__2025-05-23T21:00:00+00:00 [running]> on host ed19f6d183a5
[2025-05-25T17:10:25.953+0000] {taskinstance.py:2480} INFO - Exporting env vars: AIRFLOW_CTX_DAG_OWNER='fede' AIRFLOW_CTX_DAG_ID='entrenamiento_modelos_regresion' AIRFLOW_CTX_TASK_ID='entrenar_y_promover' AIRFLOW_CTX_EXECUTION_DATE='2025-05-23T21:00:00+00:00' AIRFLOW_CTX_TRY_NUMBER='1' AIRFLOW_CTX_DAG_RUN_ID='scheduled__2025-05-23T21:00:00+00:00'
[2025-05-25T17:10:31.281+0000] {logging_mixin.py:188} WARNING - /opt/***/dags/entrenamiento_modelos_regresion_dag.py:52 SettingWithCopyWarning:
A value is trying to be set on a copy of a slice from a DataFrame.
Try using .loc[row_indexer,col_indexer] = value instead

See the caveats in the documentation: https://pandas.pydata.org/pandas-docs/stable/user_guide/indexing.html#returning-a-view-versus-a-copy
[2025-05-25T17:10:31.310+0000] {logging_mixin.py:188} WARNING - /opt/***/dags/entrenamiento_modelos_regresion_dag.py:55 SettingWithCopyWarning:
A value is trying to be set on a copy of a slice from a DataFrame.
Try using .loc[row_indexer,col_indexer] = value instead

See the caveats in the documentation: https://pandas.pydata.org/pandas-docs/stable/user_guide/indexing.html#returning-a-view-versus-a-copy
[2025-05-25T17:10:31.313+0000] {logging_mixin.py:188} WARNING - /opt/***/dags/entrenamiento_modelos_regresion_dag.py:57 SettingWithCopyWarning:
A value is trying to be set on a copy of a slice from a DataFrame.
Try using .loc[row_indexer,col_indexer] = value instead

See the caveats in the documentation: https://pandas.pydata.org/pandas-docs/stable/user_guide/indexing.html#returning-a-view-versus-a-copy
[2025-05-25T17:10:31.315+0000] {logging_mixin.py:188} WARNING - /opt/***/dags/entrenamiento_modelos_regresion_dag.py:59 SettingWithCopyWarning:
A value is trying to be set on a copy of a slice from a DataFrame

See the caveats in the documentation: https://pandas.pydata.org/pandas-docs/stable/user_guide/indexing.html#returning-a-view-versus-a-copy
[2025-05-25T17:10:31.359+0000] {logging_mixin.py:188} WARNING - 2025/05/25 17:10:31 INFO mlflow.tracking.fluent: Experiment with name 'entrenamiento_orquestado' does not exist. Creating a new experiment.
[2025-05-25T17:10:31.390+0000] {taskinstance.py:2698} ERROR - Task failed with exception
Traceback (most recent call last):
  File "/home/airflow/.local/lib/python3.8/site-packages/airflow/models/taskinstance.py", line 433, in _execute_task
    result = execute_callable(context=context, **execute_callable_kwargs)
  File "/home/airflow/.local/lib/python3.8/site-packages/airflow/decorators/base.py", line 241, in execute
    return_value = super().execute(context)
  File "/home/airflow/.local/lib/python3.8/site-packages/airflow/operators/python.py", line 199, in execute
    return_value = self.execute_callable()
  File "/home/airflow/.local/lib/python3.8/site-packages/airflow/operators/python.py", line 216, in execute_callable
    return self.python_callable(*self.op_args, **self.op_kwargs)
  File "/opt/airflow/dags/entrenamiento_modelos_regresion_dag.py", line 64, in entrenar_y_promover
    mlflow.set_experiment("entrenamiento_orquestado")
  File "/home/airflow/.local/lib/python3.8/site-packages/mlflow/tracking/fluent.py", line 154, in set_experiment
    experiment_id = client.create_experiment(experiment_name)
  File "/home/airflow/.local/lib/python3.8/site-packages/mlflow/tracking/client.py", line 1310, in create_experiment
    return self._tracking_client.create_experiment(name, artifact_location, tags)
  File "/home/airflow/.local/lib/python3.8/site-packages/mlflow/tracking/_tracking_service/client.py", line 518, in create_experiment
    return self.store.create_experiment(
  File "/home/airflow/.local/lib/python3.8/site-packages/mlflow/store/tracking/rest_store.py", line 123, in create_experiment
    response_proto = self._call_endpoint(CreateExperiment, req_body)
  File "/home/airflow/.local/lib/python3.8/site-packages/mlflow/store/tracking/rest_store.py", line 82, in _call_endpoint
    return call_endpoint(self.get_host_creds(), endpoint, method, json_body, response_proto)
  File "/home/airflow/.local/lib/python3.8/site-packages/mlflow/utils/rest_utils.py", line 370, in call_endpoint
    response = verify_rest_response(response, endpoint)
  File "/home/airflow/.local/lib/python3.8/site-packages/mlflow/utils/rest_utils.py", line 240, in verify_rest_response
    raise RestException(json.loads(response.text))
mlflow.exceptions.RestException: RESOURCE_ALREADY_EXISTS: Experiment(name=entrenamiento_orquestado) already exists. Error: (raised as a result of Query-invoked autoflush; consider using a session.no_autoflush block if this flush is occurring prematurely)
(sqlite3.IntegrityError) UNIQUE constraint failed: experiments.name
[SQL: INSERT INTO experiments (name, artifact_location, lifecycle_stage, creation_time, last_update_time) VALUES (?, ?, ?, ?, ?)]
[parameters: ('entrenamiento_orquestado', '', 'active', 1748193031366, 1748193031366)]
(Background on this error at: https://sqlalche.me/e/20/gkpj)
[2025-05-25T17:10:31.433+0000] {taskinstance.py:1138} INFO - Marking task as UP_FOR_RETRY. dag_id=entrenamiento_modelos_regresion, task_id=entrenar_y_promover, execution_date=20250523T210000, start_date=20250525T171025, end_date=20250525T171031
[2025-05-25T17:10:31.451+0000] {standard_task_runner.py:107} ERROR - Failed to execute job 3 for task entrenar_y_promover (RESOURCE_ALREADY_EXISTS: Experiment(name=entrenamiento_orquestado) already exists. Error: (raised as a result of Query-invoked autoflush; consider using a session.no_autoflush block if this flush is occurring prematurely)
(sqlite3.IntegrityError) UNIQUE constraint failed: experiments.name
[SQL: INSERT INTO experiments (name, artifact_location, lifecycle_stage, creation_time, last_update_time) VALUES (?, ?, ?, ?, ?)]
[parameters: ('entrenamiento_orquestado', '', 'active', 1748193031366, 1748193031366)]
(Background on this error at: https://sqlalche.me/e/20/gkpj); 458)
[2025-05-25T17:10:31.471+0000] {local_task_job_runner.py:234} INFO - Task exited with return code 1
[2025-05-25T17:10:31.492+0000] {taskinstance.py:3280} INFO - 0 downstream tasks scheduled from follow-on schedule check
