[2025-06-12T19:16:40.907+0000] {taskinstance.py:1956} INFO - Dependencies all met for dep_context=non-requeueable deps ti=<TaskInstance: procesamiento_datos_autopia_dag.trigger_entrenamiento manual__2025-06-12T19:16:33.068969+00:00 [queued]>
[2025-06-12T19:16:40.947+0000] {taskinstance.py:1956} INFO - Dependencies all met for dep_context=requeueable deps ti=<TaskInstance: procesamiento_datos_autopia_dag.trigger_entrenamiento manual__2025-06-12T19:16:33.068969+00:00 [queued]>
[2025-06-12T19:16:40.949+0000] {taskinstance.py:2170} INFO - Starting attempt 1 of 2
[2025-06-12T19:16:41.019+0000] {taskinstance.py:2191} INFO - Executing <Task(TriggerDagRunOperator): trigger_entrenamiento> on 2025-06-12 19:16:33.068969+00:00
[2025-06-12T19:16:41.043+0000] {standard_task_runner.py:60} INFO - Started process 422 to run task
[2025-06-12T19:16:41.059+0000] {standard_task_runner.py:87} INFO - Running: ['***', 'tasks', 'run', 'procesamiento_datos_autopia_dag', 'trigger_entrenamiento', 'manual__2025-06-12T19:16:33.068969+00:00', '--job-id', '42', '--raw', '--subdir', 'DAGS_FOLDER/procesamiento_datos_autopia_dag.py', '--cfg-path', '/tmp/tmp7ra7kquh']
[2025-06-12T19:16:41.065+0000] {standard_task_runner.py:88} INFO - Job 42: Subtask trigger_entrenamiento
[2025-06-12T19:16:41.199+0000] {task_command.py:423} INFO - Running <TaskInstance: procesamiento_datos_autopia_dag.trigger_entrenamiento manual__2025-06-12T19:16:33.068969+00:00 [running]> on host 24edc8b790cf
[2025-06-12T19:16:41.397+0000] {taskinstance.py:2480} INFO - Exporting env vars: AIRFLOW_CTX_DAG_OWNER='fede' AIRFLOW_CTX_DAG_ID='procesamiento_datos_autopia_dag' AIRFLOW_CTX_TASK_ID='trigger_entrenamiento' AIRFLOW_CTX_EXECUTION_DATE='2025-06-12T19:16:33.068969+00:00' AIRFLOW_CTX_TRY_NUMBER='1' AIRFLOW_CTX_DAG_RUN_ID='manual__2025-06-12T19:16:33.068969+00:00'
[2025-06-12T19:16:45.327+0000] {logging_mixin.py:188} WARNING - /home/***/.local/lib/python3.8/site-packages/***/providers/google/cloud/links/dataproc.py:79 AirflowProviderDeprecationWarning: This DataprocLink is deprecated.
[2025-06-12T19:16:45.332+0000] {logging_mixin.py:188} WARNING - /home/***/.local/lib/python3.8/site-packages/***/providers/google/cloud/links/dataproc.py:128 AirflowProviderDeprecationWarning: This DataprocListLink is deprecated.
[2025-06-12T19:16:47.917+0000] {trigger_dagrun.py:210} INFO - Waiting for entrenamiento_modelos_regresion on 2025-06-12 19:16:41.399111+00:00 to become allowed state ['success'] ...
[2025-06-12T19:17:45.353+0000] {trigger_dagrun.py:210} INFO - Waiting for entrenamiento_modelos_regresion on 2025-06-12 19:16:41.399111+00:00 to become allowed state ['success'] ...
[2025-06-12T19:18:42.891+0000] {trigger_dagrun.py:210} INFO - Waiting for entrenamiento_modelos_regresion on 2025-06-12 19:16:41.399111+00:00 to become allowed state ['success'] ...
[2025-06-12T19:19:40.424+0000] {trigger_dagrun.py:210} INFO - Waiting for entrenamiento_modelos_regresion on 2025-06-12 19:16:41.399111+00:00 to become allowed state ['success'] ...
[2025-06-12T19:20:37.978+0000] {trigger_dagrun.py:210} INFO - Waiting for entrenamiento_modelos_regresion on 2025-06-12 19:16:41.399111+00:00 to become allowed state ['success'] ...
[2025-06-12T19:21:35.573+0000] {trigger_dagrun.py:210} INFO - Waiting for entrenamiento_modelos_regresion on 2025-06-12 19:16:41.399111+00:00 to become allowed state ['success'] ...
[2025-06-12T19:22:33.135+0000] {taskinstance.py:2698} ERROR - Task failed with exception
Traceback (most recent call last):
  File "/home/airflow/.local/lib/python3.8/site-packages/airflow/models/taskinstance.py", line 433, in _execute_task
    result = execute_callable(context=context, **execute_callable_kwargs)
  File "/home/airflow/.local/lib/python3.8/site-packages/airflow/operators/trigger_dagrun.py", line 221, in execute
    raise AirflowException(f"{self.trigger_dag_id} failed with failed states {state}")
airflow.exceptions.AirflowException: entrenamiento_modelos_regresion failed with failed states failed
[2025-06-12T19:22:33.147+0000] {taskinstance.py:1138} INFO - Marking task as UP_FOR_RETRY. dag_id=procesamiento_datos_autopia_dag, task_id=trigger_entrenamiento, execution_date=20250612T191633, start_date=20250612T191640, end_date=20250612T192233
[2025-06-12T19:22:33.201+0000] {standard_task_runner.py:107} ERROR - Failed to execute job 42 for task trigger_entrenamiento (entrenamiento_modelos_regresion failed with failed states failed; 422)
[2025-06-12T19:22:33.360+0000] {local_task_job_runner.py:234} INFO - Task exited with return code 1
[2025-06-12T19:22:33.594+0000] {taskinstance.py:3280} INFO - 0 downstream tasks scheduled from follow-on schedule check
