[2025-06-17T22:49:46.297+0000] {taskinstance.py:1956} INFO - Dependencies all met for dep_context=non-requeueable deps ti=<TaskInstance: prediccion_modelo_produccion_dag.predecir scheduled__2025-06-16T22:00:00+00:00 [queued]>
[2025-06-17T22:49:46.311+0000] {taskinstance.py:1956} INFO - Dependencies all met for dep_context=requeueable deps ti=<TaskInstance: prediccion_modelo_produccion_dag.predecir scheduled__2025-06-16T22:00:00+00:00 [queued]>
[2025-06-17T22:49:46.312+0000] {taskinstance.py:2170} INFO - Starting attempt 1 of 2
[2025-06-17T22:49:46.335+0000] {taskinstance.py:2191} INFO - Executing <Task(_PythonDecoratedOperator): predecir> on 2025-06-16 22:00:00+00:00
[2025-06-17T22:49:46.343+0000] {standard_task_runner.py:60} INFO - Started process 203 to run task
[2025-06-17T22:49:46.352+0000] {standard_task_runner.py:87} INFO - Running: ['***', 'tasks', 'run', 'prediccion_modelo_produccion_dag', 'predecir', 'scheduled__2025-06-16T22:00:00+00:00', '--job-id', '212', '--raw', '--subdir', 'DAGS_FOLDER/prediccion_modelo_produccion_dag.py', '--cfg-path', '/tmp/tmpm17pnqts']
[2025-06-17T22:49:46.357+0000] {standard_task_runner.py:88} INFO - Job 212: Subtask predecir
[2025-06-17T22:49:46.613+0000] {task_command.py:423} INFO - Running <TaskInstance: prediccion_modelo_produccion_dag.predecir scheduled__2025-06-16T22:00:00+00:00 [running]> on host cdfb22e6be80
[2025-06-17T22:49:46.815+0000] {taskinstance.py:2480} INFO - Exporting env vars: AIRFLOW_CTX_DAG_OWNER='fede' AIRFLOW_CTX_DAG_ID='prediccion_modelo_produccion_dag' AIRFLOW_CTX_TASK_ID='predecir' AIRFLOW_CTX_EXECUTION_DATE='2025-06-16T22:00:00+00:00' AIRFLOW_CTX_TRY_NUMBER='1' AIRFLOW_CTX_DAG_RUN_ID='scheduled__2025-06-16T22:00:00+00:00'
[2025-06-17T22:49:51.046+0000] {logging_mixin.py:188} WARNING - /home/***/.local/lib/python3.8/site-packages/mlflow/store/artifact/utils/models.py:31 FutureWarning: ``mlflow.tracking.client.MlflowClient.get_latest_versions`` is deprecated since 2.9.0. Model registry stages will be removed in a future major release. To learn more about the deprecation of model registry stages, see our migration guide here: https://mlflow.org/docs/latest/model-registry.html#migrating-from-stages
[2025-06-17T22:49:54.897+0000] {connectionpool.py:824} WARNING - Retrying (JitteredRetry(total=4, connect=4, read=5, redirect=5, status=5)) after connection broken by 'NewConnectionError('<urllib3.connection.HTTPConnection object at 0x7587035cd4c0>: Failed to establish a new connection: [Errno -2] Name or service not known')': /api/2.0/mlflow/registered-models/get-latest-versions
[2025-06-17T22:50:02.541+0000] {connectionpool.py:824} WARNING - Retrying (JitteredRetry(total=3, connect=3, read=5, redirect=5, status=5)) after connection broken by 'NewConnectionError('<urllib3.connection.HTTPConnection object at 0x7587035cd220>: Failed to establish a new connection: [Errno -2] Name or service not known')': /api/2.0/mlflow/registered-models/get-latest-versions
[2025-06-17T22:50:12.003+0000] {connectionpool.py:824} WARNING - Retrying (JitteredRetry(total=2, connect=2, read=5, redirect=5, status=5)) after connection broken by 'NewConnectionError('<urllib3.connection.HTTPConnection object at 0x7587035d49d0>: Failed to establish a new connection: [Errno -2] Name or service not known')': /api/2.0/mlflow/registered-models/get-latest-versions
[2025-06-17T22:50:29.396+0000] {connectionpool.py:824} WARNING - Retrying (JitteredRetry(total=1, connect=1, read=5, redirect=5, status=5)) after connection broken by 'NewConnectionError('<urllib3.connection.HTTPConnection object at 0x7587035d4bb0>: Failed to establish a new connection: [Errno -2] Name or service not known')': /api/2.0/mlflow/registered-models/get-latest-versions
[2025-06-17T22:51:02.769+0000] {connectionpool.py:824} WARNING - Retrying (JitteredRetry(total=0, connect=0, read=5, redirect=5, status=5)) after connection broken by 'NewConnectionError('<urllib3.connection.HTTPConnection object at 0x7587035d4880>: Failed to establish a new connection: [Errno -2] Name or service not known')': /api/2.0/mlflow/registered-models/get-latest-versions
[2025-06-17T22:51:06.485+0000] {taskinstance.py:2698} ERROR - Task failed with exception
Traceback (most recent call last):
  File "/home/airflow/.local/lib/python3.8/site-packages/urllib3/connection.py", line 174, in _new_conn
    conn = connection.create_connection(
  File "/home/airflow/.local/lib/python3.8/site-packages/urllib3/util/connection.py", line 72, in create_connection
    for res in socket.getaddrinfo(host, port, family, socket.SOCK_STREAM):
  File "/usr/local/lib/python3.8/socket.py", line 918, in getaddrinfo
    for res in _socket.getaddrinfo(host, port, family, type, proto, flags):
socket.gaierror: [Errno -2] Name or service not known

During handling of the above exception, another exception occurred:

Traceback (most recent call last):
  File "/home/airflow/.local/lib/python3.8/site-packages/urllib3/connectionpool.py", line 715, in urlopen
    httplib_response = self._make_request(
  File "/home/airflow/.local/lib/python3.8/site-packages/urllib3/connectionpool.py", line 416, in _make_request
    conn.request(method, url, **httplib_request_kw)
  File "/home/airflow/.local/lib/python3.8/site-packages/urllib3/connection.py", line 244, in request
    super(HTTPConnection, self).request(method, url, body=body, headers=headers)
  File "/usr/local/lib/python3.8/http/client.py", line 1256, in request
    self._send_request(method, url, body, headers, encode_chunked)
  File "/usr/local/lib/python3.8/http/client.py", line 1302, in _send_request
    self.endheaders(body, encode_chunked=encode_chunked)
  File "/usr/local/lib/python3.8/http/client.py", line 1251, in endheaders
    self._send_output(message_body, encode_chunked=encode_chunked)
  File "/usr/local/lib/python3.8/http/client.py", line 1011, in _send_output
    self.send(msg)
  File "/usr/local/lib/python3.8/http/client.py", line 951, in send
    self.connect()
  File "/home/airflow/.local/lib/python3.8/site-packages/urllib3/connection.py", line 205, in connect
    conn = self._new_conn()
  File "/home/airflow/.local/lib/python3.8/site-packages/urllib3/connection.py", line 186, in _new_conn
    raise NewConnectionError(
urllib3.exceptions.NewConnectionError: <urllib3.connection.HTTPConnection object at 0x7587035d4730>: Failed to establish a new connection: [Errno -2] Name or service not known

During handling of the above exception, another exception occurred:

Traceback (most recent call last):
  File "/home/airflow/.local/lib/python3.8/site-packages/requests/adapters.py", line 486, in send
    resp = conn.urlopen(
  File "/home/airflow/.local/lib/python3.8/site-packages/urllib3/connectionpool.py", line 827, in urlopen
    return self.urlopen(
  File "/home/airflow/.local/lib/python3.8/site-packages/urllib3/connectionpool.py", line 827, in urlopen
    return self.urlopen(
  File "/home/airflow/.local/lib/python3.8/site-packages/urllib3/connectionpool.py", line 827, in urlopen
    return self.urlopen(
  [Previous line repeated 2 more times]
  File "/home/airflow/.local/lib/python3.8/site-packages/urllib3/connectionpool.py", line 799, in urlopen
    retries = retries.increment(
  File "/home/airflow/.local/lib/python3.8/site-packages/urllib3/util/retry.py", line 592, in increment
    raise MaxRetryError(_pool, url, error or ResponseError(cause))
urllib3.exceptions.MaxRetryError: HTTPConnectionPool(host='mlflow', port=5000): Max retries exceeded with url: /api/2.0/mlflow/registered-models/get-latest-versions (Caused by NewConnectionError('<urllib3.connection.HTTPConnection object at 0x7587035d4730>: Failed to establish a new connection: [Errno -2] Name or service not known'))

During handling of the above exception, another exception occurred:

Traceback (most recent call last):
  File "/home/airflow/.local/lib/python3.8/site-packages/mlflow/utils/rest_utils.py", line 189, in http_request
    return _get_http_response_with_retries(
  File "/home/airflow/.local/lib/python3.8/site-packages/mlflow/utils/request_utils.py", line 237, in _get_http_response_with_retries
    return session.request(method, url, allow_redirects=allow_redirects, **kwargs)
  File "/home/airflow/.local/lib/python3.8/site-packages/requests/sessions.py", line 589, in request
    resp = self.send(prep, **send_kwargs)
  File "/home/airflow/.local/lib/python3.8/site-packages/requests/sessions.py", line 703, in send
    r = adapter.send(request, **kwargs)
  File "/home/airflow/.local/lib/python3.8/site-packages/requests/adapters.py", line 519, in send
    raise ConnectionError(e, request=request)
requests.exceptions.ConnectionError: HTTPConnectionPool(host='mlflow', port=5000): Max retries exceeded with url: /api/2.0/mlflow/registered-models/get-latest-versions (Caused by NewConnectionError('<urllib3.connection.HTTPConnection object at 0x7587035d4730>: Failed to establish a new connection: [Errno -2] Name or service not known'))

During handling of the above exception, another exception occurred:

Traceback (most recent call last):
  File "/home/airflow/.local/lib/python3.8/site-packages/airflow/models/taskinstance.py", line 433, in _execute_task
    result = execute_callable(context=context, **execute_callable_kwargs)
  File "/home/airflow/.local/lib/python3.8/site-packages/airflow/decorators/base.py", line 241, in execute
    return_value = super().execute(context)
  File "/home/airflow/.local/lib/python3.8/site-packages/airflow/operators/python.py", line 199, in execute
    return_value = self.execute_callable()
  File "/home/airflow/.local/lib/python3.8/site-packages/airflow/operators/python.py", line 216, in execute_callable
    return self.python_callable(*self.op_args, **self.op_kwargs)
  File "/opt/airflow/dags/prediccion_modelo_produccion_dag.py", line 49, in predecir
    model = mlflow.sklearn.load_model(f"models:/{model_name}/{stage}")
  File "/home/airflow/.local/lib/python3.8/site-packages/mlflow/sklearn/__init__.py", line 633, in load_model
    local_model_path = _download_artifact_from_uri(artifact_uri=model_uri, output_path=dst_path)
  File "/home/airflow/.local/lib/python3.8/site-packages/mlflow/tracking/artifact_utils.py", line 108, in _download_artifact_from_uri
    repo = get_artifact_repository(artifact_uri=root_uri)
  File "/home/airflow/.local/lib/python3.8/site-packages/mlflow/store/artifact/artifact_repository_registry.py", line 132, in get_artifact_repository
    return _artifact_repository_registry.get_artifact_repository(artifact_uri)
  File "/home/airflow/.local/lib/python3.8/site-packages/mlflow/store/artifact/artifact_repository_registry.py", line 77, in get_artifact_repository
    return repository(artifact_uri)
  File "/home/airflow/.local/lib/python3.8/site-packages/mlflow/store/artifact/models_artifact_repo.py", line 69, in __init__
    ) = ModelsArtifactRepository._get_model_uri_infos(artifact_uri)
  File "/home/airflow/.local/lib/python3.8/site-packages/mlflow/store/artifact/models_artifact_repo.py", line 103, in _get_model_uri_infos
    name, version = get_model_name_and_version(client, uri)
  File "/home/airflow/.local/lib/python3.8/site-packages/mlflow/store/artifact/utils/models.py", line 93, in get_model_name_and_version
    return model_name, str(_get_latest_model_version(client, model_name, model_stage))
  File "/home/airflow/.local/lib/python3.8/site-packages/mlflow/store/artifact/utils/models.py", line 31, in _get_latest_model_version
    latest = client.get_latest_versions(name, None if stage is None else [stage])
  File "/home/airflow/.local/lib/python3.8/site-packages/mlflow/utils/annotations.py", line 145, in deprecated_func
    return func(*args, **kwargs)
  File "/home/airflow/.local/lib/python3.8/site-packages/mlflow/tracking/client.py", line 3487, in get_latest_versions
    return self._get_registry_client().get_latest_versions(name, stages)
  File "/home/airflow/.local/lib/python3.8/site-packages/mlflow/tracking/_model_registry/client.py", line 153, in get_latest_versions
    return self.store.get_latest_versions(name, stages)
  File "/home/airflow/.local/lib/python3.8/site-packages/mlflow/store/model_registry/rest_store.py", line 193, in get_latest_versions
    response_proto = self._call_endpoint(GetLatestVersions, req_body, call_all_endpoints=True)
  File "/home/airflow/.local/lib/python3.8/site-packages/mlflow/store/model_registry/base_rest_store.py", line 39, in _call_endpoint
    return call_endpoints(
  File "/home/airflow/.local/lib/python3.8/site-packages/mlflow/utils/rest_utils.py", line 382, in call_endpoints
    return call_endpoint(
  File "/home/airflow/.local/lib/python3.8/site-packages/mlflow/utils/rest_utils.py", line 368, in call_endpoint
    response = http_request(**call_kwargs)
  File "/home/airflow/.local/lib/python3.8/site-packages/mlflow/utils/rest_utils.py", line 212, in http_request
    raise MlflowException(f"API request to {url} failed with exception {e}")
mlflow.exceptions.MlflowException: API request to http://mlflow:5000/api/2.0/mlflow/registered-models/get-latest-versions failed with exception HTTPConnectionPool(host='mlflow', port=5000): Max retries exceeded with url: /api/2.0/mlflow/registered-models/get-latest-versions (Caused by NewConnectionError('<urllib3.connection.HTTPConnection object at 0x7587035d4730>: Failed to establish a new connection: [Errno -2] Name or service not known'))
[2025-06-17T22:51:06.620+0000] {taskinstance.py:1138} INFO - Marking task as UP_FOR_RETRY. dag_id=prediccion_modelo_produccion_dag, task_id=predecir, execution_date=20250616T220000, start_date=20250617T224946, end_date=20250617T225106
[2025-06-17T22:51:06.682+0000] {standard_task_runner.py:107} ERROR - Failed to execute job 212 for task predecir (API request to http://mlflow:5000/api/2.0/mlflow/registered-models/get-latest-versions failed with exception HTTPConnectionPool(host='mlflow', port=5000): Max retries exceeded with url: /api/2.0/mlflow/registered-models/get-latest-versions (Caused by NewConnectionError('<urllib3.connection.HTTPConnection object at 0x7587035d4730>: Failed to establish a new connection: [Errno -2] Name or service not known')); 203)
[2025-06-17T22:51:06.796+0000] {local_task_job_runner.py:234} INFO - Task exited with return code 1
[2025-06-17T22:51:06.883+0000] {taskinstance.py:3280} INFO - 0 downstream tasks scheduled from follow-on schedule check
[2025-06-18T00:55:47.599+0000] {taskinstance.py:1956} INFO - Dependencies all met for dep_context=non-requeueable deps ti=<TaskInstance: prediccion_modelo_produccion_dag.predecir scheduled__2025-06-16T22:00:00+00:00 [queued]>
[2025-06-18T00:55:47.610+0000] {taskinstance.py:1956} INFO - Dependencies all met for dep_context=requeueable deps ti=<TaskInstance: prediccion_modelo_produccion_dag.predecir scheduled__2025-06-16T22:00:00+00:00 [queued]>
[2025-06-18T00:55:47.610+0000] {taskinstance.py:2170} INFO - Starting attempt 1 of 2
[2025-06-18T00:55:47.625+0000] {taskinstance.py:2191} INFO - Executing <Task(_PythonDecoratedOperator): predecir> on 2025-06-16 22:00:00+00:00
[2025-06-18T00:55:47.630+0000] {standard_task_runner.py:60} INFO - Started process 467 to run task
[2025-06-18T00:55:47.634+0000] {standard_task_runner.py:87} INFO - Running: ['***', 'tasks', 'run', 'prediccion_modelo_produccion_dag', 'predecir', 'scheduled__2025-06-16T22:00:00+00:00', '--job-id', '3', '--raw', '--subdir', 'DAGS_FOLDER/prediccion_modelo_produccion_dag.py', '--cfg-path', '/tmp/tmpa4jturuk']
[2025-06-18T00:55:47.637+0000] {standard_task_runner.py:88} INFO - Job 3: Subtask predecir
[2025-06-18T00:55:47.715+0000] {task_command.py:423} INFO - Running <TaskInstance: prediccion_modelo_produccion_dag.predecir scheduled__2025-06-16T22:00:00+00:00 [running]> on host 7e38bae46728
[2025-06-18T00:55:47.834+0000] {taskinstance.py:2480} INFO - Exporting env vars: AIRFLOW_CTX_DAG_OWNER='fede' AIRFLOW_CTX_DAG_ID='prediccion_modelo_produccion_dag' AIRFLOW_CTX_TASK_ID='predecir' AIRFLOW_CTX_EXECUTION_DATE='2025-06-16T22:00:00+00:00' AIRFLOW_CTX_TRY_NUMBER='1' AIRFLOW_CTX_DAG_RUN_ID='scheduled__2025-06-16T22:00:00+00:00'
[2025-06-18T00:55:49.778+0000] {logging_mixin.py:188} WARNING - /home/***/.local/lib/python3.8/site-packages/mlflow/store/artifact/utils/models.py:31 FutureWarning: ``mlflow.tracking.client.MlflowClient.get_latest_versions`` is deprecated since 2.9.0. Model registry stages will be removed in a future major release. To learn more about the deprecation of model registry stages, see our migration guide here: https://mlflow.org/docs/latest/model-registry.html#migrating-from-stages
[2025-06-18T00:55:50.346+0000] {taskinstance.py:2698} ERROR - Task failed with exception
Traceback (most recent call last):
  File "/home/airflow/.local/lib/python3.8/site-packages/airflow/models/taskinstance.py", line 433, in _execute_task
    result = execute_callable(context=context, **execute_callable_kwargs)
  File "/home/airflow/.local/lib/python3.8/site-packages/airflow/decorators/base.py", line 241, in execute
    return_value = super().execute(context)
  File "/home/airflow/.local/lib/python3.8/site-packages/airflow/operators/python.py", line 199, in execute
    return_value = self.execute_callable()
  File "/home/airflow/.local/lib/python3.8/site-packages/airflow/operators/python.py", line 216, in execute_callable
    return self.python_callable(*self.op_args, **self.op_kwargs)
  File "/opt/airflow/dags/prediccion_modelo_produccion_dag.py", line 53, in predecir
    model = mlflow.sklearn.load_model(f"models:/{model_name}/{stage}")
  File "/home/airflow/.local/lib/python3.8/site-packages/mlflow/sklearn/__init__.py", line 633, in load_model
    local_model_path = _download_artifact_from_uri(artifact_uri=model_uri, output_path=dst_path)
  File "/home/airflow/.local/lib/python3.8/site-packages/mlflow/tracking/artifact_utils.py", line 108, in _download_artifact_from_uri
    repo = get_artifact_repository(artifact_uri=root_uri)
  File "/home/airflow/.local/lib/python3.8/site-packages/mlflow/store/artifact/artifact_repository_registry.py", line 132, in get_artifact_repository
    return _artifact_repository_registry.get_artifact_repository(artifact_uri)
  File "/home/airflow/.local/lib/python3.8/site-packages/mlflow/store/artifact/artifact_repository_registry.py", line 77, in get_artifact_repository
    return repository(artifact_uri)
  File "/home/airflow/.local/lib/python3.8/site-packages/mlflow/store/artifact/models_artifact_repo.py", line 69, in __init__
    ) = ModelsArtifactRepository._get_model_uri_infos(artifact_uri)
  File "/home/airflow/.local/lib/python3.8/site-packages/mlflow/store/artifact/models_artifact_repo.py", line 103, in _get_model_uri_infos
    name, version = get_model_name_and_version(client, uri)
  File "/home/airflow/.local/lib/python3.8/site-packages/mlflow/store/artifact/utils/models.py", line 93, in get_model_name_and_version
    return model_name, str(_get_latest_model_version(client, model_name, model_stage))
  File "/home/airflow/.local/lib/python3.8/site-packages/mlflow/store/artifact/utils/models.py", line 31, in _get_latest_model_version
    latest = client.get_latest_versions(name, None if stage is None else [stage])
  File "/home/airflow/.local/lib/python3.8/site-packages/mlflow/utils/annotations.py", line 145, in deprecated_func
    return func(*args, **kwargs)
  File "/home/airflow/.local/lib/python3.8/site-packages/mlflow/tracking/client.py", line 3487, in get_latest_versions
    return self._get_registry_client().get_latest_versions(name, stages)
  File "/home/airflow/.local/lib/python3.8/site-packages/mlflow/tracking/_model_registry/client.py", line 153, in get_latest_versions
    return self.store.get_latest_versions(name, stages)
  File "/home/airflow/.local/lib/python3.8/site-packages/mlflow/store/model_registry/rest_store.py", line 193, in get_latest_versions
    response_proto = self._call_endpoint(GetLatestVersions, req_body, call_all_endpoints=True)
  File "/home/airflow/.local/lib/python3.8/site-packages/mlflow/store/model_registry/base_rest_store.py", line 39, in _call_endpoint
    return call_endpoints(
  File "/home/airflow/.local/lib/python3.8/site-packages/mlflow/utils/rest_utils.py", line 387, in call_endpoints
    raise e
  File "/home/airflow/.local/lib/python3.8/site-packages/mlflow/utils/rest_utils.py", line 382, in call_endpoints
    return call_endpoint(
  File "/home/airflow/.local/lib/python3.8/site-packages/mlflow/utils/rest_utils.py", line 370, in call_endpoint
    response = verify_rest_response(response, endpoint)
  File "/home/airflow/.local/lib/python3.8/site-packages/mlflow/utils/rest_utils.py", line 240, in verify_rest_response
    raise RestException(json.loads(response.text))
mlflow.exceptions.RestException: RESOURCE_DOES_NOT_EXIST: Registered Model with name=mejor_modelo_orquestado not found
[2025-06-18T00:55:50.373+0000] {taskinstance.py:1138} INFO - Marking task as UP_FOR_RETRY. dag_id=prediccion_modelo_produccion_dag, task_id=predecir, execution_date=20250616T220000, start_date=20250618T005547, end_date=20250618T005550
[2025-06-18T00:55:50.394+0000] {standard_task_runner.py:107} ERROR - Failed to execute job 3 for task predecir (RESOURCE_DOES_NOT_EXIST: Registered Model with name=mejor_modelo_orquestado not found; 467)
[2025-06-18T00:55:50.426+0000] {local_task_job_runner.py:234} INFO - Task exited with return code 1
[2025-06-18T00:55:50.451+0000] {taskinstance.py:3280} INFO - 0 downstream tasks scheduled from follow-on schedule check
