[2025-06-14T19:38:35.822+0000] {taskinstance.py:1956} INFO - Dependencies all met for dep_context=non-requeueable deps ti=<TaskInstance: entrenamiento_modelos_regresion.entrenar_y_promover manual__2025-06-14T19:33:20.380833+00:00 [queued]>
[2025-06-14T19:38:35.851+0000] {taskinstance.py:1956} INFO - Dependencies all met for dep_context=requeueable deps ti=<TaskInstance: entrenamiento_modelos_regresion.entrenar_y_promover manual__2025-06-14T19:33:20.380833+00:00 [queued]>
[2025-06-14T19:38:35.852+0000] {taskinstance.py:2170} INFO - Starting attempt 2 of 2
[2025-06-14T19:38:35.903+0000] {taskinstance.py:2191} INFO - Executing <Task(_PythonDecoratedOperator): entrenar_y_promover> on 2025-06-14 19:33:20.380833+00:00
[2025-06-14T19:38:35.920+0000] {standard_task_runner.py:60} INFO - Started process 2406 to run task
[2025-06-14T19:38:35.935+0000] {standard_task_runner.py:87} INFO - Running: ['***', 'tasks', 'run', 'entrenamiento_modelos_regresion', 'entrenar_y_promover', 'manual__2025-06-14T19:33:20.380833+00:00', '--job-id', '129', '--raw', '--subdir', 'DAGS_FOLDER/entrenamiento_modelos_regresion_dag.py', '--cfg-path', '/tmp/tmp3wmjjv9h']
[2025-06-14T19:38:35.944+0000] {standard_task_runner.py:88} INFO - Job 129: Subtask entrenar_y_promover
[2025-06-14T19:38:36.192+0000] {task_command.py:423} INFO - Running <TaskInstance: entrenamiento_modelos_regresion.entrenar_y_promover manual__2025-06-14T19:33:20.380833+00:00 [running]> on host 15346582a165
[2025-06-14T19:38:36.627+0000] {taskinstance.py:2480} INFO - Exporting env vars: AIRFLOW_CTX_DAG_OWNER='fede' AIRFLOW_CTX_DAG_ID='entrenamiento_modelos_regresion' AIRFLOW_CTX_TASK_ID='entrenar_y_promover' AIRFLOW_CTX_EXECUTION_DATE='2025-06-14T19:33:20.380833+00:00' AIRFLOW_CTX_TRY_NUMBER='2' AIRFLOW_CTX_DAG_RUN_ID='manual__2025-06-14T19:33:20.380833+00:00'
[2025-06-14T19:38:37.214+0000] {local_task_job_runner.py:121} ERROR - Received SIGTERM. Terminating subprocesses
[2025-06-14T19:38:37.220+0000] {process_utils.py:131} INFO - Sending 15 to group 2406. PIDs of all processes in the group: [2406]
[2025-06-14T19:38:37.221+0000] {process_utils.py:86} INFO - Sending the signal 15 to group 2406
[2025-06-14T19:38:37.592+0000] {taskinstance.py:2450} ERROR - Received SIGTERM. Terminating subprocesses.
[2025-06-14T19:38:37.619+0000] {taskinstance.py:2698} ERROR - Task failed with exception
Traceback (most recent call last):
  File "/home/airflow/.local/lib/python3.8/site-packages/airflow/models/taskinstance.py", line 433, in _execute_task
    result = execute_callable(context=context, **execute_callable_kwargs)
  File "/home/airflow/.local/lib/python3.8/site-packages/airflow/decorators/base.py", line 241, in execute
    return_value = super().execute(context)
  File "/home/airflow/.local/lib/python3.8/site-packages/airflow/operators/python.py", line 199, in execute
    return_value = self.execute_callable()
  File "/home/airflow/.local/lib/python3.8/site-packages/airflow/operators/python.py", line 216, in execute_callable
    return self.python_callable(*self.op_args, **self.op_kwargs)
  File "/opt/airflow/dags/entrenamiento_modelos_regresion_dag.py", line 37, in entrenar_y_promover
    import pandas as pd
  File "/home/airflow/.local/lib/python3.8/site-packages/pandas/__init__.py", line 48, in <module>
    from pandas.core.api import (
  File "/home/airflow/.local/lib/python3.8/site-packages/pandas/core/api.py", line 47, in <module>
    from pandas.core.groupby import (
  File "/home/airflow/.local/lib/python3.8/site-packages/pandas/core/groupby/__init__.py", line 1, in <module>
    from pandas.core.groupby.generic import (
  File "/home/airflow/.local/lib/python3.8/site-packages/pandas/core/groupby/generic.py", line 77, in <module>
    from pandas.core.frame import DataFrame
  File "/home/airflow/.local/lib/python3.8/site-packages/pandas/core/frame.py", line 182, in <module>
    from pandas.core.generic import NDFrame
  File "/home/airflow/.local/lib/python3.8/site-packages/pandas/core/generic.py", line 138, in <module>
    from pandas.core import (
  File "/home/airflow/.local/lib/python3.8/site-packages/pandas/core/indexing.py", line 77, in <module>
    from pandas.core.indexes.api import (
  File "/home/airflow/.local/lib/python3.8/site-packages/pandas/core/indexes/api.py", line 27, in <module>
    from pandas.core.indexes.interval import IntervalIndex
  File "/home/airflow/.local/lib/python3.8/site-packages/pandas/core/indexes/interval.py", line 89, in <module>
    from pandas.core.indexes.multi import MultiIndex
  File "<frozen importlib._bootstrap>", line 991, in _find_and_load
  File "<frozen importlib._bootstrap>", line 975, in _find_and_load_unlocked
  File "<frozen importlib._bootstrap>", line 671, in _load_unlocked
  File "<frozen importlib._bootstrap_external>", line 839, in exec_module
  File "<frozen importlib._bootstrap_external>", line 971, in get_code
  File "<frozen importlib._bootstrap_external>", line 640, in _compile_bytecode
  File "/home/airflow/.local/lib/python3.8/site-packages/airflow/models/taskinstance.py", line 2452, in signal_handler
    raise AirflowException("Task received SIGTERM signal")
airflow.exceptions.AirflowException: Task received SIGTERM signal
[2025-06-14T19:38:37.658+0000] {taskinstance.py:1138} INFO - Marking task as FAILED. dag_id=entrenamiento_modelos_regresion, task_id=entrenar_y_promover, execution_date=20250614T193320, start_date=20250614T193835, end_date=20250614T193837
[2025-06-14T19:38:37.696+0000] {standard_task_runner.py:107} ERROR - Failed to execute job 129 for task entrenar_y_promover (Task received SIGTERM signal; 2406)
[2025-06-14T19:38:37.745+0000] {process_utils.py:79} INFO - Process psutil.Process(pid=2406, status='terminated', exitcode=1, started='19:38:35') (2406) terminated with exit code 1
[2025-06-14T19:38:37.747+0000] {local_task_job_runner.py:234} INFO - Task exited with return code 143
[2025-06-14T19:38:37.806+0000] {taskinstance.py:3280} INFO - 0 downstream tasks scheduled from follow-on schedule check
[2025-06-14T19:38:40.246+0000] {local_task_job_runner.py:121} ERROR - Received SIGTERM. Terminating subprocesses
[2025-06-14T19:38:40.247+0000] {local_task_job_runner.py:234} INFO - Task exited with return code 143
