[2025-05-25T16:09:08.326+0000] {taskinstance.py:1956} INFO - Dependencies all met for dep_context=non-requeueable deps ti=<TaskInstance: entrenamiento_modelos_regresion.entrenar_y_promover manual__2025-05-25T16:00:47.056173+00:00 [queued]>
[2025-05-25T16:09:08.362+0000] {taskinstance.py:1956} INFO - Dependencies all met for dep_context=requeueable deps ti=<TaskInstance: entrenamiento_modelos_regresion.entrenar_y_promover manual__2025-05-25T16:00:47.056173+00:00 [queued]>
[2025-05-25T16:09:08.363+0000] {taskinstance.py:2170} INFO - Starting attempt 2 of 2
[2025-05-25T16:09:08.422+0000] {taskinstance.py:2191} INFO - Executing <Task(_PythonDecoratedOperator): entrenar_y_promover> on 2025-05-25 16:00:47.056173+00:00
[2025-05-25T16:09:08.434+0000] {standard_task_runner.py:60} INFO - Started process 187 to run task
[2025-05-25T16:09:08.448+0000] {standard_task_runner.py:87} INFO - Running: ['***', 'tasks', 'run', 'entrenamiento_modelos_regresion', 'entrenar_y_promover', 'manual__2025-05-25T16:00:47.056173+00:00', '--job-id', '16', '--raw', '--subdir', 'DAGS_FOLDER/entrenamiento_modelos_regresion_dag.py', '--cfg-path', '/tmp/tmpsmak5fay']
[2025-05-25T16:09:08.457+0000] {standard_task_runner.py:88} INFO - Job 16: Subtask entrenar_y_promover
[2025-05-25T16:09:08.696+0000] {task_command.py:423} INFO - Running <TaskInstance: entrenamiento_modelos_regresion.entrenar_y_promover manual__2025-05-25T16:00:47.056173+00:00 [running]> on host a709e0d5c22b
[2025-05-25T16:09:09.074+0000] {taskinstance.py:2480} INFO - Exporting env vars: AIRFLOW_CTX_DAG_OWNER='fede' AIRFLOW_CTX_DAG_ID='entrenamiento_modelos_regresion' AIRFLOW_CTX_TASK_ID='entrenar_y_promover' AIRFLOW_CTX_EXECUTION_DATE='2025-05-25T16:00:47.056173+00:00' AIRFLOW_CTX_TRY_NUMBER='2' AIRFLOW_CTX_DAG_RUN_ID='manual__2025-05-25T16:00:47.056173+00:00'
[2025-05-25T16:09:14.324+0000] {logging_mixin.py:188} WARNING - /opt/***/dags/entrenamiento_modelos_regresion_dag.py:51 SettingWithCopyWarning:
A value is trying to be set on a copy of a slice from a DataFrame.
Try using .loc[row_indexer,col_indexer] = value instead

See the caveats in the documentation: https://pandas.pydata.org/pandas-docs/stable/user_guide/indexing.html#returning-a-view-versus-a-copy
[2025-05-25T16:09:14.363+0000] {logging_mixin.py:188} WARNING - /opt/***/dags/entrenamiento_modelos_regresion_dag.py:54 SettingWithCopyWarning:
A value is trying to be set on a copy of a slice from a DataFrame.
Try using .loc[row_indexer,col_indexer] = value instead

See the caveats in the documentation: https://pandas.pydata.org/pandas-docs/stable/user_guide/indexing.html#returning-a-view-versus-a-copy
[2025-05-25T16:09:14.370+0000] {logging_mixin.py:188} WARNING - /opt/***/dags/entrenamiento_modelos_regresion_dag.py:56 SettingWithCopyWarning:
A value is trying to be set on a copy of a slice from a DataFrame.
Try using .loc[row_indexer,col_indexer] = value instead

See the caveats in the documentation: https://pandas.pydata.org/pandas-docs/stable/user_guide/indexing.html#returning-a-view-versus-a-copy
[2025-05-25T16:09:14.377+0000] {logging_mixin.py:188} WARNING - /opt/***/dags/entrenamiento_modelos_regresion_dag.py:58 SettingWithCopyWarning:
A value is trying to be set on a copy of a slice from a DataFrame

See the caveats in the documentation: https://pandas.pydata.org/pandas-docs/stable/user_guide/indexing.html#returning-a-view-versus-a-copy
[2025-05-25T16:09:14.385+0000] {logging_mixin.py:188} WARNING - /opt/***/dags/entrenamiento_modelos_regresion_dag.py:60 SettingWithCopyWarning:
A value is trying to be set on a copy of a slice from a DataFrame

See the caveats in the documentation: https://pandas.pydata.org/pandas-docs/stable/user_guide/indexing.html#returning-a-view-versus-a-copy
[2025-05-25T16:09:14.387+0000] {taskinstance.py:2698} ERROR - Task failed with exception
Traceback (most recent call last):
  File "/home/airflow/.local/lib/python3.8/site-packages/airflow/models/taskinstance.py", line 433, in _execute_task
    result = execute_callable(context=context, **execute_callable_kwargs)
  File "/home/airflow/.local/lib/python3.8/site-packages/airflow/decorators/base.py", line 241, in execute
    return_value = super().execute(context)
  File "/home/airflow/.local/lib/python3.8/site-packages/airflow/operators/python.py", line 199, in execute
    return_value = self.execute_callable()
  File "/home/airflow/.local/lib/python3.8/site-packages/airflow/operators/python.py", line 216, in execute_callable
    return self.python_callable(*self.op_args, **self.op_kwargs)
  File "/opt/airflow/dags/entrenamiento_modelos_regresion_dag.py", line 62, in entrenar_y_promover
    X_train, X_test, y_train, y_test = train_test_split(X, y, test_size=0.2, random_state=42)
  File "/home/airflow/.local/lib/python3.8/site-packages/sklearn/utils/_param_validation.py", line 214, in wrapper
    return func(*args, **kwargs)
  File "/home/airflow/.local/lib/python3.8/site-packages/sklearn/model_selection/_split.py", line 2646, in train_test_split
    arrays = indexable(*arrays)
  File "/home/airflow/.local/lib/python3.8/site-packages/sklearn/utils/validation.py", line 453, in indexable
    check_consistent_length(*result)
  File "/home/airflow/.local/lib/python3.8/site-packages/sklearn/utils/validation.py", line 407, in check_consistent_length
    raise ValueError(
ValueError: Found input variables with inconsistent numbers of samples: [873, 949]
[2025-05-25T16:09:14.430+0000] {taskinstance.py:1138} INFO - Marking task as FAILED. dag_id=entrenamiento_modelos_regresion, task_id=entrenar_y_promover, execution_date=20250525T160047, start_date=20250525T160908, end_date=20250525T160914
[2025-05-25T16:09:14.469+0000] {standard_task_runner.py:107} ERROR - Failed to execute job 16 for task entrenar_y_promover (Found input variables with inconsistent numbers of samples: [873, 949]; 187)
[2025-05-25T16:09:14.510+0000] {local_task_job_runner.py:234} INFO - Task exited with return code 1
[2025-05-25T16:09:14.558+0000] {taskinstance.py:3280} INFO - 0 downstream tasks scheduled from follow-on schedule check
