[2025-05-25T15:46:34.099+0000] {taskinstance.py:1956} INFO - Dependencies all met for dep_context=non-requeueable deps ti=<TaskInstance: entrenamiento_modelos_regresion.entrenar_y_promover manual__2025-05-25T15:37:32.815779+00:00 [queued]>
[2025-05-25T15:46:34.120+0000] {taskinstance.py:1956} INFO - Dependencies all met for dep_context=requeueable deps ti=<TaskInstance: entrenamiento_modelos_regresion.entrenar_y_promover manual__2025-05-25T15:37:32.815779+00:00 [queued]>
[2025-05-25T15:46:34.121+0000] {taskinstance.py:2170} INFO - Starting attempt 2 of 2
[2025-05-25T15:46:34.157+0000] {taskinstance.py:2191} INFO - Executing <Task(_PythonDecoratedOperator): entrenar_y_promover> on 2025-05-25 15:37:32.815779+00:00
[2025-05-25T15:46:34.165+0000] {standard_task_runner.py:60} INFO - Started process 187 to run task
[2025-05-25T15:46:34.175+0000] {standard_task_runner.py:87} INFO - Running: ['***', 'tasks', 'run', 'entrenamiento_modelos_regresion', 'entrenar_y_promover', 'manual__2025-05-25T15:37:32.815779+00:00', '--job-id', '10', '--raw', '--subdir', 'DAGS_FOLDER/entrenamiento_modelos_regresion_dag.py', '--cfg-path', '/tmp/tmpzm_3e27k']
[2025-05-25T15:46:34.180+0000] {standard_task_runner.py:88} INFO - Job 10: Subtask entrenar_y_promover
[2025-05-25T15:46:34.348+0000] {task_command.py:423} INFO - Running <TaskInstance: entrenamiento_modelos_regresion.entrenar_y_promover manual__2025-05-25T15:37:32.815779+00:00 [running]> on host a709e0d5c22b
[2025-05-25T15:46:34.608+0000] {taskinstance.py:2480} INFO - Exporting env vars: AIRFLOW_CTX_DAG_OWNER='fede' AIRFLOW_CTX_DAG_ID='entrenamiento_modelos_regresion' AIRFLOW_CTX_TASK_ID='entrenar_y_promover' AIRFLOW_CTX_EXECUTION_DATE='2025-05-25T15:37:32.815779+00:00' AIRFLOW_CTX_TRY_NUMBER='2' AIRFLOW_CTX_DAG_RUN_ID='manual__2025-05-25T15:37:32.815779+00:00'
[2025-05-25T15:46:40.275+0000] {logging_mixin.py:188} WARNING - /opt/***/dags/entrenamiento_modelos_regresion_dag.py:51 SettingWithCopyWarning:
A value is trying to be set on a copy of a slice from a DataFrame.
Try using .loc[row_indexer,col_indexer] = value instead

See the caveats in the documentation: https://pandas.pydata.org/pandas-docs/stable/user_guide/indexing.html#returning-a-view-versus-a-copy
[2025-05-25T15:46:40.315+0000] {logging_mixin.py:188} WARNING - /opt/***/dags/entrenamiento_modelos_regresion_dag.py:54 SettingWithCopyWarning:
A value is trying to be set on a copy of a slice from a DataFrame.
Try using .loc[row_indexer,col_indexer] = value instead

See the caveats in the documentation: https://pandas.pydata.org/pandas-docs/stable/user_guide/indexing.html#returning-a-view-versus-a-copy
[2025-05-25T15:46:40.321+0000] {logging_mixin.py:188} WARNING - /opt/***/dags/entrenamiento_modelos_regresion_dag.py:56 SettingWithCopyWarning:
A value is trying to be set on a copy of a slice from a DataFrame.
Try using .loc[row_indexer,col_indexer] = value instead

See the caveats in the documentation: https://pandas.pydata.org/pandas-docs/stable/user_guide/indexing.html#returning-a-view-versus-a-copy
[2025-05-25T15:46:40.326+0000] {logging_mixin.py:188} WARNING - /opt/***/dags/entrenamiento_modelos_regresion_dag.py:58 SettingWithCopyWarning:
A value is trying to be set on a copy of a slice from a DataFrame

See the caveats in the documentation: https://pandas.pydata.org/pandas-docs/stable/user_guide/indexing.html#returning-a-view-versus-a-copy
[2025-05-25T15:46:40.400+0000] {connectionpool.py:824} WARNING - Retrying (JitteredRetry(total=4, connect=4, read=5, redirect=5, status=5)) after connection broken by 'NewConnectionError('<urllib3.connection.HTTPConnection object at 0x7fad9f829940>: Failed to establish a new connection: [Errno 111] Connection refused')': /api/2.0/mlflow/experiments/get-by-name?experiment_name=entrenamiento_orquestado
[2025-05-25T15:46:44.407+0000] {connectionpool.py:824} WARNING - Retrying (JitteredRetry(total=3, connect=3, read=5, redirect=5, status=5)) after connection broken by 'NewConnectionError('<urllib3.connection.HTTPConnection object at 0x7fad9f8298b0>: Failed to establish a new connection: [Errno 111] Connection refused')': /api/2.0/mlflow/experiments/get-by-name?experiment_name=entrenamiento_orquestado
[2025-05-25T15:46:52.420+0000] {connectionpool.py:824} WARNING - Retrying (JitteredRetry(total=2, connect=2, read=5, redirect=5, status=5)) after connection broken by 'NewConnectionError('<urllib3.connection.HTTPConnection object at 0x7fad9f8295b0>: Failed to establish a new connection: [Errno 111] Connection refused')': /api/2.0/mlflow/experiments/get-by-name?experiment_name=entrenamiento_orquestado
[2025-05-25T15:47:06.591+0000] {connectionpool.py:824} WARNING - Retrying (JitteredRetry(total=1, connect=1, read=5, redirect=5, status=5)) after connection broken by 'NewConnectionError('<urllib3.connection.HTTPConnection object at 0x7fad9f861040>: Failed to establish a new connection: [Errno 111] Connection refused')': /api/2.0/mlflow/experiments/get-by-name?experiment_name=entrenamiento_orquestado
[2025-05-25T15:47:36.884+0000] {connectionpool.py:824} WARNING - Retrying (JitteredRetry(total=0, connect=0, read=5, redirect=5, status=5)) after connection broken by 'NewConnectionError('<urllib3.connection.HTTPConnection object at 0x7fad9f8610d0>: Failed to establish a new connection: [Errno 111] Connection refused')': /api/2.0/mlflow/experiments/get-by-name?experiment_name=entrenamiento_orquestado
[2025-05-25T15:47:36.893+0000] {taskinstance.py:2698} ERROR - Task failed with exception
Traceback (most recent call last):
  File "/home/airflow/.local/lib/python3.8/site-packages/urllib3/connection.py", line 174, in _new_conn
    conn = connection.create_connection(
  File "/home/airflow/.local/lib/python3.8/site-packages/urllib3/util/connection.py", line 95, in create_connection
    raise err
  File "/home/airflow/.local/lib/python3.8/site-packages/urllib3/util/connection.py", line 85, in create_connection
    sock.connect(sa)
ConnectionRefusedError: [Errno 111] Connection refused

During handling of the above exception, another exception occurred:

Traceback (most recent call last):
  File "/home/airflow/.local/lib/python3.8/site-packages/urllib3/connectionpool.py", line 715, in urlopen
    httplib_response = self._make_request(
  File "/home/airflow/.local/lib/python3.8/site-packages/urllib3/connectionpool.py", line 416, in _make_request
    conn.request(method, url, **httplib_request_kw)
  File "/home/airflow/.local/lib/python3.8/site-packages/urllib3/connection.py", line 244, in request
    super(HTTPConnection, self).request(method, url, body=body, headers=headers)
  File "/usr/local/lib/python3.8/http/client.py", line 1256, in request
    self._send_request(method, url, body, headers, encode_chunked)
  File "/usr/local/lib/python3.8/http/client.py", line 1302, in _send_request
    self.endheaders(body, encode_chunked=encode_chunked)
  File "/usr/local/lib/python3.8/http/client.py", line 1251, in endheaders
    self._send_output(message_body, encode_chunked=encode_chunked)
  File "/usr/local/lib/python3.8/http/client.py", line 1011, in _send_output
    self.send(msg)
  File "/usr/local/lib/python3.8/http/client.py", line 951, in send
    self.connect()
  File "/home/airflow/.local/lib/python3.8/site-packages/urllib3/connection.py", line 205, in connect
    conn = self._new_conn()
  File "/home/airflow/.local/lib/python3.8/site-packages/urllib3/connection.py", line 186, in _new_conn
    raise NewConnectionError(
urllib3.exceptions.NewConnectionError: <urllib3.connection.HTTPConnection object at 0x7fad9f861370>: Failed to establish a new connection: [Errno 111] Connection refused

During handling of the above exception, another exception occurred:

Traceback (most recent call last):
  File "/home/airflow/.local/lib/python3.8/site-packages/requests/adapters.py", line 486, in send
    resp = conn.urlopen(
  File "/home/airflow/.local/lib/python3.8/site-packages/urllib3/connectionpool.py", line 827, in urlopen
    return self.urlopen(
  File "/home/airflow/.local/lib/python3.8/site-packages/urllib3/connectionpool.py", line 827, in urlopen
    return self.urlopen(
  File "/home/airflow/.local/lib/python3.8/site-packages/urllib3/connectionpool.py", line 827, in urlopen
    return self.urlopen(
  [Previous line repeated 2 more times]
  File "/home/airflow/.local/lib/python3.8/site-packages/urllib3/connectionpool.py", line 799, in urlopen
    retries = retries.increment(
  File "/home/airflow/.local/lib/python3.8/site-packages/urllib3/util/retry.py", line 592, in increment
    raise MaxRetryError(_pool, url, error or ResponseError(cause))
urllib3.exceptions.MaxRetryError: HTTPConnectionPool(host='localhost', port=5000): Max retries exceeded with url: /api/2.0/mlflow/experiments/get-by-name?experiment_name=entrenamiento_orquestado (Caused by NewConnectionError('<urllib3.connection.HTTPConnection object at 0x7fad9f861370>: Failed to establish a new connection: [Errno 111] Connection refused'))

During handling of the above exception, another exception occurred:

Traceback (most recent call last):
  File "/home/airflow/.local/lib/python3.8/site-packages/mlflow/utils/rest_utils.py", line 189, in http_request
    return _get_http_response_with_retries(
  File "/home/airflow/.local/lib/python3.8/site-packages/mlflow/utils/request_utils.py", line 237, in _get_http_response_with_retries
    return session.request(method, url, allow_redirects=allow_redirects, **kwargs)
  File "/home/airflow/.local/lib/python3.8/site-packages/requests/sessions.py", line 589, in request
    resp = self.send(prep, **send_kwargs)
  File "/home/airflow/.local/lib/python3.8/site-packages/requests/sessions.py", line 703, in send
    r = adapter.send(request, **kwargs)
  File "/home/airflow/.local/lib/python3.8/site-packages/requests/adapters.py", line 519, in send
    raise ConnectionError(e, request=request)
requests.exceptions.ConnectionError: HTTPConnectionPool(host='localhost', port=5000): Max retries exceeded with url: /api/2.0/mlflow/experiments/get-by-name?experiment_name=entrenamiento_orquestado (Caused by NewConnectionError('<urllib3.connection.HTTPConnection object at 0x7fad9f861370>: Failed to establish a new connection: [Errno 111] Connection refused'))

During handling of the above exception, another exception occurred:

Traceback (most recent call last):
  File "/home/airflow/.local/lib/python3.8/site-packages/airflow/models/taskinstance.py", line 433, in _execute_task
    result = execute_callable(context=context, **execute_callable_kwargs)
  File "/home/airflow/.local/lib/python3.8/site-packages/airflow/decorators/base.py", line 241, in execute
    return_value = super().execute(context)
  File "/home/airflow/.local/lib/python3.8/site-packages/airflow/operators/python.py", line 199, in execute
    return_value = self.execute_callable()
  File "/home/airflow/.local/lib/python3.8/site-packages/airflow/operators/python.py", line 216, in execute_callable
    return self.python_callable(*self.op_args, **self.op_kwargs)
  File "/opt/airflow/dags/entrenamiento_modelos_regresion_dag.py", line 63, in entrenar_y_promover
    mlflow.set_experiment("entrenamiento_orquestado")
  File "/home/airflow/.local/lib/python3.8/site-packages/mlflow/tracking/fluent.py", line 145, in set_experiment
    experiment = client.get_experiment_by_name(experiment_name)
  File "/home/airflow/.local/lib/python3.8/site-packages/mlflow/tracking/client.py", line 1256, in get_experiment_by_name
    return self._tracking_client.get_experiment_by_name(name)
  File "/home/airflow/.local/lib/python3.8/site-packages/mlflow/tracking/_tracking_service/client.py", line 501, in get_experiment_by_name
    return self.store.get_experiment_by_name(name)
  File "/home/airflow/.local/lib/python3.8/site-packages/mlflow/store/tracking/rest_store.py", line 519, in get_experiment_by_name
    response_proto = self._call_endpoint(GetExperimentByName, req_body)
  File "/home/airflow/.local/lib/python3.8/site-packages/mlflow/store/tracking/rest_store.py", line 82, in _call_endpoint
    return call_endpoint(self.get_host_creds(), endpoint, method, json_body, response_proto)
  File "/home/airflow/.local/lib/python3.8/site-packages/mlflow/utils/rest_utils.py", line 365, in call_endpoint
    response = http_request(**call_kwargs)
  File "/home/airflow/.local/lib/python3.8/site-packages/mlflow/utils/rest_utils.py", line 212, in http_request
    raise MlflowException(f"API request to {url} failed with exception {e}")
mlflow.exceptions.MlflowException: API request to http://localhost:5000/api/2.0/mlflow/experiments/get-by-name failed with exception HTTPConnectionPool(host='localhost', port=5000): Max retries exceeded with url: /api/2.0/mlflow/experiments/get-by-name?experiment_name=entrenamiento_orquestado (Caused by NewConnectionError('<urllib3.connection.HTTPConnection object at 0x7fad9f861370>: Failed to establish a new connection: [Errno 111] Connection refused'))
[2025-05-25T15:47:37.006+0000] {taskinstance.py:1138} INFO - Marking task as FAILED. dag_id=entrenamiento_modelos_regresion, task_id=entrenar_y_promover, execution_date=20250525T153732, start_date=20250525T154634, end_date=20250525T154737
[2025-05-25T15:47:37.086+0000] {standard_task_runner.py:107} ERROR - Failed to execute job 10 for task entrenar_y_promover (API request to http://localhost:5000/api/2.0/mlflow/experiments/get-by-name failed with exception HTTPConnectionPool(host='localhost', port=5000): Max retries exceeded with url: /api/2.0/mlflow/experiments/get-by-name?experiment_name=entrenamiento_orquestado (Caused by NewConnectionError('<urllib3.connection.HTTPConnection object at 0x7fad9f861370>: Failed to establish a new connection: [Errno 111] Connection refused')); 187)
[2025-05-25T15:47:37.186+0000] {local_task_job_runner.py:234} INFO - Task exited with return code 1
[2025-05-25T15:47:37.286+0000] {taskinstance.py:3280} INFO - 0 downstream tasks scheduled from follow-on schedule check
