[2025-06-14T17:57:21.841+0000] {taskinstance.py:1956} INFO - Dependencies all met for dep_context=non-requeueable deps ti=<TaskInstance: prediccion_modelo_produccion_dag.predecir scheduled__2025-06-12T22:00:00+00:00 [queued]>
[2025-06-14T17:57:21.858+0000] {taskinstance.py:1956} INFO - Dependencies all met for dep_context=requeueable deps ti=<TaskInstance: prediccion_modelo_produccion_dag.predecir scheduled__2025-06-12T22:00:00+00:00 [queued]>
[2025-06-14T17:57:21.859+0000] {taskinstance.py:2170} INFO - Starting attempt 2 of 2
[2025-06-14T17:57:21.883+0000] {taskinstance.py:2191} INFO - Executing <Task(_PythonDecoratedOperator): predecir> on 2025-06-12 22:00:00+00:00
[2025-06-14T17:57:21.891+0000] {standard_task_runner.py:60} INFO - Started process 203 to run task
[2025-06-14T17:57:21.900+0000] {standard_task_runner.py:87} INFO - Running: ['***', 'tasks', 'run', 'prediccion_modelo_produccion_dag', 'predecir', 'scheduled__2025-06-12T22:00:00+00:00', '--job-id', '107', '--raw', '--subdir', 'DAGS_FOLDER/prediccion_modelo_produccion_dag.py', '--cfg-path', '/tmp/tmpq5tqab2s']
[2025-06-14T17:57:21.906+0000] {standard_task_runner.py:88} INFO - Job 107: Subtask predecir
[2025-06-14T17:57:22.030+0000] {task_command.py:423} INFO - Running <TaskInstance: prediccion_modelo_produccion_dag.predecir scheduled__2025-06-12T22:00:00+00:00 [running]> on host 817deb7140ea
[2025-06-14T17:57:22.249+0000] {taskinstance.py:2480} INFO - Exporting env vars: AIRFLOW_CTX_DAG_OWNER='fede' AIRFLOW_CTX_DAG_ID='prediccion_modelo_produccion_dag' AIRFLOW_CTX_TASK_ID='predecir' AIRFLOW_CTX_EXECUTION_DATE='2025-06-12T22:00:00+00:00' AIRFLOW_CTX_TRY_NUMBER='2' AIRFLOW_CTX_DAG_RUN_ID='scheduled__2025-06-12T22:00:00+00:00'
[2025-06-14T17:57:24.800+0000] {logging_mixin.py:188} WARNING - /home/***/.local/lib/python3.8/site-packages/mlflow/store/artifact/utils/models.py:31 FutureWarning: ``mlflow.tracking.client.MlflowClient.get_latest_versions`` is deprecated since 2.9.0. Model registry stages will be removed in a future major release. To learn more about the deprecation of model registry stages, see our migration guide here: https://mlflow.org/docs/latest/model-registry.html#migrating-from-stages
[2025-06-14T17:57:25.591+0000] {taskinstance.py:2698} ERROR - Task failed with exception
Traceback (most recent call last):
  File "/home/airflow/.local/lib/python3.8/site-packages/airflow/models/taskinstance.py", line 433, in _execute_task
    result = execute_callable(context=context, **execute_callable_kwargs)
  File "/home/airflow/.local/lib/python3.8/site-packages/airflow/decorators/base.py", line 241, in execute
    return_value = super().execute(context)
  File "/home/airflow/.local/lib/python3.8/site-packages/airflow/operators/python.py", line 199, in execute
    return_value = self.execute_callable()
  File "/home/airflow/.local/lib/python3.8/site-packages/airflow/operators/python.py", line 216, in execute_callable
    return self.python_callable(*self.op_args, **self.op_kwargs)
  File "/opt/airflow/dags/prediccion_modelo_produccion_dag.py", line 49, in predecir
    model = mlflow.sklearn.load_model(f"models:/{model_name}/{stage}")
  File "/home/airflow/.local/lib/python3.8/site-packages/mlflow/sklearn/__init__.py", line 633, in load_model
    local_model_path = _download_artifact_from_uri(artifact_uri=model_uri, output_path=dst_path)
  File "/home/airflow/.local/lib/python3.8/site-packages/mlflow/tracking/artifact_utils.py", line 111, in _download_artifact_from_uri
    return repo.download_artifacts(
  File "/home/airflow/.local/lib/python3.8/site-packages/mlflow/store/artifact/models_artifact_repo.py", line 205, in download_artifacts
    self._add_registered_model_meta_file(model_path)
  File "/home/airflow/.local/lib/python3.8/site-packages/mlflow/store/artifact/models_artifact_repo.py", line 161, in _add_registered_model_meta_file
    write_yaml(
  File "/home/airflow/.local/lib/python3.8/site-packages/mlflow/utils/file_utils.py", line 246, in write_yaml
    with codecs.open(yaml_file_name, mode="w", encoding=ENCODING) as yaml_file:
  File "/usr/local/lib/python3.8/codecs.py", line 905, in open
    file = builtins.open(filename, mode, buffering)
PermissionError: [Errno 13] Permission denied: '/mlflow/mlruns/1/401fbb63b8d4439ea74b6c2fb0be418e/artifacts/modelo/registered_model_meta'
[2025-06-14T17:57:25.613+0000] {taskinstance.py:1138} INFO - Marking task as FAILED. dag_id=prediccion_modelo_produccion_dag, task_id=predecir, execution_date=20250612T220000, start_date=20250614T175721, end_date=20250614T175725
[2025-06-14T17:57:25.641+0000] {standard_task_runner.py:107} ERROR - Failed to execute job 107 for task predecir ([Errno 13] Permission denied: '/mlflow/mlruns/1/401fbb63b8d4439ea74b6c2fb0be418e/artifacts/modelo/registered_model_meta'; 203)
[2025-06-14T17:57:25.674+0000] {local_task_job_runner.py:234} INFO - Task exited with return code 1
[2025-06-14T17:57:25.712+0000] {taskinstance.py:3280} INFO - 0 downstream tasks scheduled from follow-on schedule check
[2025-06-14T20:21:34.727+0000] {taskinstance.py:1956} INFO - Dependencies all met for dep_context=non-requeueable deps ti=<TaskInstance: prediccion_modelo_produccion_dag.predecir scheduled__2025-06-12T22:00:00+00:00 [queued]>
[2025-06-14T20:21:34.739+0000] {taskinstance.py:1956} INFO - Dependencies all met for dep_context=requeueable deps ti=<TaskInstance: prediccion_modelo_produccion_dag.predecir scheduled__2025-06-12T22:00:00+00:00 [queued]>
[2025-06-14T20:21:34.739+0000] {taskinstance.py:2170} INFO - Starting attempt 2 of 2
[2025-06-14T20:21:34.754+0000] {taskinstance.py:2191} INFO - Executing <Task(_PythonDecoratedOperator): predecir> on 2025-06-12 22:00:00+00:00
[2025-06-14T20:21:34.762+0000] {standard_task_runner.py:60} INFO - Started process 1534 to run task
[2025-06-14T20:21:34.767+0000] {standard_task_runner.py:87} INFO - Running: ['***', 'tasks', 'run', 'prediccion_modelo_produccion_dag', 'predecir', 'scheduled__2025-06-12T22:00:00+00:00', '--job-id', '12', '--raw', '--subdir', 'DAGS_FOLDER/prediccion_modelo_produccion_dag.py', '--cfg-path', '/tmp/tmpi0jyhmv9']
[2025-06-14T20:21:34.769+0000] {standard_task_runner.py:88} INFO - Job 12: Subtask predecir
[2025-06-14T20:21:34.843+0000] {task_command.py:423} INFO - Running <TaskInstance: prediccion_modelo_produccion_dag.predecir scheduled__2025-06-12T22:00:00+00:00 [running]> on host b32a9208912d
[2025-06-14T20:21:34.940+0000] {taskinstance.py:2480} INFO - Exporting env vars: AIRFLOW_CTX_DAG_OWNER='fede' AIRFLOW_CTX_DAG_ID='prediccion_modelo_produccion_dag' AIRFLOW_CTX_TASK_ID='predecir' AIRFLOW_CTX_EXECUTION_DATE='2025-06-12T22:00:00+00:00' AIRFLOW_CTX_TRY_NUMBER='2' AIRFLOW_CTX_DAG_RUN_ID='scheduled__2025-06-12T22:00:00+00:00'
[2025-06-14T20:21:35.792+0000] {logging_mixin.py:188} WARNING - /home/***/.local/lib/python3.8/site-packages/mlflow/store/artifact/utils/models.py:31 FutureWarning: ``mlflow.tracking.client.MlflowClient.get_latest_versions`` is deprecated since 2.9.0. Model registry stages will be removed in a future major release. To learn more about the deprecation of model registry stages, see our migration guide here: https://mlflow.org/docs/latest/model-registry.html#migrating-from-stages
[2025-06-14T20:21:36.424+0000] {taskinstance.py:2698} ERROR - Task failed with exception
Traceback (most recent call last):
  File "/home/airflow/.local/lib/python3.8/site-packages/airflow/models/taskinstance.py", line 433, in _execute_task
    result = execute_callable(context=context, **execute_callable_kwargs)
  File "/home/airflow/.local/lib/python3.8/site-packages/airflow/decorators/base.py", line 241, in execute
    return_value = super().execute(context)
  File "/home/airflow/.local/lib/python3.8/site-packages/airflow/operators/python.py", line 199, in execute
    return_value = self.execute_callable()
  File "/home/airflow/.local/lib/python3.8/site-packages/airflow/operators/python.py", line 216, in execute_callable
    return self.python_callable(*self.op_args, **self.op_kwargs)
  File "/opt/airflow/dags/prediccion_modelo_produccion_dag.py", line 57, in predecir
    predicciones = model.predict(nuevos_datos)
  File "/home/airflow/.local/lib/python3.8/site-packages/sklearn/ensemble/_forest.py", line 984, in predict
    X = self._validate_X_predict(X)
  File "/home/airflow/.local/lib/python3.8/site-packages/sklearn/ensemble/_forest.py", line 599, in _validate_X_predict
    X = self._validate_data(X, dtype=DTYPE, accept_sparse="csr", reset=False)
  File "/home/airflow/.local/lib/python3.8/site-packages/sklearn/base.py", line 580, in _validate_data
    self._check_feature_names(X, reset=reset)
  File "/home/airflow/.local/lib/python3.8/site-packages/sklearn/base.py", line 507, in _check_feature_names
    raise ValueError(message)
ValueError: The feature names should match those that were passed during fit.
Feature names unseen at fit time:
- puertas

[2025-06-14T20:21:36.437+0000] {taskinstance.py:1138} INFO - Marking task as FAILED. dag_id=prediccion_modelo_produccion_dag, task_id=predecir, execution_date=20250612T220000, start_date=20250614T202134, end_date=20250614T202136
[2025-06-14T20:21:36.452+0000] {standard_task_runner.py:107} ERROR - Failed to execute job 12 for task predecir (The feature names should match those that were passed during fit.
Feature names unseen at fit time:
- puertas
; 1534)
[2025-06-14T20:21:36.507+0000] {local_task_job_runner.py:234} INFO - Task exited with return code 1
[2025-06-14T20:21:36.529+0000] {taskinstance.py:3280} INFO - 0 downstream tasks scheduled from follow-on schedule check
