[2025-05-31T16:59:10.644+0000] {taskinstance.py:1956} INFO - Dependencies all met for dep_context=non-requeueable deps ti=<TaskInstance: entrenamiento_modelos_regresion.entrenar_y_promover manual__2025-05-31T16:53:59.729360+00:00 [queued]>
[2025-05-31T16:59:10.666+0000] {taskinstance.py:1956} INFO - Dependencies all met for dep_context=requeueable deps ti=<TaskInstance: entrenamiento_modelos_regresion.entrenar_y_promover manual__2025-05-31T16:53:59.729360+00:00 [queued]>
[2025-05-31T16:59:10.667+0000] {taskinstance.py:2170} INFO - Starting attempt 2 of 2
[2025-05-31T16:59:10.707+0000] {taskinstance.py:2191} INFO - Executing <Task(_PythonDecoratedOperator): entrenar_y_promover> on 2025-05-31 16:53:59.729360+00:00
[2025-05-31T16:59:10.721+0000] {standard_task_runner.py:60} INFO - Started process 257 to run task
[2025-05-31T16:59:10.737+0000] {standard_task_runner.py:87} INFO - Running: ['***', 'tasks', 'run', 'entrenamiento_modelos_regresion', 'entrenar_y_promover', 'manual__2025-05-31T16:53:59.729360+00:00', '--job-id', '9', '--raw', '--subdir', 'DAGS_FOLDER/entrenamiento_modelos_regresion_dag.py', '--cfg-path', '/tmp/tmpuyw5op8j']
[2025-05-31T16:59:10.747+0000] {standard_task_runner.py:88} INFO - Job 9: Subtask entrenar_y_promover
[2025-05-31T16:59:10.931+0000] {task_command.py:423} INFO - Running <TaskInstance: entrenamiento_modelos_regresion.entrenar_y_promover manual__2025-05-31T16:53:59.729360+00:00 [running]> on host 3baa60b072de
[2025-05-31T16:59:11.122+0000] {taskinstance.py:2480} INFO - Exporting env vars: AIRFLOW_CTX_DAG_OWNER='fede' AIRFLOW_CTX_DAG_ID='entrenamiento_modelos_regresion' AIRFLOW_CTX_TASK_ID='entrenar_y_promover' AIRFLOW_CTX_EXECUTION_DATE='2025-05-31T16:53:59.729360+00:00' AIRFLOW_CTX_TRY_NUMBER='2' AIRFLOW_CTX_DAG_RUN_ID='manual__2025-05-31T16:53:59.729360+00:00'
[2025-05-31T16:59:13.036+0000] {logging_mixin.py:188} WARNING - /opt/***/dags/entrenamiento_modelos_regresion_dag.py:56 SettingWithCopyWarning:
A value is trying to be set on a copy of a slice from a DataFrame.
Try using .loc[row_indexer,col_indexer] = value instead

See the caveats in the documentation: https://pandas.pydata.org/pandas-docs/stable/user_guide/indexing.html#returning-a-view-versus-a-copy
[2025-05-31T16:59:13.059+0000] {logging_mixin.py:188} WARNING - /opt/***/dags/entrenamiento_modelos_regresion_dag.py:59 SettingWithCopyWarning:
A value is trying to be set on a copy of a slice from a DataFrame.
Try using .loc[row_indexer,col_indexer] = value instead

See the caveats in the documentation: https://pandas.pydata.org/pandas-docs/stable/user_guide/indexing.html#returning-a-view-versus-a-copy
[2025-05-31T16:59:13.064+0000] {logging_mixin.py:188} WARNING - /opt/***/dags/entrenamiento_modelos_regresion_dag.py:61 SettingWithCopyWarning:
A value is trying to be set on a copy of a slice from a DataFrame.
Try using .loc[row_indexer,col_indexer] = value instead

See the caveats in the documentation: https://pandas.pydata.org/pandas-docs/stable/user_guide/indexing.html#returning-a-view-versus-a-copy
[2025-05-31T16:59:13.068+0000] {logging_mixin.py:188} WARNING - /opt/***/dags/entrenamiento_modelos_regresion_dag.py:63 SettingWithCopyWarning:
A value is trying to be set on a copy of a slice from a DataFrame

See the caveats in the documentation: https://pandas.pydata.org/pandas-docs/stable/user_guide/indexing.html#returning-a-view-versus-a-copy
[2025-05-31T16:59:14.006+0000] {logging_mixin.py:188} WARNING - 2025/05/31 16:59:14 WARNING mlflow.utils.git_utils: Failed to import Git (the Git executable is probably not on your PATH), so Git SHA is not available. Error: Failed to initialize: Bad git executable.
The git executable must be specified in one of the following ways:
    - be included in your $PATH
    - be set via $GIT_PYTHON_GIT_EXECUTABLE
    - explicitly set via git.refresh(<full-path-to-git-executable>)

All git commands will error until this is rectified.

This initial message can be silenced or aggravated in the future by setting the
$GIT_PYTHON_REFRESH environment variable. Use one of the following values:
    - quiet|q|silence|s|silent|none|n|0: for no message or exception
    - warn|w|warning|log|l|1: for a warning message (logging level CRITICAL, displayed by default)
    - error|e|exception|raise|r|2: for a raised exception

Example:
    export GIT_PYTHON_REFRESH=quiet
[2025-05-31T16:59:14.072+0000] {logging_mixin.py:188} WARNING - 2025/05/31 16:59:14 INFO mlflow.tracking._tracking_service.client: üèÉ View run RandomForest at: http://mlflow:5000/#/experiments/1/runs/9bfc6fd141db48bca9285abdc84af5e1.
[2025-05-31T16:59:14.073+0000] {logging_mixin.py:188} WARNING - 2025/05/31 16:59:14 INFO mlflow.tracking._tracking_service.client: üß™ View experiment at: http://mlflow:5000/#/experiments/1.
[2025-05-31T16:59:15.271+0000] {taskinstance.py:2698} ERROR - Task failed with exception
Traceback (most recent call last):
  File "/home/airflow/.local/lib/python3.8/site-packages/airflow/models/taskinstance.py", line 433, in _execute_task
    result = execute_callable(context=context, **execute_callable_kwargs)
  File "/home/airflow/.local/lib/python3.8/site-packages/airflow/decorators/base.py", line 241, in execute
    return_value = super().execute(context)
  File "/home/airflow/.local/lib/python3.8/site-packages/airflow/operators/python.py", line 199, in execute
    return_value = self.execute_callable()
  File "/home/airflow/.local/lib/python3.8/site-packages/airflow/operators/python.py", line 216, in execute_callable
    return self.python_callable(*self.op_args, **self.op_kwargs)
  File "/opt/airflow/dags/entrenamiento_modelos_regresion_dag.py", line 83, in entrenar_y_promover
    modelo.fit(X_train, y_train)
  File "/home/airflow/.local/lib/python3.8/site-packages/sklearn/base.py", line 1152, in wrapper
    return fit_method(estimator, *args, **kwargs)
  File "/home/airflow/.local/lib/python3.8/site-packages/sklearn/ensemble/_forest.py", line 348, in fit
    X, y = self._validate_data(
  File "/home/airflow/.local/lib/python3.8/site-packages/sklearn/base.py", line 622, in _validate_data
    X, y = check_X_y(X, y, **check_params)
  File "/home/airflow/.local/lib/python3.8/site-packages/sklearn/utils/validation.py", line 1146, in check_X_y
    X = check_array(
  File "/home/airflow/.local/lib/python3.8/site-packages/sklearn/utils/validation.py", line 915, in check_array
    array = _asarray_with_order(array, order=order, dtype=dtype, xp=xp)
  File "/home/airflow/.local/lib/python3.8/site-packages/sklearn/utils/_array_api.py", line 380, in _asarray_with_order
    array = numpy.asarray(array, order=order, dtype=dtype)
  File "/home/airflow/.local/lib/python3.8/site-packages/pandas/core/generic.py", line 1998, in __array__
    arr = np.asarray(values, dtype=dtype)
ValueError: could not convert string to float: 'Gris Oscuro'
[2025-05-31T16:59:15.304+0000] {taskinstance.py:1138} INFO - Marking task as FAILED. dag_id=entrenamiento_modelos_regresion, task_id=entrenar_y_promover, execution_date=20250531T165359, start_date=20250531T165910, end_date=20250531T165915
[2025-05-31T16:59:15.331+0000] {standard_task_runner.py:107} ERROR - Failed to execute job 9 for task entrenar_y_promover (could not convert string to float: 'Gris Oscuro'; 257)
[2025-05-31T16:59:15.459+0000] {local_task_job_runner.py:234} INFO - Task exited with return code 1
[2025-05-31T16:59:15.549+0000] {taskinstance.py:3280} INFO - 0 downstream tasks scheduled from follow-on schedule check
