[2025-06-17T23:00:10.153+0000] {taskinstance.py:1956} INFO - Dependencies all met for dep_context=non-requeueable deps ti=<TaskInstance: entrenamiento_modelos_regresion.entrenar_y_promover scheduled__2025-06-16T21:00:00+00:00 [queued]>
[2025-06-17T23:00:10.163+0000] {taskinstance.py:1956} INFO - Dependencies all met for dep_context=requeueable deps ti=<TaskInstance: entrenamiento_modelos_regresion.entrenar_y_promover scheduled__2025-06-16T21:00:00+00:00 [queued]>
[2025-06-17T23:00:10.163+0000] {taskinstance.py:2170} INFO - Starting attempt 2 of 2
[2025-06-17T23:00:10.185+0000] {taskinstance.py:2191} INFO - Executing <Task(_PythonDecoratedOperator): entrenar_y_promover> on 2025-06-16 21:00:00+00:00
[2025-06-17T23:00:10.192+0000] {standard_task_runner.py:60} INFO - Started process 205 to run task
[2025-06-17T23:00:10.197+0000] {standard_task_runner.py:87} INFO - Running: ['***', 'tasks', 'run', 'entrenamiento_modelos_regresion', 'entrenar_y_promover', 'scheduled__2025-06-16T21:00:00+00:00', '--job-id', '214', '--raw', '--subdir', 'DAGS_FOLDER/entrenamiento_modelos_regresion_dag.py', '--cfg-path', '/tmp/tmpvkgzqmzg']
[2025-06-17T23:00:10.201+0000] {standard_task_runner.py:88} INFO - Job 214: Subtask entrenar_y_promover
[2025-06-17T23:00:10.282+0000] {task_command.py:423} INFO - Running <TaskInstance: entrenamiento_modelos_regresion.entrenar_y_promover scheduled__2025-06-16T21:00:00+00:00 [running]> on host cdfb22e6be80
[2025-06-17T23:00:10.424+0000] {taskinstance.py:2480} INFO - Exporting env vars: AIRFLOW_CTX_DAG_OWNER='fede' AIRFLOW_CTX_DAG_ID='entrenamiento_modelos_regresion' AIRFLOW_CTX_TASK_ID='entrenar_y_promover' AIRFLOW_CTX_EXECUTION_DATE='2025-06-16T21:00:00+00:00' AIRFLOW_CTX_TRY_NUMBER='2' AIRFLOW_CTX_DAG_RUN_ID='scheduled__2025-06-16T21:00:00+00:00'
[2025-06-17T23:00:16.840+0000] {logging_mixin.py:188} WARNING - /opt/***/dags/entrenamiento_modelos_regresion_dag.py:53 SettingWithCopyWarning:
A value is trying to be set on a copy of a slice from a DataFrame.
Try using .loc[row_indexer,col_indexer] = value instead

See the caveats in the documentation: https://pandas.pydata.org/pandas-docs/stable/user_guide/indexing.html#returning-a-view-versus-a-copy
[2025-06-17T23:00:16.854+0000] {logging_mixin.py:188} WARNING - /opt/***/dags/entrenamiento_modelos_regresion_dag.py:56 SettingWithCopyWarning:
A value is trying to be set on a copy of a slice from a DataFrame.
Try using .loc[row_indexer,col_indexer] = value instead

See the caveats in the documentation: https://pandas.pydata.org/pandas-docs/stable/user_guide/indexing.html#returning-a-view-versus-a-copy
[2025-06-17T23:00:16.856+0000] {logging_mixin.py:188} WARNING - /opt/***/dags/entrenamiento_modelos_regresion_dag.py:58 SettingWithCopyWarning:
A value is trying to be set on a copy of a slice from a DataFrame.
Try using .loc[row_indexer,col_indexer] = value instead

See the caveats in the documentation: https://pandas.pydata.org/pandas-docs/stable/user_guide/indexing.html#returning-a-view-versus-a-copy
[2025-06-17T23:00:16.858+0000] {logging_mixin.py:188} WARNING - /opt/***/dags/entrenamiento_modelos_regresion_dag.py:59 SettingWithCopyWarning:
A value is trying to be set on a copy of a slice from a DataFrame

See the caveats in the documentation: https://pandas.pydata.org/pandas-docs/stable/user_guide/indexing.html#returning-a-view-versus-a-copy
[2025-06-17T23:00:17.126+0000] {logging_mixin.py:188} WARNING - 2025/06/17 23:00:17 WARNING mlflow.utils.git_utils: Failed to import Git (the Git executable is probably not on your PATH), so Git SHA is not available. Error: Failed to initialize: Bad git executable.
The git executable must be specified in one of the following ways:
    - be included in your $PATH
    - be set via $GIT_PYTHON_GIT_EXECUTABLE
    - explicitly set via git.refresh(<full-path-to-git-executable>)

All git commands will error until this is rectified.

This initial message can be silenced or aggravated in the future by setting the
$GIT_PYTHON_REFRESH environment variable. Use one of the following values:
    - quiet|q|silence|s|silent|none|n|0: for no message or exception
    - warn|w|warning|log|l|1: for a warning message (logging level CRITICAL, displayed by default)
    - error|e|exception|raise|r|2: for a raised exception

Example:
    export GIT_PYTHON_REFRESH=quiet
[2025-06-17T23:00:22.331+0000] {logging_mixin.py:188} WARNING - 2025/06/17 23:00:22 WARNING mlflow.models.model: Model logged without a signature and input example. Please set `input_example` parameter when logging the model to auto infer the model signature.
[2025-06-17T23:00:22.412+0000] {logging_mixin.py:188} WARNING - 2025/06/17 23:00:22 INFO mlflow.tracking._tracking_service.client: üèÉ View run RandomForest at: http://mlflow:5000/#/experiments/1/runs/fc44166868964d71ac89bb342359571f.
[2025-06-17T23:00:22.412+0000] {logging_mixin.py:188} WARNING - 2025/06/17 23:00:22 INFO mlflow.tracking._tracking_service.client: üß™ View experiment at: http://mlflow:5000/#/experiments/1.
[2025-06-17T23:00:24.963+0000] {logging_mixin.py:188} WARNING - 2025/06/17 23:00:24 WARNING mlflow.models.model: Model logged without a signature and input example. Please set `input_example` parameter when logging the model to auto infer the model signature.
[2025-06-17T23:00:25.019+0000] {logging_mixin.py:188} WARNING - 2025/06/17 23:00:25 INFO mlflow.tracking._tracking_service.client: üèÉ View run GradientBoosting at: http://mlflow:5000/#/experiments/1/runs/a85dd400b38a4b1293d2d711cf1dacf5.
[2025-06-17T23:00:25.019+0000] {logging_mixin.py:188} WARNING - 2025/06/17 23:00:25 INFO mlflow.tracking._tracking_service.client: üß™ View experiment at: http://mlflow:5000/#/experiments/1.
[2025-06-17T23:00:27.194+0000] {logging_mixin.py:188} WARNING - 2025/06/17 23:00:27 WARNING mlflow.models.model: Model logged without a signature and input example. Please set `input_example` parameter when logging the model to auto infer the model signature.
[2025-06-17T23:00:27.719+0000] {logging_mixin.py:188} WARNING - 2025/06/17 23:00:27 INFO mlflow.tracking._tracking_service.client: üèÉ View run SVR at: http://mlflow:5000/#/experiments/1/runs/1703676bc2ff49079f3b726a3473abee.
[2025-06-17T23:00:27.720+0000] {logging_mixin.py:188} WARNING - 2025/06/17 23:00:27 INFO mlflow.tracking._tracking_service.client: üß™ View experiment at: http://mlflow:5000/#/experiments/1.
[2025-06-17T23:00:27.802+0000] {logging_mixin.py:188} WARNING - Registered model 'mejor_modelo_orquestado' already exists. Creating a new version of this model...
[2025-06-17T23:00:27.909+0000] {logging_mixin.py:188} WARNING - 2025/06/17 23:00:27 INFO mlflow.store.model_registry.abstract_store: Waiting up to 300 seconds for model version to finish creation. Model name: mejor_modelo_orquestado, version 13
[2025-06-17T23:00:27.909+0000] {logging_mixin.py:188} WARNING - Created version '13' of model 'mejor_modelo_orquestado'.
[2025-06-17T23:00:27.911+0000] {logging_mixin.py:188} WARNING - /opt/***/dags/entrenamiento_modelos_regresion_dag.py:105 FutureWarning: ``mlflow.tracking.client.MlflowClient.get_latest_versions`` is deprecated since 2.9.0. Model registry stages will be removed in a future major release. To learn more about the deprecation of model registry stages, see our migration guide here: https://mlflow.org/docs/latest/model-registry.html#migrating-from-stages
[2025-06-17T23:00:27.922+0000] {logging_mixin.py:188} WARNING - /opt/***/dags/entrenamiento_modelos_regresion_dag.py:116 FutureWarning: ``mlflow.tracking.client.MlflowClient.transition_model_version_stage`` is deprecated since 2.9.0. Model registry stages will be removed in a future major release. To learn more about the deprecation of model registry stages, see our migration guide here: https://mlflow.org/docs/latest/model-registry.html#migrating-from-stages
[2025-06-17T23:00:27.947+0000] {logging_mixin.py:188} WARNING - /opt/***/dags/entrenamiento_modelos_regresion_dag.py:109 FutureWarning: ``mlflow.tracking.client.MlflowClient.transition_model_version_stage`` is deprecated since 2.9.0. Model registry stages will be removed in a future major release. To learn more about the deprecation of model registry stages, see our migration guide here: https://mlflow.org/docs/latest/model-registry.html#migrating-from-stages
[2025-06-17T23:00:28.119+0000] {python.py:201} INFO - Done. Returned value was: None
[2025-06-17T23:00:28.145+0000] {taskinstance.py:1138} INFO - Marking task as SUCCESS. dag_id=entrenamiento_modelos_regresion, task_id=entrenar_y_promover, execution_date=20250616T210000, start_date=20250617T230010, end_date=20250617T230028
[2025-06-17T23:00:28.197+0000] {local_task_job_runner.py:234} INFO - Task exited with return code 0
[2025-06-17T23:00:28.241+0000] {taskinstance.py:3280} INFO - 1 downstream tasks scheduled from follow-on schedule check
[2025-06-18T01:01:21.260+0000] {taskinstance.py:1956} INFO - Dependencies all met for dep_context=non-requeueable deps ti=<TaskInstance: entrenamiento_modelos_regresion.entrenar_y_promover scheduled__2025-06-16T21:00:00+00:00 [queued]>
[2025-06-18T01:01:21.273+0000] {taskinstance.py:1956} INFO - Dependencies all met for dep_context=requeueable deps ti=<TaskInstance: entrenamiento_modelos_regresion.entrenar_y_promover scheduled__2025-06-16T21:00:00+00:00 [queued]>
[2025-06-18T01:01:21.273+0000] {taskinstance.py:2170} INFO - Starting attempt 2 of 2
[2025-06-18T01:01:21.292+0000] {taskinstance.py:2191} INFO - Executing <Task(_PythonDecoratedOperator): entrenar_y_promover> on 2025-06-16 21:00:00+00:00
[2025-06-18T01:01:21.297+0000] {standard_task_runner.py:60} INFO - Started process 1503 to run task
[2025-06-18T01:01:21.303+0000] {standard_task_runner.py:87} INFO - Running: ['***', 'tasks', 'run', 'entrenamiento_modelos_regresion', 'entrenar_y_promover', 'scheduled__2025-06-16T21:00:00+00:00', '--job-id', '11', '--raw', '--subdir', 'DAGS_FOLDER/entrenamiento_modelos_regresion_dag.py', '--cfg-path', '/tmp/tmppg8pguec']
[2025-06-18T01:01:21.306+0000] {standard_task_runner.py:88} INFO - Job 11: Subtask entrenar_y_promover
[2025-06-18T01:01:21.388+0000] {task_command.py:423} INFO - Running <TaskInstance: entrenamiento_modelos_regresion.entrenar_y_promover scheduled__2025-06-16T21:00:00+00:00 [running]> on host 7e38bae46728
[2025-06-18T01:01:21.508+0000] {taskinstance.py:2480} INFO - Exporting env vars: AIRFLOW_CTX_DAG_OWNER='fede' AIRFLOW_CTX_DAG_ID='entrenamiento_modelos_regresion' AIRFLOW_CTX_TASK_ID='entrenar_y_promover' AIRFLOW_CTX_EXECUTION_DATE='2025-06-16T21:00:00+00:00' AIRFLOW_CTX_TRY_NUMBER='2' AIRFLOW_CTX_DAG_RUN_ID='scheduled__2025-06-16T21:00:00+00:00'
[2025-06-18T01:01:23.196+0000] {logging_mixin.py:188} WARNING - /opt/***/dags/entrenamiento_modelos_regresion_dag.py:59 SettingWithCopyWarning:
A value is trying to be set on a copy of a slice from a DataFrame.
Try using .loc[row_indexer,col_indexer] = value instead

See the caveats in the documentation: https://pandas.pydata.org/pandas-docs/stable/user_guide/indexing.html#returning-a-view-versus-a-copy
[2025-06-18T01:01:23.209+0000] {logging_mixin.py:188} WARNING - /opt/***/dags/entrenamiento_modelos_regresion_dag.py:62 SettingWithCopyWarning:
A value is trying to be set on a copy of a slice from a DataFrame.
Try using .loc[row_indexer,col_indexer] = value instead

See the caveats in the documentation: https://pandas.pydata.org/pandas-docs/stable/user_guide/indexing.html#returning-a-view-versus-a-copy
[2025-06-18T01:01:23.211+0000] {logging_mixin.py:188} WARNING - /opt/***/dags/entrenamiento_modelos_regresion_dag.py:64 SettingWithCopyWarning:
A value is trying to be set on a copy of a slice from a DataFrame.
Try using .loc[row_indexer,col_indexer] = value instead

See the caveats in the documentation: https://pandas.pydata.org/pandas-docs/stable/user_guide/indexing.html#returning-a-view-versus-a-copy
[2025-06-18T01:01:23.213+0000] {logging_mixin.py:188} WARNING - /opt/***/dags/entrenamiento_modelos_regresion_dag.py:65 SettingWithCopyWarning:
A value is trying to be set on a copy of a slice from a DataFrame

See the caveats in the documentation: https://pandas.pydata.org/pandas-docs/stable/user_guide/indexing.html#returning-a-view-versus-a-copy
[2025-06-18T01:01:23.311+0000] {logging_mixin.py:188} WARNING - 2025/06/18 01:01:23 WARNING mlflow.utils.git_utils: Failed to import Git (the Git executable is probably not on your PATH), so Git SHA is not available. Error: Failed to initialize: Bad git executable.
The git executable must be specified in one of the following ways:
    - be included in your $PATH
    - be set via $GIT_PYTHON_GIT_EXECUTABLE
    - explicitly set via git.refresh(<full-path-to-git-executable>)

All git commands will error until this is rectified.

This initial message can be silenced or aggravated in the future by setting the
$GIT_PYTHON_REFRESH environment variable. Use one of the following values:
    - quiet|q|silence|s|silent|none|n|0: for no message or exception
    - warn|w|warning|log|l|1: for a warning message (logging level CRITICAL, displayed by default)
    - error|e|exception|raise|r|2: for a raised exception

Example:
    export GIT_PYTHON_REFRESH=quiet
[2025-06-18T01:01:27.102+0000] {logging_mixin.py:188} WARNING - 2025/06/18 01:01:27 WARNING mlflow.models.model: Model logged without a signature and input example. Please set `input_example` parameter when logging the model to auto infer the model signature.
[2025-06-18T01:01:27.145+0000] {logging_mixin.py:188} WARNING - 2025/06/18 01:01:27 INFO mlflow.tracking._tracking_service.client: üèÉ View run RandomForest at: http://mlflow:5000/#/experiments/1/runs/a6e23c661d4d4886868d54002e02ba98.
[2025-06-18T01:01:27.145+0000] {logging_mixin.py:188} WARNING - 2025/06/18 01:01:27 INFO mlflow.tracking._tracking_service.client: üß™ View experiment at: http://mlflow:5000/#/experiments/1.
[2025-06-18T01:01:27.167+0000] {taskinstance.py:2698} ERROR - Task failed with exception
Traceback (most recent call last):
  File "/home/airflow/.local/lib/python3.8/site-packages/airflow/models/taskinstance.py", line 433, in _execute_task
    result = execute_callable(context=context, **execute_callable_kwargs)
  File "/home/airflow/.local/lib/python3.8/site-packages/airflow/decorators/base.py", line 241, in execute
    return_value = super().execute(context)
  File "/home/airflow/.local/lib/python3.8/site-packages/airflow/operators/python.py", line 199, in execute
    return_value = self.execute_callable()
  File "/home/airflow/.local/lib/python3.8/site-packages/airflow/operators/python.py", line 216, in execute_callable
    return self.python_callable(*self.op_args, **self.op_kwargs)
  File "/opt/airflow/dags/entrenamiento_modelos_regresion_dag.py", line 103, in entrenar_y_promover
    mlflow.sklearn.log_model(modelo, "modelo")
  File "/home/airflow/.local/lib/python3.8/site-packages/mlflow/sklearn/__init__.py", line 413, in log_model
    return Model.log(
  File "/home/airflow/.local/lib/python3.8/site-packages/mlflow/models/model.py", line 744, in log
    mlflow.tracking.fluent.log_artifacts(local_path, mlflow_model.artifact_path, run_id)
  File "/home/airflow/.local/lib/python3.8/site-packages/mlflow/tracking/fluent.py", line 1170, in log_artifacts
    MlflowClient().log_artifacts(run_id, local_dir, artifact_path)
  File "/home/airflow/.local/lib/python3.8/site-packages/mlflow/tracking/client.py", line 1977, in log_artifacts
    self._tracking_client.log_artifacts(run_id, local_dir, artifact_path)
  File "/home/airflow/.local/lib/python3.8/site-packages/mlflow/tracking/_tracking_service/client.py", line 874, in log_artifacts
    self._get_artifact_repo(run_id).log_artifacts(local_dir, artifact_path)
  File "/home/airflow/.local/lib/python3.8/site-packages/mlflow/store/artifact/local_artifact_repo.py", line 66, in log_artifacts
    mkdir(artifact_dir)
  File "/home/airflow/.local/lib/python3.8/site-packages/mlflow/utils/file_utils.py", line 211, in mkdir
    raise e
  File "/home/airflow/.local/lib/python3.8/site-packages/mlflow/utils/file_utils.py", line 208, in mkdir
    os.makedirs(target, exist_ok=True)
  File "/usr/local/lib/python3.8/os.py", line 213, in makedirs
    makedirs(head, exist_ok=exist_ok)
  File "/usr/local/lib/python3.8/os.py", line 213, in makedirs
    makedirs(head, exist_ok=exist_ok)
  File "/usr/local/lib/python3.8/os.py", line 223, in makedirs
    mkdir(name, mode)
PermissionError: [Errno 13] Permission denied: '/mlflow/mlruns/1/a6e23c661d4d4886868d54002e02ba98'
[2025-06-18T01:01:27.189+0000] {taskinstance.py:1138} INFO - Marking task as FAILED. dag_id=entrenamiento_modelos_regresion, task_id=entrenar_y_promover, execution_date=20250616T210000, start_date=20250618T010121, end_date=20250618T010127
[2025-06-18T01:01:27.238+0000] {standard_task_runner.py:107} ERROR - Failed to execute job 11 for task entrenar_y_promover ([Errno 13] Permission denied: '/mlflow/mlruns/1/a6e23c661d4d4886868d54002e02ba98'; 1503)
[2025-06-18T01:01:27.297+0000] {local_task_job_runner.py:234} INFO - Task exited with return code 1
[2025-06-18T01:01:27.327+0000] {taskinstance.py:3280} INFO - 0 downstream tasks scheduled from follow-on schedule check
