[2025-06-17T22:49:45.132+0000] {taskinstance.py:1956} INFO - Dependencies all met for dep_context=non-requeueable deps ti=<TaskInstance: entrenamiento_modelos_regresion.entrenar_y_promover scheduled__2025-06-16T21:00:00+00:00 [queued]>
[2025-06-17T22:49:45.145+0000] {taskinstance.py:1956} INFO - Dependencies all met for dep_context=requeueable deps ti=<TaskInstance: entrenamiento_modelos_regresion.entrenar_y_promover scheduled__2025-06-16T21:00:00+00:00 [queued]>
[2025-06-17T22:49:45.146+0000] {taskinstance.py:2170} INFO - Starting attempt 1 of 2
[2025-06-17T22:49:45.168+0000] {taskinstance.py:2191} INFO - Executing <Task(_PythonDecoratedOperator): entrenar_y_promover> on 2025-06-16 21:00:00+00:00
[2025-06-17T22:49:45.176+0000] {standard_task_runner.py:60} INFO - Started process 200 to run task
[2025-06-17T22:49:45.181+0000] {standard_task_runner.py:87} INFO - Running: ['***', 'tasks', 'run', 'entrenamiento_modelos_regresion', 'entrenar_y_promover', 'scheduled__2025-06-16T21:00:00+00:00', '--job-id', '211', '--raw', '--subdir', 'DAGS_FOLDER/entrenamiento_modelos_regresion_dag.py', '--cfg-path', '/tmp/tmpgt_ch59s']
[2025-06-17T22:49:45.185+0000] {standard_task_runner.py:88} INFO - Job 211: Subtask entrenar_y_promover
[2025-06-17T22:49:45.280+0000] {task_command.py:423} INFO - Running <TaskInstance: entrenamiento_modelos_regresion.entrenar_y_promover scheduled__2025-06-16T21:00:00+00:00 [running]> on host cdfb22e6be80
[2025-06-17T22:49:45.457+0000] {taskinstance.py:2480} INFO - Exporting env vars: AIRFLOW_CTX_DAG_OWNER='fede' AIRFLOW_CTX_DAG_ID='entrenamiento_modelos_regresion' AIRFLOW_CTX_TASK_ID='entrenar_y_promover' AIRFLOW_CTX_EXECUTION_DATE='2025-06-16T21:00:00+00:00' AIRFLOW_CTX_TRY_NUMBER='1' AIRFLOW_CTX_DAG_RUN_ID='scheduled__2025-06-16T21:00:00+00:00'
[2025-06-17T22:49:53.841+0000] {logging_mixin.py:188} WARNING - /opt/***/dags/entrenamiento_modelos_regresion_dag.py:53 SettingWithCopyWarning:
A value is trying to be set on a copy of a slice from a DataFrame.
Try using .loc[row_indexer,col_indexer] = value instead

See the caveats in the documentation: https://pandas.pydata.org/pandas-docs/stable/user_guide/indexing.html#returning-a-view-versus-a-copy
[2025-06-17T22:49:53.859+0000] {logging_mixin.py:188} WARNING - /opt/***/dags/entrenamiento_modelos_regresion_dag.py:56 SettingWithCopyWarning:
A value is trying to be set on a copy of a slice from a DataFrame.
Try using .loc[row_indexer,col_indexer] = value instead

See the caveats in the documentation: https://pandas.pydata.org/pandas-docs/stable/user_guide/indexing.html#returning-a-view-versus-a-copy
[2025-06-17T22:49:53.862+0000] {logging_mixin.py:188} WARNING - /opt/***/dags/entrenamiento_modelos_regresion_dag.py:58 SettingWithCopyWarning:
A value is trying to be set on a copy of a slice from a DataFrame.
Try using .loc[row_indexer,col_indexer] = value instead

See the caveats in the documentation: https://pandas.pydata.org/pandas-docs/stable/user_guide/indexing.html#returning-a-view-versus-a-copy
[2025-06-17T22:49:53.865+0000] {logging_mixin.py:188} WARNING - /opt/***/dags/entrenamiento_modelos_regresion_dag.py:59 SettingWithCopyWarning:
A value is trying to be set on a copy of a slice from a DataFrame

See the caveats in the documentation: https://pandas.pydata.org/pandas-docs/stable/user_guide/indexing.html#returning-a-view-versus-a-copy
[2025-06-17T22:49:57.590+0000] {connectionpool.py:824} WARNING - Retrying (JitteredRetry(total=4, connect=4, read=5, redirect=5, status=5)) after connection broken by 'NewConnectionError('<urllib3.connection.HTTPConnection object at 0x7586ffeaa790>: Failed to establish a new connection: [Errno -2] Name or service not known')': /api/2.0/mlflow/experiments/get-by-name?experiment_name=entrenamiento_orquestado
[2025-06-17T22:50:02.963+0000] {connectionpool.py:824} WARNING - Retrying (JitteredRetry(total=3, connect=3, read=5, redirect=5, status=5)) after connection broken by 'NewConnectionError('<urllib3.connection.HTTPConnection object at 0x7586ffeaa6a0>: Failed to establish a new connection: [Errno -2] Name or service not known')': /api/2.0/mlflow/experiments/get-by-name?experiment_name=entrenamiento_orquestado
[2025-06-17T22:50:14.607+0000] {connectionpool.py:824} WARNING - Retrying (JitteredRetry(total=2, connect=2, read=5, redirect=5, status=5)) after connection broken by 'NewConnectionError('<urllib3.connection.HTTPConnection object at 0x7586ffec2cd0>: Failed to establish a new connection: [Errno -2] Name or service not known')': /api/2.0/mlflow/experiments/get-by-name?experiment_name=entrenamiento_orquestado
[2025-06-17T22:50:31.898+0000] {connectionpool.py:824} WARNING - Retrying (JitteredRetry(total=1, connect=1, read=5, redirect=5, status=5)) after connection broken by 'NewConnectionError('<urllib3.connection.HTTPConnection object at 0x7586ffec2e20>: Failed to establish a new connection: [Errno -2] Name or service not known')': /api/2.0/mlflow/experiments/get-by-name?experiment_name=entrenamiento_orquestado
[2025-06-17T22:51:05.221+0000] {connectionpool.py:824} WARNING - Retrying (JitteredRetry(total=0, connect=0, read=5, redirect=5, status=5)) after connection broken by 'NewConnectionError('<urllib3.connection.HTTPConnection object at 0x7586ffec2b20>: Failed to establish a new connection: [Errno -2] Name or service not known')': /api/2.0/mlflow/experiments/get-by-name?experiment_name=entrenamiento_orquestado
[2025-06-17T22:51:08.910+0000] {taskinstance.py:2698} ERROR - Task failed with exception
Traceback (most recent call last):
  File "/home/airflow/.local/lib/python3.8/site-packages/urllib3/connection.py", line 174, in _new_conn
    conn = connection.create_connection(
  File "/home/airflow/.local/lib/python3.8/site-packages/urllib3/util/connection.py", line 72, in create_connection
    for res in socket.getaddrinfo(host, port, family, socket.SOCK_STREAM):
  File "/usr/local/lib/python3.8/socket.py", line 918, in getaddrinfo
    for res in _socket.getaddrinfo(host, port, family, type, proto, flags):
socket.gaierror: [Errno -2] Name or service not known

During handling of the above exception, another exception occurred:

Traceback (most recent call last):
  File "/home/airflow/.local/lib/python3.8/site-packages/urllib3/connectionpool.py", line 715, in urlopen
    httplib_response = self._make_request(
  File "/home/airflow/.local/lib/python3.8/site-packages/urllib3/connectionpool.py", line 416, in _make_request
    conn.request(method, url, **httplib_request_kw)
  File "/home/airflow/.local/lib/python3.8/site-packages/urllib3/connection.py", line 244, in request
    super(HTTPConnection, self).request(method, url, body=body, headers=headers)
  File "/usr/local/lib/python3.8/http/client.py", line 1256, in request
    self._send_request(method, url, body, headers, encode_chunked)
  File "/usr/local/lib/python3.8/http/client.py", line 1302, in _send_request
    self.endheaders(body, encode_chunked=encode_chunked)
  File "/usr/local/lib/python3.8/http/client.py", line 1251, in endheaders
    self._send_output(message_body, encode_chunked=encode_chunked)
  File "/usr/local/lib/python3.8/http/client.py", line 1011, in _send_output
    self.send(msg)
  File "/usr/local/lib/python3.8/http/client.py", line 951, in send
    self.connect()
  File "/home/airflow/.local/lib/python3.8/site-packages/urllib3/connection.py", line 205, in connect
    conn = self._new_conn()
  File "/home/airflow/.local/lib/python3.8/site-packages/urllib3/connection.py", line 186, in _new_conn
    raise NewConnectionError(
urllib3.exceptions.NewConnectionError: <urllib3.connection.HTTPConnection object at 0x7586ffec2940>: Failed to establish a new connection: [Errno -2] Name or service not known

During handling of the above exception, another exception occurred:

Traceback (most recent call last):
  File "/home/airflow/.local/lib/python3.8/site-packages/requests/adapters.py", line 486, in send
    resp = conn.urlopen(
  File "/home/airflow/.local/lib/python3.8/site-packages/urllib3/connectionpool.py", line 827, in urlopen
    return self.urlopen(
  File "/home/airflow/.local/lib/python3.8/site-packages/urllib3/connectionpool.py", line 827, in urlopen
    return self.urlopen(
  File "/home/airflow/.local/lib/python3.8/site-packages/urllib3/connectionpool.py", line 827, in urlopen
    return self.urlopen(
  [Previous line repeated 2 more times]
  File "/home/airflow/.local/lib/python3.8/site-packages/urllib3/connectionpool.py", line 799, in urlopen
    retries = retries.increment(
  File "/home/airflow/.local/lib/python3.8/site-packages/urllib3/util/retry.py", line 592, in increment
    raise MaxRetryError(_pool, url, error or ResponseError(cause))
urllib3.exceptions.MaxRetryError: HTTPConnectionPool(host='mlflow', port=5000): Max retries exceeded with url: /api/2.0/mlflow/experiments/get-by-name?experiment_name=entrenamiento_orquestado (Caused by NewConnectionError('<urllib3.connection.HTTPConnection object at 0x7586ffec2940>: Failed to establish a new connection: [Errno -2] Name or service not known'))

During handling of the above exception, another exception occurred:

Traceback (most recent call last):
  File "/home/airflow/.local/lib/python3.8/site-packages/mlflow/utils/rest_utils.py", line 189, in http_request
    return _get_http_response_with_retries(
  File "/home/airflow/.local/lib/python3.8/site-packages/mlflow/utils/request_utils.py", line 237, in _get_http_response_with_retries
    return session.request(method, url, allow_redirects=allow_redirects, **kwargs)
  File "/home/airflow/.local/lib/python3.8/site-packages/requests/sessions.py", line 589, in request
    resp = self.send(prep, **send_kwargs)
  File "/home/airflow/.local/lib/python3.8/site-packages/requests/sessions.py", line 703, in send
    r = adapter.send(request, **kwargs)
  File "/home/airflow/.local/lib/python3.8/site-packages/requests/adapters.py", line 519, in send
    raise ConnectionError(e, request=request)
requests.exceptions.ConnectionError: HTTPConnectionPool(host='mlflow', port=5000): Max retries exceeded with url: /api/2.0/mlflow/experiments/get-by-name?experiment_name=entrenamiento_orquestado (Caused by NewConnectionError('<urllib3.connection.HTTPConnection object at 0x7586ffec2940>: Failed to establish a new connection: [Errno -2] Name or service not known'))

During handling of the above exception, another exception occurred:

Traceback (most recent call last):
  File "/home/airflow/.local/lib/python3.8/site-packages/airflow/models/taskinstance.py", line 433, in _execute_task
    result = execute_callable(context=context, **execute_callable_kwargs)
  File "/home/airflow/.local/lib/python3.8/site-packages/airflow/decorators/base.py", line 241, in execute
    return_value = super().execute(context)
  File "/home/airflow/.local/lib/python3.8/site-packages/airflow/operators/python.py", line 199, in execute
    return_value = self.execute_callable()
  File "/home/airflow/.local/lib/python3.8/site-packages/airflow/operators/python.py", line 216, in execute_callable
    return self.python_callable(*self.op_args, **self.op_kwargs)
  File "/opt/airflow/dags/entrenamiento_modelos_regresion_dag.py", line 75, in entrenar_y_promover
    mlflow.set_experiment("entrenamiento_orquestado")
  File "/home/airflow/.local/lib/python3.8/site-packages/mlflow/tracking/fluent.py", line 145, in set_experiment
    experiment = client.get_experiment_by_name(experiment_name)
  File "/home/airflow/.local/lib/python3.8/site-packages/mlflow/tracking/client.py", line 1256, in get_experiment_by_name
    return self._tracking_client.get_experiment_by_name(name)
  File "/home/airflow/.local/lib/python3.8/site-packages/mlflow/tracking/_tracking_service/client.py", line 501, in get_experiment_by_name
    return self.store.get_experiment_by_name(name)
  File "/home/airflow/.local/lib/python3.8/site-packages/mlflow/store/tracking/rest_store.py", line 519, in get_experiment_by_name
    response_proto = self._call_endpoint(GetExperimentByName, req_body)
  File "/home/airflow/.local/lib/python3.8/site-packages/mlflow/store/tracking/rest_store.py", line 82, in _call_endpoint
    return call_endpoint(self.get_host_creds(), endpoint, method, json_body, response_proto)
  File "/home/airflow/.local/lib/python3.8/site-packages/mlflow/utils/rest_utils.py", line 365, in call_endpoint
    response = http_request(**call_kwargs)
  File "/home/airflow/.local/lib/python3.8/site-packages/mlflow/utils/rest_utils.py", line 212, in http_request
    raise MlflowException(f"API request to {url} failed with exception {e}")
mlflow.exceptions.MlflowException: API request to http://mlflow:5000/api/2.0/mlflow/experiments/get-by-name failed with exception HTTPConnectionPool(host='mlflow', port=5000): Max retries exceeded with url: /api/2.0/mlflow/experiments/get-by-name?experiment_name=entrenamiento_orquestado (Caused by NewConnectionError('<urllib3.connection.HTTPConnection object at 0x7586ffec2940>: Failed to establish a new connection: [Errno -2] Name or service not known'))
[2025-06-17T22:51:09.003+0000] {taskinstance.py:1138} INFO - Marking task as UP_FOR_RETRY. dag_id=entrenamiento_modelos_regresion, task_id=entrenar_y_promover, execution_date=20250616T210000, start_date=20250617T224945, end_date=20250617T225109
[2025-06-17T22:51:09.061+0000] {standard_task_runner.py:107} ERROR - Failed to execute job 211 for task entrenar_y_promover (API request to http://mlflow:5000/api/2.0/mlflow/experiments/get-by-name failed with exception HTTPConnectionPool(host='mlflow', port=5000): Max retries exceeded with url: /api/2.0/mlflow/experiments/get-by-name?experiment_name=entrenamiento_orquestado (Caused by NewConnectionError('<urllib3.connection.HTTPConnection object at 0x7586ffec2940>: Failed to establish a new connection: [Errno -2] Name or service not known')); 200)
[2025-06-17T22:51:09.146+0000] {local_task_job_runner.py:234} INFO - Task exited with return code 1
[2025-06-17T22:51:09.186+0000] {taskinstance.py:3280} INFO - 0 downstream tasks scheduled from follow-on schedule check
[2025-06-18T00:55:52.080+0000] {taskinstance.py:1956} INFO - Dependencies all met for dep_context=non-requeueable deps ti=<TaskInstance: entrenamiento_modelos_regresion.entrenar_y_promover scheduled__2025-06-16T21:00:00+00:00 [queued]>
[2025-06-18T00:55:52.092+0000] {taskinstance.py:1956} INFO - Dependencies all met for dep_context=requeueable deps ti=<TaskInstance: entrenamiento_modelos_regresion.entrenar_y_promover scheduled__2025-06-16T21:00:00+00:00 [queued]>
[2025-06-18T00:55:52.092+0000] {taskinstance.py:2170} INFO - Starting attempt 1 of 2
[2025-06-18T00:55:52.109+0000] {taskinstance.py:2191} INFO - Executing <Task(_PythonDecoratedOperator): entrenar_y_promover> on 2025-06-16 21:00:00+00:00
[2025-06-18T00:55:52.117+0000] {standard_task_runner.py:60} INFO - Started process 477 to run task
[2025-06-18T00:55:52.124+0000] {standard_task_runner.py:87} INFO - Running: ['***', 'tasks', 'run', 'entrenamiento_modelos_regresion', 'entrenar_y_promover', 'scheduled__2025-06-16T21:00:00+00:00', '--job-id', '4', '--raw', '--subdir', 'DAGS_FOLDER/entrenamiento_modelos_regresion_dag.py', '--cfg-path', '/tmp/tmpupivzpbq']
[2025-06-18T00:55:52.128+0000] {standard_task_runner.py:88} INFO - Job 4: Subtask entrenar_y_promover
[2025-06-18T00:55:52.236+0000] {task_command.py:423} INFO - Running <TaskInstance: entrenamiento_modelos_regresion.entrenar_y_promover scheduled__2025-06-16T21:00:00+00:00 [running]> on host 7e38bae46728
[2025-06-18T00:55:52.364+0000] {taskinstance.py:2480} INFO - Exporting env vars: AIRFLOW_CTX_DAG_OWNER='fede' AIRFLOW_CTX_DAG_ID='entrenamiento_modelos_regresion' AIRFLOW_CTX_TASK_ID='entrenar_y_promover' AIRFLOW_CTX_EXECUTION_DATE='2025-06-16T21:00:00+00:00' AIRFLOW_CTX_TRY_NUMBER='1' AIRFLOW_CTX_DAG_RUN_ID='scheduled__2025-06-16T21:00:00+00:00'
[2025-06-18T00:56:00.555+0000] {logging_mixin.py:188} WARNING - /opt/***/dags/entrenamiento_modelos_regresion_dag.py:59 SettingWithCopyWarning:
A value is trying to be set on a copy of a slice from a DataFrame.
Try using .loc[row_indexer,col_indexer] = value instead

See the caveats in the documentation: https://pandas.pydata.org/pandas-docs/stable/user_guide/indexing.html#returning-a-view-versus-a-copy
[2025-06-18T00:56:00.593+0000] {logging_mixin.py:188} WARNING - /opt/***/dags/entrenamiento_modelos_regresion_dag.py:62 SettingWithCopyWarning:
A value is trying to be set on a copy of a slice from a DataFrame.
Try using .loc[row_indexer,col_indexer] = value instead

See the caveats in the documentation: https://pandas.pydata.org/pandas-docs/stable/user_guide/indexing.html#returning-a-view-versus-a-copy
[2025-06-18T00:56:00.599+0000] {logging_mixin.py:188} WARNING - /opt/***/dags/entrenamiento_modelos_regresion_dag.py:64 SettingWithCopyWarning:
A value is trying to be set on a copy of a slice from a DataFrame.
Try using .loc[row_indexer,col_indexer] = value instead

See the caveats in the documentation: https://pandas.pydata.org/pandas-docs/stable/user_guide/indexing.html#returning-a-view-versus-a-copy
[2025-06-18T00:56:00.615+0000] {logging_mixin.py:188} WARNING - /opt/***/dags/entrenamiento_modelos_regresion_dag.py:65 SettingWithCopyWarning:
A value is trying to be set on a copy of a slice from a DataFrame

See the caveats in the documentation: https://pandas.pydata.org/pandas-docs/stable/user_guide/indexing.html#returning-a-view-versus-a-copy
[2025-06-18T00:56:00.846+0000] {logging_mixin.py:188} WARNING - 2025/06/18 00:56:00 INFO mlflow.tracking.fluent: Experiment with name 'entrenamiento_orquestado' does not exist. Creating a new experiment.
[2025-06-18T00:56:01.074+0000] {logging_mixin.py:188} WARNING - 2025/06/18 00:56:01 WARNING mlflow.utils.git_utils: Failed to import Git (the Git executable is probably not on your PATH), so Git SHA is not available. Error: Failed to initialize: Bad git executable.
The git executable must be specified in one of the following ways:
    - be included in your $PATH
    - be set via $GIT_PYTHON_GIT_EXECUTABLE
    - explicitly set via git.refresh(<full-path-to-git-executable>)

All git commands will error until this is rectified.

This initial message can be silenced or aggravated in the future by setting the
$GIT_PYTHON_REFRESH environment variable. Use one of the following values:
    - quiet|q|silence|s|silent|none|n|0: for no message or exception
    - warn|w|warning|log|l|1: for a warning message (logging level CRITICAL, displayed by default)
    - error|e|exception|raise|r|2: for a raised exception

Example:
    export GIT_PYTHON_REFRESH=quiet
[2025-06-18T00:56:20.190+0000] {logging_mixin.py:188} WARNING - 2025/06/18 00:56:20 WARNING mlflow.models.model: Model logged without a signature and input example. Please set `input_example` parameter when logging the model to auto infer the model signature.
[2025-06-18T00:56:20.243+0000] {logging_mixin.py:188} WARNING - 2025/06/18 00:56:20 INFO mlflow.tracking._tracking_service.client: 🏃 View run RandomForest at: http://mlflow:5000/#/experiments/1/runs/4d9f6de978a0452983b28fd0f7e0231f.
[2025-06-18T00:56:20.243+0000] {logging_mixin.py:188} WARNING - 2025/06/18 00:56:20 INFO mlflow.tracking._tracking_service.client: 🧪 View experiment at: http://mlflow:5000/#/experiments/1.
[2025-06-18T00:56:20.279+0000] {taskinstance.py:2698} ERROR - Task failed with exception
Traceback (most recent call last):
  File "/home/airflow/.local/lib/python3.8/site-packages/airflow/models/taskinstance.py", line 433, in _execute_task
    result = execute_callable(context=context, **execute_callable_kwargs)
  File "/home/airflow/.local/lib/python3.8/site-packages/airflow/decorators/base.py", line 241, in execute
    return_value = super().execute(context)
  File "/home/airflow/.local/lib/python3.8/site-packages/airflow/operators/python.py", line 199, in execute
    return_value = self.execute_callable()
  File "/home/airflow/.local/lib/python3.8/site-packages/airflow/operators/python.py", line 216, in execute_callable
    return self.python_callable(*self.op_args, **self.op_kwargs)
  File "/opt/airflow/dags/entrenamiento_modelos_regresion_dag.py", line 103, in entrenar_y_promover
    mlflow.sklearn.log_model(modelo, "modelo")
  File "/home/airflow/.local/lib/python3.8/site-packages/mlflow/sklearn/__init__.py", line 413, in log_model
    return Model.log(
  File "/home/airflow/.local/lib/python3.8/site-packages/mlflow/models/model.py", line 744, in log
    mlflow.tracking.fluent.log_artifacts(local_path, mlflow_model.artifact_path, run_id)
  File "/home/airflow/.local/lib/python3.8/site-packages/mlflow/tracking/fluent.py", line 1170, in log_artifacts
    MlflowClient().log_artifacts(run_id, local_dir, artifact_path)
  File "/home/airflow/.local/lib/python3.8/site-packages/mlflow/tracking/client.py", line 1977, in log_artifacts
    self._tracking_client.log_artifacts(run_id, local_dir, artifact_path)
  File "/home/airflow/.local/lib/python3.8/site-packages/mlflow/tracking/_tracking_service/client.py", line 874, in log_artifacts
    self._get_artifact_repo(run_id).log_artifacts(local_dir, artifact_path)
  File "/home/airflow/.local/lib/python3.8/site-packages/mlflow/store/artifact/local_artifact_repo.py", line 66, in log_artifacts
    mkdir(artifact_dir)
  File "/home/airflow/.local/lib/python3.8/site-packages/mlflow/utils/file_utils.py", line 211, in mkdir
    raise e
  File "/home/airflow/.local/lib/python3.8/site-packages/mlflow/utils/file_utils.py", line 208, in mkdir
    os.makedirs(target, exist_ok=True)
  File "/usr/local/lib/python3.8/os.py", line 213, in makedirs
    makedirs(head, exist_ok=exist_ok)
  File "/usr/local/lib/python3.8/os.py", line 213, in makedirs
    makedirs(head, exist_ok=exist_ok)
  File "/usr/local/lib/python3.8/os.py", line 223, in makedirs
    mkdir(name, mode)
PermissionError: [Errno 13] Permission denied: '/mlflow/mlruns/1/4d9f6de978a0452983b28fd0f7e0231f'
[2025-06-18T00:56:20.350+0000] {taskinstance.py:1138} INFO - Marking task as UP_FOR_RETRY. dag_id=entrenamiento_modelos_regresion, task_id=entrenar_y_promover, execution_date=20250616T210000, start_date=20250618T005552, end_date=20250618T005620
[2025-06-18T00:56:20.398+0000] {standard_task_runner.py:107} ERROR - Failed to execute job 4 for task entrenar_y_promover ([Errno 13] Permission denied: '/mlflow/mlruns/1/4d9f6de978a0452983b28fd0f7e0231f'; 477)
[2025-06-18T00:56:20.464+0000] {local_task_job_runner.py:234} INFO - Task exited with return code 1
[2025-06-18T00:56:20.541+0000] {taskinstance.py:3280} INFO - 0 downstream tasks scheduled from follow-on schedule check
