[2025-06-15T11:41:54.952+0000] {taskinstance.py:1956} INFO - Dependencies all met for dep_context=non-requeueable deps ti=<TaskInstance: entrenamiento_modelos_regresion.trigger_prediccion manual__2025-06-15T11:41:31.458328+00:00 [queued]>
[2025-06-15T11:41:54.969+0000] {taskinstance.py:1956} INFO - Dependencies all met for dep_context=requeueable deps ti=<TaskInstance: entrenamiento_modelos_regresion.trigger_prediccion manual__2025-06-15T11:41:31.458328+00:00 [queued]>
[2025-06-15T11:41:54.969+0000] {taskinstance.py:2170} INFO - Starting attempt 1 of 2
[2025-06-15T11:41:54.994+0000] {taskinstance.py:2191} INFO - Executing <Task(TriggerDagRunOperator): trigger_prediccion> on 2025-06-15 11:41:31.458328+00:00
[2025-06-15T11:41:55.002+0000] {standard_task_runner.py:60} INFO - Started process 467 to run task
[2025-06-15T11:41:55.007+0000] {standard_task_runner.py:87} INFO - Running: ['***', 'tasks', 'run', 'entrenamiento_modelos_regresion', 'trigger_prediccion', 'manual__2025-06-15T11:41:31.458328+00:00', '--job-id', '175', '--raw', '--subdir', 'DAGS_FOLDER/entrenamiento_modelos_regresion_dag.py', '--cfg-path', '/tmp/tmphu5cjke4']
[2025-06-15T11:41:55.010+0000] {standard_task_runner.py:88} INFO - Job 175: Subtask trigger_prediccion
[2025-06-15T11:41:55.112+0000] {task_command.py:423} INFO - Running <TaskInstance: entrenamiento_modelos_regresion.trigger_prediccion manual__2025-06-15T11:41:31.458328+00:00 [running]> on host e0d496ebcdc0
[2025-06-15T11:41:55.354+0000] {taskinstance.py:2480} INFO - Exporting env vars: AIRFLOW_CTX_DAG_OWNER='fede' AIRFLOW_CTX_DAG_ID='entrenamiento_modelos_regresion' AIRFLOW_CTX_TASK_ID='trigger_prediccion' AIRFLOW_CTX_EXECUTION_DATE='2025-06-15T11:41:31.458328+00:00' AIRFLOW_CTX_TRY_NUMBER='1' AIRFLOW_CTX_DAG_RUN_ID='manual__2025-06-15T11:41:31.458328+00:00'
[2025-06-15T11:41:55.489+0000] {taskinstance.py:2698} ERROR - Task failed with exception
Traceback (most recent call last):
  File "/home/airflow/.local/lib/python3.8/site-packages/airflow/models/taskinstance.py", line 433, in _execute_task
    result = execute_callable(context=context, **execute_callable_kwargs)
  File "/home/airflow/.local/lib/python3.8/site-packages/airflow/operators/trigger_dagrun.py", line 165, in execute
    dag_run = trigger_dag(
  File "/home/airflow/.local/lib/python3.8/site-packages/airflow/api/common/trigger_dag.py", line 125, in trigger_dag
    triggers = _trigger_dag(
  File "/home/airflow/.local/lib/python3.8/site-packages/airflow/api/common/trigger_dag.py", line 55, in _trigger_dag
    raise DagNotFound(f"Dag id {dag_id} not found")
airflow.exceptions.DagNotFound: Dag id prediccion_modelo_produccion_dag not found
[2025-06-15T11:41:55.506+0000] {taskinstance.py:1138} INFO - Marking task as UP_FOR_RETRY. dag_id=entrenamiento_modelos_regresion, task_id=trigger_prediccion, execution_date=20250615T114131, start_date=20250615T114154, end_date=20250615T114155
[2025-06-15T11:41:55.589+0000] {standard_task_runner.py:107} ERROR - Failed to execute job 175 for task trigger_prediccion (Dag id prediccion_modelo_produccion_dag not found; 467)
[2025-06-15T11:41:55.674+0000] {local_task_job_runner.py:234} INFO - Task exited with return code 1
[2025-06-15T11:41:55.829+0000] {taskinstance.py:3280} INFO - 0 downstream tasks scheduled from follow-on schedule check
