[2025-05-31T11:35:19.718+0000] {taskinstance.py:1956} INFO - Dependencies all met for dep_context=non-requeueable deps ti=<TaskInstance: entrenamiento_modelos_regresion.entrenar_y_promover scheduled__2025-05-29T21:00:00+00:00 [queued]>
[2025-05-31T11:35:19.745+0000] {taskinstance.py:1956} INFO - Dependencies all met for dep_context=requeueable deps ti=<TaskInstance: entrenamiento_modelos_regresion.entrenar_y_promover scheduled__2025-05-29T21:00:00+00:00 [queued]>
[2025-05-31T11:35:19.745+0000] {taskinstance.py:2170} INFO - Starting attempt 1 of 2
[2025-05-31T11:35:19.806+0000] {taskinstance.py:2191} INFO - Executing <Task(_PythonDecoratedOperator): entrenar_y_promover> on 2025-05-29 21:00:00+00:00
[2025-05-31T11:35:19.823+0000] {standard_task_runner.py:60} INFO - Started process 199 to run task
[2025-05-31T11:35:19.828+0000] {standard_task_runner.py:87} INFO - Running: ['***', 'tasks', 'run', 'entrenamiento_modelos_regresion', 'entrenar_y_promover', 'scheduled__2025-05-29T21:00:00+00:00', '--job-id', '23', '--raw', '--subdir', 'DAGS_FOLDER/entrenamiento_modelos_regresion_dag.py', '--cfg-path', '/tmp/tmplhpkfoy3']
[2025-05-31T11:35:19.836+0000] {standard_task_runner.py:88} INFO - Job 23: Subtask entrenar_y_promover
[2025-05-31T11:35:20.077+0000] {task_command.py:423} INFO - Running <TaskInstance: entrenamiento_modelos_regresion.entrenar_y_promover scheduled__2025-05-29T21:00:00+00:00 [running]> on host 3ee3f6d1c85c
[2025-05-31T11:35:20.418+0000] {taskinstance.py:2480} INFO - Exporting env vars: AIRFLOW_CTX_DAG_OWNER='fede' AIRFLOW_CTX_DAG_ID='entrenamiento_modelos_regresion' AIRFLOW_CTX_TASK_ID='entrenar_y_promover' AIRFLOW_CTX_EXECUTION_DATE='2025-05-29T21:00:00+00:00' AIRFLOW_CTX_TRY_NUMBER='1' AIRFLOW_CTX_DAG_RUN_ID='scheduled__2025-05-29T21:00:00+00:00'
[2025-05-31T11:35:27.426+0000] {logging_mixin.py:188} WARNING - /opt/***/dags/entrenamiento_modelos_regresion_dag.py:52 SettingWithCopyWarning:
A value is trying to be set on a copy of a slice from a DataFrame.
Try using .loc[row_indexer,col_indexer] = value instead

See the caveats in the documentation: https://pandas.pydata.org/pandas-docs/stable/user_guide/indexing.html#returning-a-view-versus-a-copy
[2025-05-31T11:35:27.454+0000] {logging_mixin.py:188} WARNING - /opt/***/dags/entrenamiento_modelos_regresion_dag.py:55 SettingWithCopyWarning:
A value is trying to be set on a copy of a slice from a DataFrame.
Try using .loc[row_indexer,col_indexer] = value instead

See the caveats in the documentation: https://pandas.pydata.org/pandas-docs/stable/user_guide/indexing.html#returning-a-view-versus-a-copy
[2025-05-31T11:35:27.456+0000] {logging_mixin.py:188} WARNING - /opt/***/dags/entrenamiento_modelos_regresion_dag.py:57 SettingWithCopyWarning:
A value is trying to be set on a copy of a slice from a DataFrame.
Try using .loc[row_indexer,col_indexer] = value instead

See the caveats in the documentation: https://pandas.pydata.org/pandas-docs/stable/user_guide/indexing.html#returning-a-view-versus-a-copy
[2025-05-31T11:35:27.459+0000] {logging_mixin.py:188} WARNING - /opt/***/dags/entrenamiento_modelos_regresion_dag.py:59 SettingWithCopyWarning:
A value is trying to be set on a copy of a slice from a DataFrame

See the caveats in the documentation: https://pandas.pydata.org/pandas-docs/stable/user_guide/indexing.html#returning-a-view-versus-a-copy
[2025-05-31T11:35:27.660+0000] {logging_mixin.py:188} WARNING - 2025/05/31 11:35:27 INFO mlflow.tracking.fluent: Experiment with name 'entrenamiento_orquestado' does not exist. Creating a new experiment.
[2025-05-31T11:35:27.867+0000] {logging_mixin.py:188} WARNING - 2025/05/31 11:35:27 WARNING mlflow.utils.git_utils: Failed to import Git (the Git executable is probably not on your PATH), so Git SHA is not available. Error: Failed to initialize: Bad git executable.
The git executable must be specified in one of the following ways:
    - be included in your $PATH
    - be set via $GIT_PYTHON_GIT_EXECUTABLE
    - explicitly set via git.refresh(<full-path-to-git-executable>)

All git commands will error until this is rectified.

This initial message can be silenced or aggravated in the future by setting the
$GIT_PYTHON_REFRESH environment variable. Use one of the following values:
    - quiet|q|silence|s|silent|none|n|0: for no message or exception
    - warn|w|warning|log|l|1: for a warning message (logging level CRITICAL, displayed by default)
    - error|e|exception|raise|r|2: for a raised exception

Example:
    export GIT_PYTHON_REFRESH=quiet
[2025-05-31T11:35:33.927+0000] {logging_mixin.py:188} WARNING - 2025/05/31 11:35:33 WARNING mlflow.models.model: Model logged without a signature and input example. Please set `input_example` parameter when logging the model to auto infer the model signature.
[2025-05-31T11:35:34.113+0000] {logging_mixin.py:188} WARNING - 2025/05/31 11:35:34 INFO mlflow.tracking._tracking_service.client: üèÉ View run RandomForest at: http://mlflow:5000/#/experiments/1/runs/e8f4f08e068a494eaa2b6035606f95a1.
[2025-05-31T11:35:34.113+0000] {logging_mixin.py:188} WARNING - 2025/05/31 11:35:34 INFO mlflow.tracking._tracking_service.client: üß™ View experiment at: http://mlflow:5000/#/experiments/1.
[2025-05-31T11:35:34.316+0000] {taskinstance.py:2698} ERROR - Task failed with exception
Traceback (most recent call last):
  File "/home/airflow/.local/lib/python3.8/site-packages/airflow/models/taskinstance.py", line 433, in _execute_task
    result = execute_callable(context=context, **execute_callable_kwargs)
  File "/home/airflow/.local/lib/python3.8/site-packages/airflow/decorators/base.py", line 241, in execute
    return_value = super().execute(context)
  File "/home/airflow/.local/lib/python3.8/site-packages/airflow/operators/python.py", line 199, in execute
    return_value = self.execute_callable()
  File "/home/airflow/.local/lib/python3.8/site-packages/airflow/operators/python.py", line 216, in execute_callable
    return self.python_callable(*self.op_args, **self.op_kwargs)
  File "/opt/airflow/dags/entrenamiento_modelos_regresion_dag.py", line 85, in entrenar_y_promover
    mlflow.sklearn.log_model(modelo, "modelo")
  File "/home/airflow/.local/lib/python3.8/site-packages/mlflow/sklearn/__init__.py", line 413, in log_model
    return Model.log(
  File "/home/airflow/.local/lib/python3.8/site-packages/mlflow/models/model.py", line 744, in log
    mlflow.tracking.fluent.log_artifacts(local_path, mlflow_model.artifact_path, run_id)
  File "/home/airflow/.local/lib/python3.8/site-packages/mlflow/tracking/fluent.py", line 1170, in log_artifacts
    MlflowClient().log_artifacts(run_id, local_dir, artifact_path)
  File "/home/airflow/.local/lib/python3.8/site-packages/mlflow/tracking/client.py", line 1977, in log_artifacts
    self._tracking_client.log_artifacts(run_id, local_dir, artifact_path)
  File "/home/airflow/.local/lib/python3.8/site-packages/mlflow/tracking/_tracking_service/client.py", line 874, in log_artifacts
    self._get_artifact_repo(run_id).log_artifacts(local_dir, artifact_path)
  File "/home/airflow/.local/lib/python3.8/site-packages/mlflow/store/artifact/local_artifact_repo.py", line 66, in log_artifacts
    mkdir(artifact_dir)
  File "/home/airflow/.local/lib/python3.8/site-packages/mlflow/utils/file_utils.py", line 211, in mkdir
    raise e
  File "/home/airflow/.local/lib/python3.8/site-packages/mlflow/utils/file_utils.py", line 208, in mkdir
    os.makedirs(target, exist_ok=True)
  File "/usr/local/lib/python3.8/os.py", line 213, in makedirs
    makedirs(head, exist_ok=exist_ok)
  File "/usr/local/lib/python3.8/os.py", line 213, in makedirs
    makedirs(head, exist_ok=exist_ok)
  File "/usr/local/lib/python3.8/os.py", line 223, in makedirs
    mkdir(name, mode)
PermissionError: [Errno 13] Permission denied: '/mlflow/mlruns/1/e8f4f08e068a494eaa2b6035606f95a1'
[2025-05-31T11:35:34.392+0000] {taskinstance.py:1138} INFO - Marking task as UP_FOR_RETRY. dag_id=entrenamiento_modelos_regresion, task_id=entrenar_y_promover, execution_date=20250529T210000, start_date=20250531T113519, end_date=20250531T113534
[2025-05-31T11:35:34.419+0000] {standard_task_runner.py:107} ERROR - Failed to execute job 23 for task entrenar_y_promover ([Errno 13] Permission denied: '/mlflow/mlruns/1/e8f4f08e068a494eaa2b6035606f95a1'; 199)
[2025-05-31T11:35:34.495+0000] {local_task_job_runner.py:234} INFO - Task exited with return code 1
[2025-05-31T11:35:34.528+0000] {taskinstance.py:3280} INFO - 0 downstream tasks scheduled from follow-on schedule check
[2025-05-31T16:54:01.439+0000] {taskinstance.py:1956} INFO - Dependencies all met for dep_context=non-requeueable deps ti=<TaskInstance: entrenamiento_modelos_regresion.entrenar_y_promover scheduled__2025-05-29T21:00:00+00:00 [queued]>
[2025-05-31T16:54:01.474+0000] {taskinstance.py:1956} INFO - Dependencies all met for dep_context=requeueable deps ti=<TaskInstance: entrenamiento_modelos_regresion.entrenar_y_promover scheduled__2025-05-29T21:00:00+00:00 [queued]>
[2025-05-31T16:54:01.477+0000] {taskinstance.py:2170} INFO - Starting attempt 1 of 2
[2025-05-31T16:54:01.528+0000] {taskinstance.py:2191} INFO - Executing <Task(_PythonDecoratedOperator): entrenar_y_promover> on 2025-05-29 21:00:00+00:00
[2025-05-31T16:54:01.548+0000] {standard_task_runner.py:60} INFO - Started process 398 to run task
[2025-05-31T16:54:01.568+0000] {standard_task_runner.py:87} INFO - Running: ['***', 'tasks', 'run', 'entrenamiento_modelos_regresion', 'entrenar_y_promover', 'scheduled__2025-05-29T21:00:00+00:00', '--job-id', '5', '--raw', '--subdir', 'DAGS_FOLDER/entrenamiento_modelos_regresion_dag.py', '--cfg-path', '/tmp/tmpt6yj8pc4']
[2025-05-31T16:54:01.577+0000] {standard_task_runner.py:88} INFO - Job 5: Subtask entrenar_y_promover
[2025-05-31T16:54:01.916+0000] {task_command.py:423} INFO - Running <TaskInstance: entrenamiento_modelos_regresion.entrenar_y_promover scheduled__2025-05-29T21:00:00+00:00 [running]> on host 5b1f99eb2bfd
[2025-05-31T16:54:02.375+0000] {taskinstance.py:2480} INFO - Exporting env vars: AIRFLOW_CTX_DAG_OWNER='fede' AIRFLOW_CTX_DAG_ID='entrenamiento_modelos_regresion' AIRFLOW_CTX_TASK_ID='entrenar_y_promover' AIRFLOW_CTX_EXECUTION_DATE='2025-05-29T21:00:00+00:00' AIRFLOW_CTX_TRY_NUMBER='1' AIRFLOW_CTX_DAG_RUN_ID='scheduled__2025-05-29T21:00:00+00:00'
[2025-05-31T16:54:09.037+0000] {taskinstance.py:2698} ERROR - Task failed with exception
Traceback (most recent call last):
  File "/home/airflow/.local/lib/python3.8/site-packages/pandas/io/pickle.py", line 196, in read_pickle
    return pickle.load(handles.handle)
ModuleNotFoundError: No module named 'ity,brand,model,year,price,detail_url,km,motor,ano,tipo,combustible,color,transmision,puertas'

During handling of the above exception, another exception occurred:

Traceback (most recent call last):
  File "/home/airflow/.local/lib/python3.8/site-packages/airflow/models/taskinstance.py", line 433, in _execute_task
    result = execute_callable(context=context, **execute_callable_kwargs)
  File "/home/airflow/.local/lib/python3.8/site-packages/airflow/decorators/base.py", line 241, in execute
    return_value = super().execute(context)
  File "/home/airflow/.local/lib/python3.8/site-packages/airflow/operators/python.py", line 199, in execute
    return_value = self.execute_callable()
  File "/home/airflow/.local/lib/python3.8/site-packages/airflow/operators/python.py", line 216, in execute_callable
    return self.python_callable(*self.op_args, **self.op_kwargs)
  File "/opt/airflow/dags/entrenamiento_modelos_regresion_dag.py", line 34, in entrenar_y_promover
    df = pd.read_pickle("/opt/airflow/dags/data/raw/scraped_autopia_2025-05-31.csv")
  File "/home/airflow/.local/lib/python3.8/site-packages/pandas/io/pickle.py", line 201, in read_pickle
    return pc.load(handles.handle, encoding=None)
  File "/home/airflow/.local/lib/python3.8/site-packages/pandas/compat/pickle_compat.py", line 218, in load
    return up.load()
  File "/usr/local/lib/python3.8/pickle.py", line 1212, in load
    dispatch[key[0]](self)
  File "/usr/local/lib/python3.8/pickle.py", line 1528, in load_global
    klass = self.find_class(module, name)
  File "/home/airflow/.local/lib/python3.8/site-packages/pandas/compat/pickle_compat.py", line 149, in find_class
    return super().find_class(module, name)
  File "/usr/local/lib/python3.8/pickle.py", line 1579, in find_class
    __import__(module, level=0)
ModuleNotFoundError: No module named 'ity,brand,model,year,price,detail_url,km,motor,ano,tipo,combustible,color,transmision,puertas'
[2025-05-31T16:54:09.070+0000] {taskinstance.py:1138} INFO - Marking task as UP_FOR_RETRY. dag_id=entrenamiento_modelos_regresion, task_id=entrenar_y_promover, execution_date=20250529T210000, start_date=20250531T165401, end_date=20250531T165409
[2025-05-31T16:54:09.096+0000] {standard_task_runner.py:107} ERROR - Failed to execute job 5 for task entrenar_y_promover (No module named 'ity,brand,model,year,price,detail_url,km,motor,ano,tipo,combustible,color,transmision,puertas'; 398)
[2025-05-31T16:54:09.183+0000] {local_task_job_runner.py:234} INFO - Task exited with return code 1
[2025-05-31T16:54:09.266+0000] {taskinstance.py:3280} INFO - 0 downstream tasks scheduled from follow-on schedule check
