[2025-05-25T17:54:46.978+0000] {taskinstance.py:1956} INFO - Dependencies all met for dep_context=non-requeueable deps ti=<TaskInstance: entrenamiento_modelos_regresion.entrenar_y_promover manual__2025-05-25T17:54:45.689292+00:00 [queued]>
[2025-05-25T17:54:47.009+0000] {taskinstance.py:1956} INFO - Dependencies all met for dep_context=requeueable deps ti=<TaskInstance: entrenamiento_modelos_regresion.entrenar_y_promover manual__2025-05-25T17:54:45.689292+00:00 [queued]>
[2025-05-25T17:54:47.010+0000] {taskinstance.py:2170} INFO - Starting attempt 1 of 2
[2025-05-25T17:54:47.067+0000] {taskinstance.py:2191} INFO - Executing <Task(_PythonDecoratedOperator): entrenar_y_promover> on 2025-05-25 17:54:45.689292+00:00
[2025-05-25T17:54:47.082+0000] {standard_task_runner.py:60} INFO - Started process 508 to run task
[2025-05-25T17:54:47.096+0000] {standard_task_runner.py:87} INFO - Running: ['***', 'tasks', 'run', 'entrenamiento_modelos_regresion', 'entrenar_y_promover', 'manual__2025-05-25T17:54:45.689292+00:00', '--job-id', '12', '--raw', '--subdir', 'DAGS_FOLDER/entrenamiento_modelos_regresion_dag.py', '--cfg-path', '/tmp/tmp5fhpmgb0']
[2025-05-25T17:54:47.104+0000] {standard_task_runner.py:88} INFO - Job 12: Subtask entrenar_y_promover
[2025-05-25T17:54:47.225+0000] {task_command.py:423} INFO - Running <TaskInstance: entrenamiento_modelos_regresion.entrenar_y_promover manual__2025-05-25T17:54:45.689292+00:00 [running]> on host f2a09463ba3f
[2025-05-25T17:54:47.411+0000] {taskinstance.py:2480} INFO - Exporting env vars: AIRFLOW_CTX_DAG_OWNER='fede' AIRFLOW_CTX_DAG_ID='entrenamiento_modelos_regresion' AIRFLOW_CTX_TASK_ID='entrenar_y_promover' AIRFLOW_CTX_EXECUTION_DATE='2025-05-25T17:54:45.689292+00:00' AIRFLOW_CTX_TRY_NUMBER='1' AIRFLOW_CTX_DAG_RUN_ID='manual__2025-05-25T17:54:45.689292+00:00'
[2025-05-25T17:54:57.553+0000] {logging_mixin.py:188} WARNING - /opt/***/dags/entrenamiento_modelos_regresion_dag.py:52 SettingWithCopyWarning:
A value is trying to be set on a copy of a slice from a DataFrame.
Try using .loc[row_indexer,col_indexer] = value instead

See the caveats in the documentation: https://pandas.pydata.org/pandas-docs/stable/user_guide/indexing.html#returning-a-view-versus-a-copy
[2025-05-25T17:54:57.577+0000] {logging_mixin.py:188} WARNING - /opt/***/dags/entrenamiento_modelos_regresion_dag.py:55 SettingWithCopyWarning:
A value is trying to be set on a copy of a slice from a DataFrame.
Try using .loc[row_indexer,col_indexer] = value instead

See the caveats in the documentation: https://pandas.pydata.org/pandas-docs/stable/user_guide/indexing.html#returning-a-view-versus-a-copy
[2025-05-25T17:54:57.581+0000] {logging_mixin.py:188} WARNING - /opt/***/dags/entrenamiento_modelos_regresion_dag.py:57 SettingWithCopyWarning:
A value is trying to be set on a copy of a slice from a DataFrame.
Try using .loc[row_indexer,col_indexer] = value instead

See the caveats in the documentation: https://pandas.pydata.org/pandas-docs/stable/user_guide/indexing.html#returning-a-view-versus-a-copy
[2025-05-25T17:54:57.585+0000] {logging_mixin.py:188} WARNING - /opt/***/dags/entrenamiento_modelos_regresion_dag.py:59 SettingWithCopyWarning:
A value is trying to be set on a copy of a slice from a DataFrame

See the caveats in the documentation: https://pandas.pydata.org/pandas-docs/stable/user_guide/indexing.html#returning-a-view-versus-a-copy
[2025-05-25T17:54:58.796+0000] {logging_mixin.py:188} WARNING - 2025/05/25 17:54:58 WARNING mlflow.utils.git_utils: Failed to import Git (the Git executable is probably not on your PATH), so Git SHA is not available. Error: Failed to initialize: Bad git executable.
The git executable must be specified in one of the following ways:
    - be included in your $PATH
    - be set via $GIT_PYTHON_GIT_EXECUTABLE
    - explicitly set via git.refresh(<full-path-to-git-executable>)

All git commands will error until this is rectified.

This initial message can be silenced or aggravated in the future by setting the
$GIT_PYTHON_REFRESH environment variable. Use one of the following values:
    - quiet|q|silence|s|silent|none|n|0: for no message or exception
    - warn|w|warning|log|l|1: for a warning message (logging level CRITICAL, displayed by default)
    - error|e|exception|raise|r|2: for a raised exception

Example:
    export GIT_PYTHON_REFRESH=quiet
[2025-05-25T17:55:31.420+0000] {job.py:213} ERROR - Job heartbeat got an exception
Traceback (most recent call last):
  File "/home/airflow/.local/lib/python3.8/site-packages/sqlalchemy/engine/base.py", line 3371, in _wrap_pool_connect
    return fn()
  File "/home/airflow/.local/lib/python3.8/site-packages/sqlalchemy/pool/base.py", line 327, in connect
    return _ConnectionFairy._checkout(self)
  File "/home/airflow/.local/lib/python3.8/site-packages/sqlalchemy/pool/base.py", line 894, in _checkout
    fairy = _ConnectionRecord.checkout(pool)
  File "/home/airflow/.local/lib/python3.8/site-packages/sqlalchemy/pool/base.py", line 493, in checkout
    rec = pool._do_get()
  File "/home/airflow/.local/lib/python3.8/site-packages/sqlalchemy/pool/impl.py", line 256, in _do_get
    return self._create_connection()
  File "/home/airflow/.local/lib/python3.8/site-packages/sqlalchemy/pool/base.py", line 273, in _create_connection
    return _ConnectionRecord(self)
  File "/home/airflow/.local/lib/python3.8/site-packages/sqlalchemy/pool/base.py", line 388, in __init__
    self.__connect()
  File "/home/airflow/.local/lib/python3.8/site-packages/sqlalchemy/pool/base.py", line 691, in __connect
    pool.logger.debug("Error on connect(): %s", e)
  File "/home/airflow/.local/lib/python3.8/site-packages/sqlalchemy/util/langhelpers.py", line 70, in __exit__
    compat.raise_(
  File "/home/airflow/.local/lib/python3.8/site-packages/sqlalchemy/util/compat.py", line 211, in raise_
    raise exception
  File "/home/airflow/.local/lib/python3.8/site-packages/sqlalchemy/pool/base.py", line 686, in __connect
    self.dbapi_connection = connection = pool._invoke_creator(self)
  File "/home/airflow/.local/lib/python3.8/site-packages/sqlalchemy/engine/create.py", line 574, in connect
    return dialect.connect(*cargs, **cparams)
  File "/home/airflow/.local/lib/python3.8/site-packages/sqlalchemy/engine/default.py", line 598, in connect
    return self.dbapi.connect(*cargs, **cparams)
  File "/home/airflow/.local/lib/python3.8/site-packages/psycopg2/__init__.py", line 122, in connect
    conn = _connect(dsn, connection_factory=connection_factory, **kwasync)
psycopg2.OperationalError: could not translate host name "postgres" to address: Temporary failure in name resolution


The above exception was the direct cause of the following exception:

Traceback (most recent call last):
  File "/home/airflow/.local/lib/python3.8/site-packages/airflow/jobs/job.py", line 187, in heartbeat
    self._merge_from(Job._fetch_from_db(self, session))
  File "/home/airflow/.local/lib/python3.8/site-packages/airflow/api_internal/internal_api_call.py", line 114, in wrapper
    return func(*args, **kwargs)
  File "/home/airflow/.local/lib/python3.8/site-packages/airflow/utils/session.py", line 76, in wrapper
    return func(*args, **kwargs)
  File "/home/airflow/.local/lib/python3.8/site-packages/airflow/jobs/job.py", line 308, in _fetch_from_db
    session.merge(job)
  File "/home/airflow/.local/lib/python3.8/site-packages/sqlalchemy/orm/session.py", line 3056, in merge
    return self._merge(
  File "/home/airflow/.local/lib/python3.8/site-packages/sqlalchemy/orm/session.py", line 3136, in _merge
    merged = self.get(
  File "/home/airflow/.local/lib/python3.8/site-packages/sqlalchemy/orm/session.py", line 2853, in get
    return self._get_impl(
  File "/home/airflow/.local/lib/python3.8/site-packages/sqlalchemy/orm/session.py", line 2975, in _get_impl
    return db_load_fn(
  File "/home/airflow/.local/lib/python3.8/site-packages/sqlalchemy/orm/loading.py", line 530, in load_on_pk_identity
    session.execute(
  File "/home/airflow/.local/lib/python3.8/site-packages/sqlalchemy/orm/session.py", line 1716, in execute
    conn = self._connection_for_bind(bind)
  File "/home/airflow/.local/lib/python3.8/site-packages/sqlalchemy/orm/session.py", line 1555, in _connection_for_bind
    return self._transaction._connection_for_bind(
  File "/home/airflow/.local/lib/python3.8/site-packages/sqlalchemy/orm/session.py", line 750, in _connection_for_bind
    conn = bind.connect()
  File "/home/airflow/.local/lib/python3.8/site-packages/sqlalchemy/future/engine.py", line 412, in connect
    return super(Engine, self).connect()
  File "/home/airflow/.local/lib/python3.8/site-packages/sqlalchemy/engine/base.py", line 3325, in connect
    return self._connection_cls(self, close_with_result=close_with_result)
  File "/home/airflow/.local/lib/python3.8/site-packages/sqlalchemy/engine/base.py", line 96, in __init__
    else engine.raw_connection()
  File "/home/airflow/.local/lib/python3.8/site-packages/sqlalchemy/engine/base.py", line 3404, in raw_connection
    return self._wrap_pool_connect(self.pool.connect, _connection)
  File "/home/airflow/.local/lib/python3.8/site-packages/sqlalchemy/engine/base.py", line 3374, in _wrap_pool_connect
    Connection._handle_dbapi_exception_noconnection(
  File "/home/airflow/.local/lib/python3.8/site-packages/sqlalchemy/engine/base.py", line 2208, in _handle_dbapi_exception_noconnection
    util.raise_(
  File "/home/airflow/.local/lib/python3.8/site-packages/sqlalchemy/util/compat.py", line 211, in raise_
    raise exception
  File "/home/airflow/.local/lib/python3.8/site-packages/sqlalchemy/engine/base.py", line 3371, in _wrap_pool_connect
    return fn()
  File "/home/airflow/.local/lib/python3.8/site-packages/sqlalchemy/pool/base.py", line 327, in connect
    return _ConnectionFairy._checkout(self)
  File "/home/airflow/.local/lib/python3.8/site-packages/sqlalchemy/pool/base.py", line 894, in _checkout
    fairy = _ConnectionRecord.checkout(pool)
  File "/home/airflow/.local/lib/python3.8/site-packages/sqlalchemy/pool/base.py", line 493, in checkout
    rec = pool._do_get()
  File "/home/airflow/.local/lib/python3.8/site-packages/sqlalchemy/pool/impl.py", line 256, in _do_get
    return self._create_connection()
  File "/home/airflow/.local/lib/python3.8/site-packages/sqlalchemy/pool/base.py", line 273, in _create_connection
    return _ConnectionRecord(self)
  File "/home/airflow/.local/lib/python3.8/site-packages/sqlalchemy/pool/base.py", line 388, in __init__
    self.__connect()
  File "/home/airflow/.local/lib/python3.8/site-packages/sqlalchemy/pool/base.py", line 691, in __connect
    pool.logger.debug("Error on connect(): %s", e)
  File "/home/airflow/.local/lib/python3.8/site-packages/sqlalchemy/util/langhelpers.py", line 70, in __exit__
    compat.raise_(
  File "/home/airflow/.local/lib/python3.8/site-packages/sqlalchemy/util/compat.py", line 211, in raise_
    raise exception
  File "/home/airflow/.local/lib/python3.8/site-packages/sqlalchemy/pool/base.py", line 686, in __connect
    self.dbapi_connection = connection = pool._invoke_creator(self)
  File "/home/airflow/.local/lib/python3.8/site-packages/sqlalchemy/engine/create.py", line 574, in connect
    return dialect.connect(*cargs, **cparams)
  File "/home/airflow/.local/lib/python3.8/site-packages/sqlalchemy/engine/default.py", line 598, in connect
    return self.dbapi.connect(*cargs, **cparams)
  File "/home/airflow/.local/lib/python3.8/site-packages/psycopg2/__init__.py", line 122, in connect
    conn = _connect(dsn, connection_factory=connection_factory, **kwasync)
sqlalchemy.exc.OperationalError: (psycopg2.OperationalError) could not translate host name "postgres" to address: Temporary failure in name resolution

(Background on this error at: https://sqlalche.me/e/14/e3q8)
[2025-05-25T17:55:32.812+0000] {job.py:221} ERROR - Job heartbeat failed with error. Scheduler is in unhealthy state
[2025-05-25T17:55:48.230+0000] {job.py:221} ERROR - Job heartbeat failed with error. Scheduler is in unhealthy state
[2025-05-25T17:56:12.447+0000] {job.py:221} ERROR - Job heartbeat failed with error. Scheduler is in unhealthy state
[2025-05-25T17:56:26.362+0000] {job.py:221} ERROR - Job heartbeat failed with error. Scheduler is in unhealthy state
[2025-05-25T17:56:41.612+0000] {job.py:221} ERROR - Job heartbeat failed with error. Scheduler is in unhealthy state
[2025-05-25T17:56:41.996+0000] {logging_mixin.py:188} WARNING - 2025/05/25 17:56:41 WARNING mlflow.models.model: Model logged without a signature and input example. Please set `input_example` parameter when logging the model to auto infer the model signature.
[2025-05-25T17:56:43.871+0000] {logging_mixin.py:188} WARNING - 2025/05/25 17:56:43 INFO mlflow.tracking._tracking_service.client: 🏃 View run RandomForest at: http://mlflow:5000/#/experiments/1/runs/3e6bfe45231647d4ad903bd80c05371d.
[2025-05-25T17:56:43.872+0000] {logging_mixin.py:188} WARNING - 2025/05/25 17:56:43 INFO mlflow.tracking._tracking_service.client: 🧪 View experiment at: http://mlflow:5000/#/experiments/1.
[2025-05-25T17:57:21.278+0000] {job.py:221} ERROR - Job heartbeat failed with error. Scheduler is in unhealthy state
[2025-05-25T17:57:35.948+0000] {job.py:221} ERROR - Job heartbeat failed with error. Scheduler is in unhealthy state
[2025-05-25T17:57:56.215+0000] {job.py:221} ERROR - Job heartbeat failed with error. Scheduler is in unhealthy state
[2025-05-25T17:58:51.111+0000] {logging_mixin.py:188} WARNING - 2025/05/25 17:58:50 WARNING mlflow.utils.environment: Encountered an unexpected error while inferring pip requirements (model URI: /tmp/tmpxhpyq6p0/model/model.pkl, flavor: sklearn). Fall back to return ['scikit-learn==1.3.2', 'cloudpickle==3.1.1']. Set logging level to DEBUG to see the full traceback.
[2025-05-25T17:58:51.352+0000] {job.py:221} ERROR - Job heartbeat failed with error. Scheduler is in unhealthy state
[2025-05-25T17:58:50.605+0000] {logging_mixin.py:188} WARNING - 2025/05/25 17:58:50 WARNING mlflow.models.model: Model logged without a signature and input example. Please set `input_example` parameter when logging the model to auto infer the model signature.
[2025-05-25T17:58:54.871+0000] {logging_mixin.py:188} WARNING - 2025/05/25 17:58:54 INFO mlflow.tracking._tracking_service.client: 🏃 View run CatBoost at: http://mlflow:5000/#/experiments/1/runs/29fd4e3a1b8b436ca282449ef01b8b7b.
[2025-05-25T17:58:54.881+0000] {logging_mixin.py:188} WARNING - 2025/05/25 17:58:54 INFO mlflow.tracking._tracking_service.client: 🧪 View experiment at: http://mlflow:5000/#/experiments/1.
[2025-05-25T17:59:10.377+0000] {job.py:221} ERROR - Job heartbeat failed with error. Scheduler is in unhealthy state
[2025-05-25T17:59:24.081+0000] {job.py:221} ERROR - Job heartbeat failed with error. Scheduler is in unhealthy state
[2025-05-25T18:00:05.972+0000] {job.py:221} ERROR - Job heartbeat failed with error. Scheduler is in unhealthy state
[2025-05-25T18:00:30.941+0000] {job.py:221} ERROR - Job heartbeat failed with error. Scheduler is in unhealthy state
[2025-05-25T18:00:53.824+0000] {job.py:221} ERROR - Job heartbeat failed with error. Scheduler is in unhealthy state
[2025-05-25T18:00:56.776+0000] {logging_mixin.py:188} WARNING - 2025/05/25 18:00:56 WARNING mlflow.utils.environment: Encountered an unexpected error while inferring pip requirements (model URI: /tmp/tmpbwvgnpab/model/model.pkl, flavor: sklearn). Fall back to return ['scikit-learn==1.3.2', 'cloudpickle==3.1.1']. Set logging level to DEBUG to see the full traceback.
[2025-05-25T18:00:57.384+0000] {logging_mixin.py:188} WARNING - 2025/05/25 18:00:57 WARNING mlflow.models.model: Model logged without a signature and input example. Please set `input_example` parameter when logging the model to auto infer the model signature.
[2025-05-25T18:01:08.053+0000] {logging_mixin.py:188} WARNING - 2025/05/25 18:01:08 INFO mlflow.tracking._tracking_service.client: 🏃 View run SVR at: http://mlflow:5000/#/experiments/1/runs/3cec9a5a3f924b289bf017ea153b00c5.
[2025-05-25T18:01:08.057+0000] {logging_mixin.py:188} WARNING - 2025/05/25 18:01:08 INFO mlflow.tracking._tracking_service.client: 🧪 View experiment at: http://mlflow:5000/#/experiments/1.
[2025-05-25T18:01:13.265+0000] {logging_mixin.py:188} WARNING - Registered model 'mejor_modelo_orquestado' already exists. Creating a new version of this model...
[2025-05-25T18:01:13.991+0000] {logging_mixin.py:188} WARNING - 2025/05/25 18:01:13 INFO mlflow.store.model_registry.abstract_store: Waiting up to 300 seconds for model version to finish creation. Model name: mejor_modelo_orquestado, version 3
[2025-05-25T18:01:13.991+0000] {logging_mixin.py:188} WARNING - Created version '3' of model 'mejor_modelo_orquestado'.
[2025-05-25T18:01:14.002+0000] {logging_mixin.py:188} WARNING - /opt/***/dags/entrenamiento_modelos_regresion_dag.py:95 FutureWarning: ``mlflow.tracking.client.MlflowClient.get_latest_versions`` is deprecated since 2.9.0. Model registry stages will be removed in a future major release. To learn more about the deprecation of model registry stages, see our migration guide here: https://mlflow.org/docs/latest/model-registry.html#migrating-from-stages
[2025-05-25T18:01:14.185+0000] {logging_mixin.py:188} WARNING - /opt/***/dags/entrenamiento_modelos_regresion_dag.py:105 FutureWarning: ``mlflow.tracking.client.MlflowClient.transition_model_version_stage`` is deprecated since 2.9.0. Model registry stages will be removed in a future major release. To learn more about the deprecation of model registry stages, see our migration guide here: https://mlflow.org/docs/latest/model-registry.html#migrating-from-stages
[2025-05-25T18:01:14.459+0000] {logging_mixin.py:188} WARNING - /opt/***/dags/entrenamiento_modelos_regresion_dag.py:98 FutureWarning: ``mlflow.tracking.client.MlflowClient.transition_model_version_stage`` is deprecated since 2.9.0. Model registry stages will be removed in a future major release. To learn more about the deprecation of model registry stages, see our migration guide here: https://mlflow.org/docs/latest/model-registry.html#migrating-from-stages
[2025-05-25T18:01:14.713+0000] {python.py:201} INFO - Done. Returned value was: None
[2025-05-25T18:01:15.065+0000] {taskinstance.py:1138} INFO - Marking task as SUCCESS. dag_id=entrenamiento_modelos_regresion, task_id=entrenar_y_promover, execution_date=20250525T175445, start_date=20250525T175446, end_date=20250525T180115
[2025-05-25T18:01:15.351+0000] {local_task_job_runner.py:234} INFO - Task exited with return code 0
[2025-05-25T18:01:15.530+0000] {taskinstance.py:3280} INFO - 0 downstream tasks scheduled from follow-on schedule check
