[2025-05-31T23:21:32.618+0000] {taskinstance.py:1956} INFO - Dependencies all met for dep_context=non-requeueable deps ti=<TaskInstance: entrenamiento_modelos_regresion.entrenar_y_promover scheduled__2025-05-30T21:00:00+00:00 [queued]>
[2025-05-31T23:21:32.634+0000] {taskinstance.py:1956} INFO - Dependencies all met for dep_context=requeueable deps ti=<TaskInstance: entrenamiento_modelos_regresion.entrenar_y_promover scheduled__2025-05-30T21:00:00+00:00 [queued]>
[2025-05-31T23:21:32.635+0000] {taskinstance.py:2170} INFO - Starting attempt 1 of 2
[2025-05-31T23:21:32.658+0000] {taskinstance.py:2191} INFO - Executing <Task(_PythonDecoratedOperator): entrenar_y_promover> on 2025-05-30 21:00:00+00:00
[2025-05-31T23:21:32.668+0000] {standard_task_runner.py:60} INFO - Started process 197 to run task
[2025-05-31T23:21:32.674+0000] {standard_task_runner.py:87} INFO - Running: ['***', 'tasks', 'run', 'entrenamiento_modelos_regresion', 'entrenar_y_promover', 'scheduled__2025-05-30T21:00:00+00:00', '--job-id', '16', '--raw', '--subdir', 'DAGS_FOLDER/entrenamiento_modelos_regresion_dag.py', '--cfg-path', '/tmp/tmpezmvc03o']
[2025-05-31T23:21:32.677+0000] {standard_task_runner.py:88} INFO - Job 16: Subtask entrenar_y_promover
[2025-05-31T23:21:32.794+0000] {task_command.py:423} INFO - Running <TaskInstance: entrenamiento_modelos_regresion.entrenar_y_promover scheduled__2025-05-30T21:00:00+00:00 [running]> on host 993869572b99
[2025-05-31T23:21:32.975+0000] {taskinstance.py:2480} INFO - Exporting env vars: AIRFLOW_CTX_DAG_OWNER='fede' AIRFLOW_CTX_DAG_ID='entrenamiento_modelos_regresion' AIRFLOW_CTX_TASK_ID='entrenar_y_promover' AIRFLOW_CTX_EXECUTION_DATE='2025-05-30T21:00:00+00:00' AIRFLOW_CTX_TRY_NUMBER='1' AIRFLOW_CTX_DAG_RUN_ID='scheduled__2025-05-30T21:00:00+00:00'
[2025-05-31T23:21:36.869+0000] {logging_mixin.py:188} WARNING - /opt/***/dags/entrenamiento_modelos_regresion_dag.py:56 SettingWithCopyWarning:
A value is trying to be set on a copy of a slice from a DataFrame.
Try using .loc[row_indexer,col_indexer] = value instead

See the caveats in the documentation: https://pandas.pydata.org/pandas-docs/stable/user_guide/indexing.html#returning-a-view-versus-a-copy
[2025-05-31T23:21:36.946+0000] {logging_mixin.py:188} WARNING - /opt/***/dags/entrenamiento_modelos_regresion_dag.py:59 SettingWithCopyWarning:
A value is trying to be set on a copy of a slice from a DataFrame.
Try using .loc[row_indexer,col_indexer] = value instead

See the caveats in the documentation: https://pandas.pydata.org/pandas-docs/stable/user_guide/indexing.html#returning-a-view-versus-a-copy
[2025-05-31T23:21:36.954+0000] {logging_mixin.py:188} WARNING - /opt/***/dags/entrenamiento_modelos_regresion_dag.py:61 SettingWithCopyWarning:
A value is trying to be set on a copy of a slice from a DataFrame.
Try using .loc[row_indexer,col_indexer] = value instead

See the caveats in the documentation: https://pandas.pydata.org/pandas-docs/stable/user_guide/indexing.html#returning-a-view-versus-a-copy
[2025-05-31T23:21:36.961+0000] {logging_mixin.py:188} WARNING - /opt/***/dags/entrenamiento_modelos_regresion_dag.py:63 SettingWithCopyWarning:
A value is trying to be set on a copy of a slice from a DataFrame

See the caveats in the documentation: https://pandas.pydata.org/pandas-docs/stable/user_guide/indexing.html#returning-a-view-versus-a-copy
[2025-05-31T23:21:44.651+0000] {connectionpool.py:824} WARNING - Retrying (JitteredRetry(total=4, connect=4, read=5, redirect=5, status=5)) after connection broken by 'NewConnectionError('<urllib3.connection.HTTPConnection object at 0x7a401d2e2220>: Failed to establish a new connection: [Errno -2] Name or service not known')': /api/2.0/mlflow/experiments/get-by-name?experiment_name=entrenamiento_orquestado
[2025-05-31T23:21:52.163+0000] {connectionpool.py:824} WARNING - Retrying (JitteredRetry(total=3, connect=3, read=5, redirect=5, status=5)) after connection broken by 'NewConnectionError('<urllib3.connection.HTTPConnection object at 0x7a401d2e2100>: Failed to establish a new connection: [Errno -2] Name or service not known')': /api/2.0/mlflow/experiments/get-by-name?experiment_name=entrenamiento_orquestado
[2025-05-31T23:22:01.911+0000] {connectionpool.py:824} WARNING - Retrying (JitteredRetry(total=2, connect=2, read=5, redirect=5, status=5)) after connection broken by 'NewConnectionError('<urllib3.connection.HTTPConnection object at 0x7a401d2e8df0>: Failed to establish a new connection: [Errno -2] Name or service not known')': /api/2.0/mlflow/experiments/get-by-name?experiment_name=entrenamiento_orquestado
[2025-05-31T23:22:21.454+0000] {connectionpool.py:824} WARNING - Retrying (JitteredRetry(total=1, connect=1, read=5, redirect=5, status=5)) after connection broken by 'NewConnectionError('<urllib3.connection.HTTPConnection object at 0x7a401d2e8bb0>: Failed to establish a new connection: [Errno -2] Name or service not known')': /api/2.0/mlflow/experiments/get-by-name?experiment_name=entrenamiento_orquestado
[2025-05-31T23:22:53.530+0000] {connectionpool.py:824} WARNING - Retrying (JitteredRetry(total=0, connect=0, read=5, redirect=5, status=5)) after connection broken by 'NewConnectionError('<urllib3.connection.HTTPConnection object at 0x7a401d2e8790>: Failed to establish a new connection: [Errno -2] Name or service not known')': /api/2.0/mlflow/experiments/get-by-name?experiment_name=entrenamiento_orquestado
[2025-05-31T23:22:57.088+0000] {taskinstance.py:2698} ERROR - Task failed with exception
Traceback (most recent call last):
  File "/home/airflow/.local/lib/python3.8/site-packages/urllib3/connection.py", line 174, in _new_conn
    conn = connection.create_connection(
  File "/home/airflow/.local/lib/python3.8/site-packages/urllib3/util/connection.py", line 72, in create_connection
    for res in socket.getaddrinfo(host, port, family, socket.SOCK_STREAM):
  File "/usr/local/lib/python3.8/socket.py", line 918, in getaddrinfo
    for res in _socket.getaddrinfo(host, port, family, type, proto, flags):
socket.gaierror: [Errno -2] Name or service not known

During handling of the above exception, another exception occurred:

Traceback (most recent call last):
  File "/home/airflow/.local/lib/python3.8/site-packages/urllib3/connectionpool.py", line 715, in urlopen
    httplib_response = self._make_request(
  File "/home/airflow/.local/lib/python3.8/site-packages/urllib3/connectionpool.py", line 416, in _make_request
    conn.request(method, url, **httplib_request_kw)
  File "/home/airflow/.local/lib/python3.8/site-packages/urllib3/connection.py", line 244, in request
    super(HTTPConnection, self).request(method, url, body=body, headers=headers)
  File "/usr/local/lib/python3.8/http/client.py", line 1256, in request
    self._send_request(method, url, body, headers, encode_chunked)
  File "/usr/local/lib/python3.8/http/client.py", line 1302, in _send_request
    self.endheaders(body, encode_chunked=encode_chunked)
  File "/usr/local/lib/python3.8/http/client.py", line 1251, in endheaders
    self._send_output(message_body, encode_chunked=encode_chunked)
  File "/usr/local/lib/python3.8/http/client.py", line 1011, in _send_output
    self.send(msg)
  File "/usr/local/lib/python3.8/http/client.py", line 951, in send
    self.connect()
  File "/home/airflow/.local/lib/python3.8/site-packages/urllib3/connection.py", line 205, in connect
    conn = self._new_conn()
  File "/home/airflow/.local/lib/python3.8/site-packages/urllib3/connection.py", line 186, in _new_conn
    raise NewConnectionError(
urllib3.exceptions.NewConnectionError: <urllib3.connection.HTTPConnection object at 0x7a401d2e8970>: Failed to establish a new connection: [Errno -2] Name or service not known

During handling of the above exception, another exception occurred:

Traceback (most recent call last):
  File "/home/airflow/.local/lib/python3.8/site-packages/requests/adapters.py", line 486, in send
    resp = conn.urlopen(
  File "/home/airflow/.local/lib/python3.8/site-packages/urllib3/connectionpool.py", line 827, in urlopen
    return self.urlopen(
  File "/home/airflow/.local/lib/python3.8/site-packages/urllib3/connectionpool.py", line 827, in urlopen
    return self.urlopen(
  File "/home/airflow/.local/lib/python3.8/site-packages/urllib3/connectionpool.py", line 827, in urlopen
    return self.urlopen(
  [Previous line repeated 2 more times]
  File "/home/airflow/.local/lib/python3.8/site-packages/urllib3/connectionpool.py", line 799, in urlopen
    retries = retries.increment(
  File "/home/airflow/.local/lib/python3.8/site-packages/urllib3/util/retry.py", line 592, in increment
    raise MaxRetryError(_pool, url, error or ResponseError(cause))
urllib3.exceptions.MaxRetryError: HTTPConnectionPool(host='mlflow', port=5000): Max retries exceeded with url: /api/2.0/mlflow/experiments/get-by-name?experiment_name=entrenamiento_orquestado (Caused by NewConnectionError('<urllib3.connection.HTTPConnection object at 0x7a401d2e8970>: Failed to establish a new connection: [Errno -2] Name or service not known'))

During handling of the above exception, another exception occurred:

Traceback (most recent call last):
  File "/home/airflow/.local/lib/python3.8/site-packages/mlflow/utils/rest_utils.py", line 189, in http_request
    return _get_http_response_with_retries(
  File "/home/airflow/.local/lib/python3.8/site-packages/mlflow/utils/request_utils.py", line 237, in _get_http_response_with_retries
    return session.request(method, url, allow_redirects=allow_redirects, **kwargs)
  File "/home/airflow/.local/lib/python3.8/site-packages/requests/sessions.py", line 589, in request
    resp = self.send(prep, **send_kwargs)
  File "/home/airflow/.local/lib/python3.8/site-packages/requests/sessions.py", line 703, in send
    r = adapter.send(request, **kwargs)
  File "/home/airflow/.local/lib/python3.8/site-packages/requests/adapters.py", line 519, in send
    raise ConnectionError(e, request=request)
requests.exceptions.ConnectionError: HTTPConnectionPool(host='mlflow', port=5000): Max retries exceeded with url: /api/2.0/mlflow/experiments/get-by-name?experiment_name=entrenamiento_orquestado (Caused by NewConnectionError('<urllib3.connection.HTTPConnection object at 0x7a401d2e8970>: Failed to establish a new connection: [Errno -2] Name or service not known'))

During handling of the above exception, another exception occurred:

Traceback (most recent call last):
  File "/home/airflow/.local/lib/python3.8/site-packages/airflow/models/taskinstance.py", line 433, in _execute_task
    result = execute_callable(context=context, **execute_callable_kwargs)
  File "/home/airflow/.local/lib/python3.8/site-packages/airflow/decorators/base.py", line 241, in execute
    return_value = super().execute(context)
  File "/home/airflow/.local/lib/python3.8/site-packages/airflow/operators/python.py", line 199, in execute
    return_value = self.execute_callable()
  File "/home/airflow/.local/lib/python3.8/site-packages/airflow/operators/python.py", line 216, in execute_callable
    return self.python_callable(*self.op_args, **self.op_kwargs)
  File "/opt/airflow/dags/entrenamiento_modelos_regresion_dag.py", line 68, in entrenar_y_promover
    mlflow.set_experiment("entrenamiento_orquestado")
  File "/home/airflow/.local/lib/python3.8/site-packages/mlflow/tracking/fluent.py", line 145, in set_experiment
    experiment = client.get_experiment_by_name(experiment_name)
  File "/home/airflow/.local/lib/python3.8/site-packages/mlflow/tracking/client.py", line 1256, in get_experiment_by_name
    return self._tracking_client.get_experiment_by_name(name)
  File "/home/airflow/.local/lib/python3.8/site-packages/mlflow/tracking/_tracking_service/client.py", line 501, in get_experiment_by_name
    return self.store.get_experiment_by_name(name)
  File "/home/airflow/.local/lib/python3.8/site-packages/mlflow/store/tracking/rest_store.py", line 519, in get_experiment_by_name
    response_proto = self._call_endpoint(GetExperimentByName, req_body)
  File "/home/airflow/.local/lib/python3.8/site-packages/mlflow/store/tracking/rest_store.py", line 82, in _call_endpoint
    return call_endpoint(self.get_host_creds(), endpoint, method, json_body, response_proto)
  File "/home/airflow/.local/lib/python3.8/site-packages/mlflow/utils/rest_utils.py", line 365, in call_endpoint
    response = http_request(**call_kwargs)
  File "/home/airflow/.local/lib/python3.8/site-packages/mlflow/utils/rest_utils.py", line 212, in http_request
    raise MlflowException(f"API request to {url} failed with exception {e}")
mlflow.exceptions.MlflowException: API request to http://mlflow:5000/api/2.0/mlflow/experiments/get-by-name failed with exception HTTPConnectionPool(host='mlflow', port=5000): Max retries exceeded with url: /api/2.0/mlflow/experiments/get-by-name?experiment_name=entrenamiento_orquestado (Caused by NewConnectionError('<urllib3.connection.HTTPConnection object at 0x7a401d2e8970>: Failed to establish a new connection: [Errno -2] Name or service not known'))
[2025-05-31T23:22:57.142+0000] {taskinstance.py:1138} INFO - Marking task as UP_FOR_RETRY. dag_id=entrenamiento_modelos_regresion, task_id=entrenar_y_promover, execution_date=20250530T210000, start_date=20250531T232132, end_date=20250531T232257
[2025-05-31T23:22:57.165+0000] {standard_task_runner.py:107} ERROR - Failed to execute job 16 for task entrenar_y_promover (API request to http://mlflow:5000/api/2.0/mlflow/experiments/get-by-name failed with exception HTTPConnectionPool(host='mlflow', port=5000): Max retries exceeded with url: /api/2.0/mlflow/experiments/get-by-name?experiment_name=entrenamiento_orquestado (Caused by NewConnectionError('<urllib3.connection.HTTPConnection object at 0x7a401d2e8970>: Failed to establish a new connection: [Errno -2] Name or service not known')); 197)
[2025-05-31T23:22:58.551+0000] {local_task_job_runner.py:234} INFO - Task exited with return code 1
[2025-05-31T23:22:58.573+0000] {taskinstance.py:3280} INFO - 0 downstream tasks scheduled from follow-on schedule check
[2025-05-31T23:56:59.481+0000] {taskinstance.py:1956} INFO - Dependencies all met for dep_context=non-requeueable deps ti=<TaskInstance: entrenamiento_modelos_regresion.entrenar_y_promover scheduled__2025-05-30T21:00:00+00:00 [queued]>
[2025-05-31T23:56:59.494+0000] {taskinstance.py:1956} INFO - Dependencies all met for dep_context=requeueable deps ti=<TaskInstance: entrenamiento_modelos_regresion.entrenar_y_promover scheduled__2025-05-30T21:00:00+00:00 [queued]>
[2025-05-31T23:56:59.495+0000] {taskinstance.py:2170} INFO - Starting attempt 1 of 2
[2025-05-31T23:56:59.512+0000] {taskinstance.py:2191} INFO - Executing <Task(_PythonDecoratedOperator): entrenar_y_promover> on 2025-05-30 21:00:00+00:00
[2025-05-31T23:56:59.518+0000] {standard_task_runner.py:60} INFO - Started process 247 to run task
[2025-05-31T23:56:59.525+0000] {standard_task_runner.py:87} INFO - Running: ['***', 'tasks', 'run', 'entrenamiento_modelos_regresion', 'entrenar_y_promover', 'scheduled__2025-05-30T21:00:00+00:00', '--job-id', '2', '--raw', '--subdir', 'DAGS_FOLDER/entrenamiento_modelos_regresion_dag.py', '--cfg-path', '/tmp/tmp2ak5v6vv']
[2025-05-31T23:56:59.529+0000] {standard_task_runner.py:88} INFO - Job 2: Subtask entrenar_y_promover
[2025-05-31T23:56:59.611+0000] {task_command.py:423} INFO - Running <TaskInstance: entrenamiento_modelos_regresion.entrenar_y_promover scheduled__2025-05-30T21:00:00+00:00 [running]> on host 76da0f717085
[2025-05-31T23:56:59.740+0000] {taskinstance.py:2480} INFO - Exporting env vars: AIRFLOW_CTX_DAG_OWNER='fede' AIRFLOW_CTX_DAG_ID='entrenamiento_modelos_regresion' AIRFLOW_CTX_TASK_ID='entrenar_y_promover' AIRFLOW_CTX_EXECUTION_DATE='2025-05-30T21:00:00+00:00' AIRFLOW_CTX_TRY_NUMBER='1' AIRFLOW_CTX_DAG_RUN_ID='scheduled__2025-05-30T21:00:00+00:00'
[2025-05-31T23:57:03.984+0000] {logging_mixin.py:188} WARNING - /opt/***/dags/entrenamiento_modelos_regresion_dag.py:56 SettingWithCopyWarning:
A value is trying to be set on a copy of a slice from a DataFrame.
Try using .loc[row_indexer,col_indexer] = value instead

See the caveats in the documentation: https://pandas.pydata.org/pandas-docs/stable/user_guide/indexing.html#returning-a-view-versus-a-copy
[2025-05-31T23:57:04.003+0000] {logging_mixin.py:188} WARNING - /opt/***/dags/entrenamiento_modelos_regresion_dag.py:59 SettingWithCopyWarning:
A value is trying to be set on a copy of a slice from a DataFrame.
Try using .loc[row_indexer,col_indexer] = value instead

See the caveats in the documentation: https://pandas.pydata.org/pandas-docs/stable/user_guide/indexing.html#returning-a-view-versus-a-copy
[2025-05-31T23:57:04.005+0000] {logging_mixin.py:188} WARNING - /opt/***/dags/entrenamiento_modelos_regresion_dag.py:61 SettingWithCopyWarning:
A value is trying to be set on a copy of a slice from a DataFrame.
Try using .loc[row_indexer,col_indexer] = value instead

See the caveats in the documentation: https://pandas.pydata.org/pandas-docs/stable/user_guide/indexing.html#returning-a-view-versus-a-copy
[2025-05-31T23:57:04.007+0000] {logging_mixin.py:188} WARNING - /opt/***/dags/entrenamiento_modelos_regresion_dag.py:63 SettingWithCopyWarning:
A value is trying to be set on a copy of a slice from a DataFrame

See the caveats in the documentation: https://pandas.pydata.org/pandas-docs/stable/user_guide/indexing.html#returning-a-view-versus-a-copy
[2025-05-31T23:57:04.721+0000] {logging_mixin.py:188} WARNING - 2025/05/31 23:57:04 WARNING mlflow.utils.git_utils: Failed to import Git (the Git executable is probably not on your PATH), so Git SHA is not available. Error: Failed to initialize: Bad git executable.
The git executable must be specified in one of the following ways:
    - be included in your $PATH
    - be set via $GIT_PYTHON_GIT_EXECUTABLE
    - explicitly set via git.refresh(<full-path-to-git-executable>)

All git commands will error until this is rectified.

This initial message can be silenced or aggravated in the future by setting the
$GIT_PYTHON_REFRESH environment variable. Use one of the following values:
    - quiet|q|silence|s|silent|none|n|0: for no message or exception
    - warn|w|warning|log|l|1: for a warning message (logging level CRITICAL, displayed by default)
    - error|e|exception|raise|r|2: for a raised exception

Example:
    export GIT_PYTHON_REFRESH=quiet
[2025-05-31T23:57:08.810+0000] {logging_mixin.py:188} WARNING - 2025/05/31 23:57:08 WARNING mlflow.models.model: Model logged without a signature and input example. Please set `input_example` parameter when logging the model to auto infer the model signature.
[2025-05-31T23:57:08.972+0000] {logging_mixin.py:188} WARNING - 2025/05/31 23:57:08 INFO mlflow.tracking._tracking_service.client: 🏃 View run RandomForest at: http://mlflow:5000/#/experiments/1/runs/1c2b1a0134404f6c8907b27e3e47dc34.
[2025-05-31T23:57:08.972+0000] {logging_mixin.py:188} WARNING - 2025/05/31 23:57:08 INFO mlflow.tracking._tracking_service.client: 🧪 View experiment at: http://mlflow:5000/#/experiments/1.
[2025-05-31T23:57:12.858+0000] {logging_mixin.py:188} WARNING - 2025/05/31 23:57:12 WARNING mlflow.models.model: Model logged without a signature and input example. Please set `input_example` parameter when logging the model to auto infer the model signature.
[2025-05-31T23:57:12.972+0000] {logging_mixin.py:188} WARNING - 2025/05/31 23:57:12 INFO mlflow.tracking._tracking_service.client: 🏃 View run CatBoost at: http://mlflow:5000/#/experiments/1/runs/9e30c753aeba45e4b033e831c9478562.
[2025-05-31T23:57:12.973+0000] {logging_mixin.py:188} WARNING - 2025/05/31 23:57:12 INFO mlflow.tracking._tracking_service.client: 🧪 View experiment at: http://mlflow:5000/#/experiments/1.
[2025-05-31T23:57:15.596+0000] {logging_mixin.py:188} WARNING - 2025/05/31 23:57:15 WARNING mlflow.models.model: Model logged without a signature and input example. Please set `input_example` parameter when logging the model to auto infer the model signature.
[2025-05-31T23:57:15.826+0000] {logging_mixin.py:188} WARNING - 2025/05/31 23:57:15 INFO mlflow.tracking._tracking_service.client: 🏃 View run SVR at: http://mlflow:5000/#/experiments/1/runs/9966a7f9566a4c188e2698a3f6e2d98a.
[2025-05-31T23:57:15.827+0000] {logging_mixin.py:188} WARNING - 2025/05/31 23:57:15 INFO mlflow.tracking._tracking_service.client: 🧪 View experiment at: http://mlflow:5000/#/experiments/1.
[2025-05-31T23:57:15.946+0000] {logging_mixin.py:188} WARNING - Registered model 'mejor_modelo_orquestado' already exists. Creating a new version of this model...
[2025-05-31T23:57:16.039+0000] {logging_mixin.py:188} WARNING - 2025/05/31 23:57:16 INFO mlflow.store.model_registry.abstract_store: Waiting up to 300 seconds for model version to finish creation. Model name: mejor_modelo_orquestado, version 2
[2025-05-31T23:57:16.039+0000] {logging_mixin.py:188} WARNING - Created version '2' of model 'mejor_modelo_orquestado'.
[2025-05-31T23:57:16.041+0000] {logging_mixin.py:188} WARNING - /opt/***/dags/entrenamiento_modelos_regresion_dag.py:99 FutureWarning: ``mlflow.tracking.client.MlflowClient.get_latest_versions`` is deprecated since 2.9.0. Model registry stages will be removed in a future major release. To learn more about the deprecation of model registry stages, see our migration guide here: https://mlflow.org/docs/latest/model-registry.html#migrating-from-stages
[2025-05-31T23:57:16.056+0000] {logging_mixin.py:188} WARNING - /opt/***/dags/entrenamiento_modelos_regresion_dag.py:109 FutureWarning: ``mlflow.tracking.client.MlflowClient.transition_model_version_stage`` is deprecated since 2.9.0. Model registry stages will be removed in a future major release. To learn more about the deprecation of model registry stages, see our migration guide here: https://mlflow.org/docs/latest/model-registry.html#migrating-from-stages
[2025-05-31T23:57:16.130+0000] {logging_mixin.py:188} WARNING - /opt/***/dags/entrenamiento_modelos_regresion_dag.py:102 FutureWarning: ``mlflow.tracking.client.MlflowClient.transition_model_version_stage`` is deprecated since 2.9.0. Model registry stages will be removed in a future major release. To learn more about the deprecation of model registry stages, see our migration guide here: https://mlflow.org/docs/latest/model-registry.html#migrating-from-stages
[2025-05-31T23:57:16.160+0000] {python.py:201} INFO - Done. Returned value was: None
[2025-05-31T23:57:16.181+0000] {taskinstance.py:1138} INFO - Marking task as SUCCESS. dag_id=entrenamiento_modelos_regresion, task_id=entrenar_y_promover, execution_date=20250530T210000, start_date=20250531T235659, end_date=20250531T235716
[2025-05-31T23:57:16.260+0000] {local_task_job_runner.py:234} INFO - Task exited with return code 0
[2025-05-31T23:57:16.279+0000] {taskinstance.py:3280} INFO - 0 downstream tasks scheduled from follow-on schedule check
[2025-06-01T15:57:40.984+0000] {taskinstance.py:1956} INFO - Dependencies all met for dep_context=non-requeueable deps ti=<TaskInstance: entrenamiento_modelos_regresion.entrenar_y_promover scheduled__2025-05-30T21:00:00+00:00 [queued]>
[2025-06-01T15:57:40.997+0000] {taskinstance.py:1956} INFO - Dependencies all met for dep_context=requeueable deps ti=<TaskInstance: entrenamiento_modelos_regresion.entrenar_y_promover scheduled__2025-05-30T21:00:00+00:00 [queued]>
[2025-06-01T15:57:40.998+0000] {taskinstance.py:2170} INFO - Starting attempt 1 of 2
[2025-06-01T15:57:41.010+0000] {taskinstance.py:2191} INFO - Executing <Task(_PythonDecoratedOperator): entrenar_y_promover> on 2025-05-30 21:00:00+00:00
[2025-06-01T15:57:41.015+0000] {standard_task_runner.py:60} INFO - Started process 46756 to run task
[2025-06-01T15:57:41.019+0000] {standard_task_runner.py:87} INFO - Running: ['***', 'tasks', 'run', 'entrenamiento_modelos_regresion', 'entrenar_y_promover', 'scheduled__2025-05-30T21:00:00+00:00', '--job-id', '3', '--raw', '--subdir', 'DAGS_FOLDER/entrenamiento_modelos_regresion_dag.py', '--cfg-path', '/tmp/tmpxj0emljk']
[2025-06-01T15:57:41.021+0000] {standard_task_runner.py:88} INFO - Job 3: Subtask entrenar_y_promover
[2025-06-01T15:57:41.089+0000] {task_command.py:423} INFO - Running <TaskInstance: entrenamiento_modelos_regresion.entrenar_y_promover scheduled__2025-05-30T21:00:00+00:00 [running]> on host f142218a01ee
[2025-06-01T15:57:41.195+0000] {taskinstance.py:2480} INFO - Exporting env vars: AIRFLOW_CTX_DAG_OWNER='fede' AIRFLOW_CTX_DAG_ID='entrenamiento_modelos_regresion' AIRFLOW_CTX_TASK_ID='entrenar_y_promover' AIRFLOW_CTX_EXECUTION_DATE='2025-05-30T21:00:00+00:00' AIRFLOW_CTX_TRY_NUMBER='1' AIRFLOW_CTX_DAG_RUN_ID='scheduled__2025-05-30T21:00:00+00:00'
[2025-06-01T15:57:47.751+0000] {logging_mixin.py:188} WARNING - /opt/***/dags/entrenamiento_modelos_regresion_dag.py:47 SettingWithCopyWarning:
A value is trying to be set on a copy of a slice from a DataFrame.
Try using .loc[row_indexer,col_indexer] = value instead

See the caveats in the documentation: https://pandas.pydata.org/pandas-docs/stable/user_guide/indexing.html#returning-a-view-versus-a-copy
[2025-06-01T15:57:47.779+0000] {logging_mixin.py:188} WARNING - /opt/***/dags/entrenamiento_modelos_regresion_dag.py:50 SettingWithCopyWarning:
A value is trying to be set on a copy of a slice from a DataFrame.
Try using .loc[row_indexer,col_indexer] = value instead

See the caveats in the documentation: https://pandas.pydata.org/pandas-docs/stable/user_guide/indexing.html#returning-a-view-versus-a-copy
[2025-06-01T15:57:47.790+0000] {logging_mixin.py:188} WARNING - /opt/***/dags/entrenamiento_modelos_regresion_dag.py:52 SettingWithCopyWarning:
A value is trying to be set on a copy of a slice from a DataFrame.
Try using .loc[row_indexer,col_indexer] = value instead

See the caveats in the documentation: https://pandas.pydata.org/pandas-docs/stable/user_guide/indexing.html#returning-a-view-versus-a-copy
[2025-06-01T15:57:47.794+0000] {logging_mixin.py:188} WARNING - /opt/***/dags/entrenamiento_modelos_regresion_dag.py:54 SettingWithCopyWarning:
A value is trying to be set on a copy of a slice from a DataFrame

See the caveats in the documentation: https://pandas.pydata.org/pandas-docs/stable/user_guide/indexing.html#returning-a-view-versus-a-copy
[2025-06-01T15:57:50.571+0000] {logging_mixin.py:188} WARNING - 2025/06/01 15:57:50 INFO mlflow.tracking.fluent: Experiment with name 'entrenamiento_orquestado' does not exist. Creating a new experiment.
[2025-06-01T15:57:50.774+0000] {logging_mixin.py:188} WARNING - 2025/06/01 15:57:50 WARNING mlflow.utils.git_utils: Failed to import Git (the Git executable is probably not on your PATH), so Git SHA is not available. Error: Failed to initialize: Bad git executable.
The git executable must be specified in one of the following ways:
    - be included in your $PATH
    - be set via $GIT_PYTHON_GIT_EXECUTABLE
    - explicitly set via git.refresh(<full-path-to-git-executable>)

All git commands will error until this is rectified.

This initial message can be silenced or aggravated in the future by setting the
$GIT_PYTHON_REFRESH environment variable. Use one of the following values:
    - quiet|q|silence|s|silent|none|n|0: for no message or exception
    - warn|w|warning|log|l|1: for a warning message (logging level CRITICAL, displayed by default)
    - error|e|exception|raise|r|2: for a raised exception

Example:
    export GIT_PYTHON_REFRESH=quiet
[2025-06-01T15:57:58.507+0000] {logging_mixin.py:188} WARNING - 2025/06/01 15:57:58 WARNING mlflow.models.model: Model logged without a signature and input example. Please set `input_example` parameter when logging the model to auto infer the model signature.
[2025-06-01T15:58:01.805+0000] {logging_mixin.py:188} WARNING - 2025/06/01 15:58:01 INFO mlflow.tracking._tracking_service.client: 🏃 View run RandomForest at: http://mlflow:5000/#/experiments/1/runs/dab4617aae4a4ed38fe82b17b25adb9c.
[2025-06-01T15:58:01.806+0000] {logging_mixin.py:188} WARNING - 2025/06/01 15:58:01 INFO mlflow.tracking._tracking_service.client: 🧪 View experiment at: http://mlflow:5000/#/experiments/1.
[2025-06-01T15:58:05.553+0000] {logging_mixin.py:188} WARNING - 2025/06/01 15:58:05 WARNING mlflow.models.model: Model logged without a signature and input example. Please set `input_example` parameter when logging the model to auto infer the model signature.
[2025-06-01T15:58:05.651+0000] {logging_mixin.py:188} WARNING - 2025/06/01 15:58:05 INFO mlflow.tracking._tracking_service.client: 🏃 View run CatBoost at: http://mlflow:5000/#/experiments/1/runs/6065f567978849c985d27bfe02636b19.
[2025-06-01T15:58:05.651+0000] {logging_mixin.py:188} WARNING - 2025/06/01 15:58:05 INFO mlflow.tracking._tracking_service.client: 🧪 View experiment at: http://mlflow:5000/#/experiments/1.
[2025-06-01T15:58:09.924+0000] {logging_mixin.py:188} WARNING - 2025/06/01 15:58:09 WARNING mlflow.models.model: Model logged without a signature and input example. Please set `input_example` parameter when logging the model to auto infer the model signature.
[2025-06-01T15:58:09.997+0000] {logging_mixin.py:188} WARNING - 2025/06/01 15:58:09 INFO mlflow.tracking._tracking_service.client: 🏃 View run SVR at: http://mlflow:5000/#/experiments/1/runs/2c1f93352fc6451b83b88e4c2d17d667.
[2025-06-01T15:58:09.997+0000] {logging_mixin.py:188} WARNING - 2025/06/01 15:58:09 INFO mlflow.tracking._tracking_service.client: 🧪 View experiment at: http://mlflow:5000/#/experiments/1.
[2025-06-01T15:58:10.146+0000] {logging_mixin.py:188} WARNING - Registered model 'mejor_modelo_orquestado' already exists. Creating a new version of this model...
[2025-06-01T15:58:10.314+0000] {logging_mixin.py:188} WARNING - 2025/06/01 15:58:10 INFO mlflow.store.model_registry.abstract_store: Waiting up to 300 seconds for model version to finish creation. Model name: mejor_modelo_orquestado, version 2
[2025-06-01T15:58:10.315+0000] {logging_mixin.py:188} WARNING - Created version '2' of model 'mejor_modelo_orquestado'.
[2025-06-01T15:58:10.317+0000] {logging_mixin.py:188} WARNING - /opt/***/dags/entrenamiento_modelos_regresion_dag.py:88 FutureWarning: ``mlflow.tracking.client.MlflowClient.get_latest_versions`` is deprecated since 2.9.0. Model registry stages will be removed in a future major release. To learn more about the deprecation of model registry stages, see our migration guide here: https://mlflow.org/docs/latest/model-registry.html#migrating-from-stages
[2025-06-01T15:58:10.337+0000] {logging_mixin.py:188} WARNING - /opt/***/dags/entrenamiento_modelos_regresion_dag.py:91 FutureWarning: ``mlflow.tracking.client.MlflowClient.transition_model_version_stage`` is deprecated since 2.9.0. Model registry stages will be removed in a future major release. To learn more about the deprecation of model registry stages, see our migration guide here: https://mlflow.org/docs/latest/model-registry.html#migrating-from-stages
[2025-06-01T15:58:10.400+0000] {python.py:201} INFO - Done. Returned value was: None
[2025-06-01T15:58:10.424+0000] {taskinstance.py:1138} INFO - Marking task as SUCCESS. dag_id=entrenamiento_modelos_regresion, task_id=entrenar_y_promover, execution_date=20250530T210000, start_date=20250601T155740, end_date=20250601T155810
[2025-06-01T15:58:10.496+0000] {local_task_job_runner.py:234} INFO - Task exited with return code 0
[2025-06-01T15:58:10.528+0000] {taskinstance.py:3280} INFO - 1 downstream tasks scheduled from follow-on schedule check
[2025-06-01T17:10:44.567+0000] {taskinstance.py:1956} INFO - Dependencies all met for dep_context=non-requeueable deps ti=<TaskInstance: entrenamiento_modelos_regresion.entrenar_y_promover scheduled__2025-05-30T21:00:00+00:00 [queued]>
[2025-06-01T17:10:44.592+0000] {taskinstance.py:1956} INFO - Dependencies all met for dep_context=requeueable deps ti=<TaskInstance: entrenamiento_modelos_regresion.entrenar_y_promover scheduled__2025-05-30T21:00:00+00:00 [queued]>
[2025-06-01T17:10:44.593+0000] {taskinstance.py:2170} INFO - Starting attempt 1 of 2
[2025-06-01T17:10:44.628+0000] {taskinstance.py:2191} INFO - Executing <Task(_PythonDecoratedOperator): entrenar_y_promover> on 2025-05-30 21:00:00+00:00
[2025-06-01T17:10:44.634+0000] {standard_task_runner.py:60} INFO - Started process 231 to run task
[2025-06-01T17:10:44.642+0000] {standard_task_runner.py:87} INFO - Running: ['***', 'tasks', 'run', 'entrenamiento_modelos_regresion', 'entrenar_y_promover', 'scheduled__2025-05-30T21:00:00+00:00', '--job-id', '3', '--raw', '--subdir', 'DAGS_FOLDER/entrenamiento_modelos_regresion_dag.py', '--cfg-path', '/tmp/tmphn87laaq']
[2025-06-01T17:10:44.645+0000] {standard_task_runner.py:88} INFO - Job 3: Subtask entrenar_y_promover
[2025-06-01T17:10:44.739+0000] {task_command.py:423} INFO - Running <TaskInstance: entrenamiento_modelos_regresion.entrenar_y_promover scheduled__2025-05-30T21:00:00+00:00 [running]> on host 29b9f1cfdb60
[2025-06-01T17:10:44.878+0000] {taskinstance.py:2480} INFO - Exporting env vars: AIRFLOW_CTX_DAG_OWNER='fede' AIRFLOW_CTX_DAG_ID='entrenamiento_modelos_regresion' AIRFLOW_CTX_TASK_ID='entrenar_y_promover' AIRFLOW_CTX_EXECUTION_DATE='2025-05-30T21:00:00+00:00' AIRFLOW_CTX_TRY_NUMBER='1' AIRFLOW_CTX_DAG_RUN_ID='scheduled__2025-05-30T21:00:00+00:00'
[2025-06-01T17:10:53.271+0000] {logging_mixin.py:188} WARNING - /opt/***/dags/entrenamiento_modelos_regresion_dag.py:47 SettingWithCopyWarning:
A value is trying to be set on a copy of a slice from a DataFrame.
Try using .loc[row_indexer,col_indexer] = value instead

See the caveats in the documentation: https://pandas.pydata.org/pandas-docs/stable/user_guide/indexing.html#returning-a-view-versus-a-copy
[2025-06-01T17:10:53.376+0000] {logging_mixin.py:188} WARNING - /opt/***/dags/entrenamiento_modelos_regresion_dag.py:50 SettingWithCopyWarning:
A value is trying to be set on a copy of a slice from a DataFrame.
Try using .loc[row_indexer,col_indexer] = value instead

See the caveats in the documentation: https://pandas.pydata.org/pandas-docs/stable/user_guide/indexing.html#returning-a-view-versus-a-copy
[2025-06-01T17:10:53.382+0000] {logging_mixin.py:188} WARNING - /opt/***/dags/entrenamiento_modelos_regresion_dag.py:52 SettingWithCopyWarning:
A value is trying to be set on a copy of a slice from a DataFrame.
Try using .loc[row_indexer,col_indexer] = value instead

See the caveats in the documentation: https://pandas.pydata.org/pandas-docs/stable/user_guide/indexing.html#returning-a-view-versus-a-copy
[2025-06-01T17:10:53.385+0000] {logging_mixin.py:188} WARNING - /opt/***/dags/entrenamiento_modelos_regresion_dag.py:54 SettingWithCopyWarning:
A value is trying to be set on a copy of a slice from a DataFrame

See the caveats in the documentation: https://pandas.pydata.org/pandas-docs/stable/user_guide/indexing.html#returning-a-view-versus-a-copy
[2025-06-01T17:10:55.725+0000] {logging_mixin.py:188} WARNING - 2025/06/01 17:10:55 INFO mlflow.tracking.fluent: Experiment with name 'entrenamiento_orquestado' does not exist. Creating a new experiment.
[2025-06-01T17:10:57.027+0000] {taskinstance.py:2698} ERROR - Task failed with exception
Traceback (most recent call last):
  File "/home/airflow/.local/lib/python3.8/site-packages/airflow/models/taskinstance.py", line 433, in _execute_task
    result = execute_callable(context=context, **execute_callable_kwargs)
  File "/home/airflow/.local/lib/python3.8/site-packages/airflow/decorators/base.py", line 241, in execute
    return_value = super().execute(context)
  File "/home/airflow/.local/lib/python3.8/site-packages/airflow/operators/python.py", line 199, in execute
    return_value = self.execute_callable()
  File "/home/airflow/.local/lib/python3.8/site-packages/airflow/operators/python.py", line 216, in execute_callable
    return self.python_callable(*self.op_args, **self.op_kwargs)
  File "/opt/airflow/dags/entrenamiento_modelos_regresion_dag.py", line 59, in entrenar_y_promover
    mlflow.set_experiment("entrenamiento_orquestado")
  File "/home/airflow/.local/lib/python3.8/site-packages/mlflow/tracking/fluent.py", line 154, in set_experiment
    experiment_id = client.create_experiment(experiment_name)
  File "/home/airflow/.local/lib/python3.8/site-packages/mlflow/tracking/client.py", line 1310, in create_experiment
    return self._tracking_client.create_experiment(name, artifact_location, tags)
  File "/home/airflow/.local/lib/python3.8/site-packages/mlflow/tracking/_tracking_service/client.py", line 518, in create_experiment
    return self.store.create_experiment(
  File "/home/airflow/.local/lib/python3.8/site-packages/mlflow/store/tracking/rest_store.py", line 123, in create_experiment
    response_proto = self._call_endpoint(CreateExperiment, req_body)
  File "/home/airflow/.local/lib/python3.8/site-packages/mlflow/store/tracking/rest_store.py", line 82, in _call_endpoint
    return call_endpoint(self.get_host_creds(), endpoint, method, json_body, response_proto)
  File "/home/airflow/.local/lib/python3.8/site-packages/mlflow/utils/rest_utils.py", line 370, in call_endpoint
    response = verify_rest_response(response, endpoint)
  File "/home/airflow/.local/lib/python3.8/site-packages/mlflow/utils/rest_utils.py", line 240, in verify_rest_response
    raise RestException(json.loads(response.text))
mlflow.exceptions.RestException: RESOURCE_ALREADY_EXISTS: Experiment(name=entrenamiento_orquestado) already exists. Error: (raised as a result of Query-invoked autoflush; consider using a session.no_autoflush block if this flush is occurring prematurely)
(sqlite3.IntegrityError) UNIQUE constraint failed: experiments.name
[SQL: INSERT INTO experiments (name, artifact_location, lifecycle_stage, creation_time, last_update_time) VALUES (?, ?, ?, ?, ?)]
[parameters: ('entrenamiento_orquestado', '', 'active', 1748797857018, 1748797857018)]
(Background on this error at: https://sqlalche.me/e/20/gkpj)
[2025-06-01T17:10:57.061+0000] {taskinstance.py:1138} INFO - Marking task as UP_FOR_RETRY. dag_id=entrenamiento_modelos_regresion, task_id=entrenar_y_promover, execution_date=20250530T210000, start_date=20250601T171044, end_date=20250601T171057
[2025-06-01T17:10:57.127+0000] {standard_task_runner.py:107} ERROR - Failed to execute job 3 for task entrenar_y_promover (RESOURCE_ALREADY_EXISTS: Experiment(name=entrenamiento_orquestado) already exists. Error: (raised as a result of Query-invoked autoflush; consider using a session.no_autoflush block if this flush is occurring prematurely)
(sqlite3.IntegrityError) UNIQUE constraint failed: experiments.name
[SQL: INSERT INTO experiments (name, artifact_location, lifecycle_stage, creation_time, last_update_time) VALUES (?, ?, ?, ?, ?)]
[parameters: ('entrenamiento_orquestado', '', 'active', 1748797857018, 1748797857018)]
(Background on this error at: https://sqlalche.me/e/20/gkpj); 231)
[2025-06-01T17:10:57.189+0000] {local_task_job_runner.py:234} INFO - Task exited with return code 1
[2025-06-01T17:10:57.238+0000] {taskinstance.py:3280} INFO - 0 downstream tasks scheduled from follow-on schedule check
